<?xml version="1.0" ?>
<!-- =================================================================================== -->
<!-- |    This document was autogenerated by xacro from centauro.urdf.xacro            | -->
<!-- |    EDITING THIS FILE BY HAND IS NOT RECOMMENDED                                 | -->
<!-- =================================================================================== -->
<robot name="centauro" xmlns:xacro="http://www.ros.org/wiki/xacro">
  <!-- /constants -->
  <!-- Here all arguments from launch file are evaluated to the final xacro poropeties.
     Also all the parameter dependencies are resolved-->
  <material name="grey">
    <color rgba="0.5 0.5 0.5 1"/>
  </material>
  <material name="dark_grey">
    <color rgba="0.3 0.3 0.3 1"/>
  </material>
  <material name="blue">
    <color rgba="0.0 0.2 0.3 1"/>
  </material>
  <material name="red">
    <color rgba="0.5 0.1 0.2 1"/>
  </material>
  <material name="black">
    <color rgba="0.0 0.0 0.0 1"/>
  </material>
  <!-- Here all arguments from launch file are evaluated to the final xacro poropeties.
     Also all the parameter dependencies are resolved-->
  <!-- load proper collision model -->
  <!-- load proper collision model -->
  <!-- Here all arguments from launch file are evaluated to the final xacro poropeties.
     Also all the parameter dependencies are resolved-->
  <!-- load proper collision model -->
  <!-- load proper collision model -->
  <!-- /macro arms -->
  <!-- /other files -->
  <!-- reference -->
  <link name="world"/>
  <link name="pelvis"/>
  <joint name="reference" type="fixed">
    <origin xyz="0.0 0.0 0.85"/>
    <parent link="world"/>
    <child link="pelvis"/>
  </joint>
  <!-- /reference  -->
  <!-- torso links -->
  <link name="torso_2">
    <inertial>
      <origin xyz="0.0047281261 0.00038307386 0.14972892"/>
      <mass value="4.5494226"/>
      <!-- mass  7: torso_1 (2) + torso_2 (5), head un_modelled -->
      <inertia ixx="0.063643392" ixy="8.939e-05" ixz="-0.00086873" iyy="0.02680235" iyz="-4.657e-05" izz="0.04743015"/>
    </inertial>
    <visual>
      <origin rpy="1.5646258233 0.00631611549186 0.00627726188579" xyz="0.006465805 0.0001011 0.153948"/>
      <geometry>
        <cylinder length="0.0891360748547" radius="0.161132"/>
      </geometry>
      <material name="grey"/>
    </visual>
    <collision>
      <origin rpy="1.5646258233 0.00631611549186 0.00627726188579" xyz="0.006465805 0.0001011 0.153948"/>
      <geometry>
        <cylinder length="0.0891360748547" radius="0.161132"/>
      </geometry>
      <material name="grey"/>
    </collision>
  </link>
  <!-- /torso links -->
  <!-- torso joints -->
  <joint name="torso_yaw" type="revolute">
    <parent link="world"/>
    <origin xyz="0.3 0.0 0.95"/>
    <child link="torso_2"/>
    <axis xyz="0 0 1"/>
    <limit effort="147" lower="-2.618" upper="2.618" velocity="5.7"/>
    <!-- TODO -->
  </joint>
  <!-- /torso joints -->
  <transmission name="t_torso_yaw">
    <type> transmission_interface/SimpleTransmission</type>
    <joint name="torso_yaw">
      <hardwareInterface>EffortJointInterface</hardwareInterface>
    </joint>
    <actuator name="motor_torso_yaw">
      <hardwareInterface>EffortJointInterface</hardwareInterface>
      <machanicalReduction>1</machanicalReduction>
    </actuator>
    <robotNamespace>/centauro</robotNamespace>
  </transmission>
  <!-- /torso actuators -->
  <!-- /torso -->
  <!-- LINKS -->
  <!-- shoulder yaw-roll-->
  <link name="arm1_1">
    <inertial>
      <origin xyz="-0.0031005886 0.040324584 0.007451937"/>
      <mass value="1.5583338"/>
      <inertia ixx="0.0032318636" ixy="4.24587e-05" ixz="4.91626e-05" iyy="0.00275718" iyz="-0.0002387056" izz="0.004275047"/>
    </inertial>
    <visual>
      <origin rpy="1.43215510177 1.49033190729 1.3529023596" xyz="-0.0048142 0.05214035 0.009074915"/>
      <geometry>
        <cylinder length="0.0751108222021" radius="0.0704036"/>
      </geometry>
      <material name="blue"/>
    </visual>
    <collision>
      <origin rpy="1.43215510177 1.49033190729 1.3529023596" xyz="-0.0048142 0.05214035 0.009074915"/>
      <geometry>
        <cylinder length="0.0751108222021" radius="0.0704036"/>
      </geometry>
      <material name="blue"/>
    </collision>
  </link>
  <!-- shoulder yaw-roll-->
  <!-- shoulder roll-pitch-->
  <link name="arm1_2">
    <inertial>
      <origin xyz="0.05105435 0.00011109 -0.07643596"/>
      <mass value="1.515061"/>
      <inertia ixx="0.01029558" ixy="2.846e-05" ixz="0.0036567" iyy="0.01178018" iyz="2.088e-05" izz="0.00386123"/>
    </inertial>
    <visual>
      <origin rpy="3.14155533114 0.292918451701 3.14133964661" xyz="0.0709568 -7.98629e-06 -0.08709620665"/>
      <geometry>
        <cylinder length="0.181861949629" radius="0.0715161"/>
      </geometry>
      <material name="grey"/>
    </visual>
    <collision>
      <origin rpy="3.14155533114 0.292918451701 3.14133964661" xyz="0.0709568 -7.98629e-06 -0.08709620665"/>
      <geometry>
        <cylinder length="0.181861949629" radius="0.0715161"/>
      </geometry>
      <material name="grey"/>
    </collision>
  </link>
  <!-- shoulder roll-pitch-->
  <!-- shoulder-elbow -->
  <link name="arm1_3">
    <inertial>
      <origin xyz="0.01207624 0.00322013 -0.03427312"/>
      <mass value="1.5088101"/>
      <inertia ixx="0.00469819" ixy="-0.00026547" ixz="0.00077706" iyy="0.00501755" iyz="0.00029679" izz="0.00310954"/>
    </inertial>
    <visual>
      <origin rpy="-3.12082286426 0.376309803205 -3.03261579115" xyz="0.011726993 0.000587176 -0.036774245"/>
      <geometry>
        <cylinder length="0.0663641129654" radius="0.0864441"/>
      </geometry>
      <material name="blue"/>
    </visual>
    <collision>
      <origin rpy="-3.12082286426 0.376309803205 -3.03261579115" xyz="0.011726993 0.000587176 -0.036774245"/>
      <geometry>
        <cylinder length="0.0663641129654" radius="0.0864441"/>
      </geometry>
      <material name="blue"/>
    </collision>
  </link>
  <!-- /shoulder-elbow -->
  <!-- elbow yaw-pitch -->
  <link name="arm1_4">
    <inertial>
      <origin xyz="0.010147552 -0.029928537 -0.032528288"/>
      <mass value="0.96297329"/>
      <inertia ixx="0.0026493567" ixy="5.1632e-06" ixz="0.0001292309" iyy="0.0023470955" iyz="-0.0007895755" izz="0.0012213063"/>
    </inertial>
    <visual>
      <origin rpy="-0.495925898415 0.203809792245 -0.0517669672272" xyz="-0.007494375 -0.03766645 -0.032153375"/>
      <geometry>
        <cylinder length="0.086188245518" radius="0.0644525"/>
      </geometry>
      <material name="grey"/>
    </visual>
    <collision>
      <origin rpy="-0.495925898415 0.203809792245 -0.0517669672272" xyz="-0.007494375 -0.03766645 -0.032153375"/>
      <geometry>
        <cylinder length="0.086188245518" radius="0.0644525"/>
      </geometry>
      <material name="grey"/>
    </collision>
  </link>
  <!-- /elbow yaw-pitch -->
  <!-- elbow-wrist -->
  <link name="arm1_5">
    <inertial>
      <origin xyz="-0.0001574443 0.0041320907 -0.10756614"/>
      <mass value="1.4703698"/>
      <inertia ixx="0.0064160453" ixy="1.96382e-05" ixz="2.49912e-05" iyy="0.0062016367" iyz="-0.0001987903" izz="0.0017091658"/>
    </inertial>
    <visual>
      <origin rpy="-0.0568462554593 0.000100286628987 -2.85122752006e-06" xyz="-1.864335e-05 0.002166045 -0.1129697"/>
      <geometry>
        <cylinder length="0.117011611001" radius="0.066519"/>
      </geometry>
      <material name="blue"/>
    </visual>
    <collision>
      <origin rpy="-0.0568462554593 0.000100286628987 -2.85122752006e-06" xyz="-1.864335e-05 0.002166045 -0.1129697"/>
      <geometry>
        <cylinder length="0.117011611001" radius="0.066519"/>
      </geometry>
      <material name="blue"/>
    </collision>
  </link>
  <!-- /elbow-wrist -->
  <!-- wrist yaw-pitch -->
  <link name="arm1_6">
    <inertial>
      <origin xyz="3.23645e-05 -0.035947237 -0.080878061"/>
      <mass value="0.94693868"/>
      <inertia ixx="0.0036896582" ixy="2.63667e-05" ixz="1.4005e-06" iyy="0.0034146283" iyz="-0.0008268103" izz="0.0010790183"/>
    </inertial>
    <visual>
      <origin rpy="2.84203235611 -0.00109442040711 -0.00725209173511" xyz="-6.44753e-05 -0.0278815 -0.067420365"/>
      <geometry>
        <cylinder length="0.145199624103" radius="0.0470691"/>
      </geometry>
      <material name="grey"/>
    </visual>
    <collision>
      <origin rpy="2.84203235611 -0.00109442040711 -0.00725209173511" xyz="-6.44753e-05 -0.0278815 -0.067420365"/>
      <geometry>
        <cylinder length="0.145199624103" radius="0.0470691"/>
      </geometry>
      <material name="grey"/>
    </collision>
  </link>
  <!-- /wrist yaw-pitch -->
  <link name="arm1_7">
    <inertial>
      <origin xyz="2.46596e-05 -0.0001467705 -0.0052993013"/>
      <mass value="0.55981036"/>
      <inertia ixx="0.0004360175" ixy="1.397e-07" ixz="-1.382e-07" iyy="0.0004299166" iyz="-1.4752e-06" izz="0.0004522224"/>
    </inertial>
    <visual>
      <origin rpy="0.0 0.0 0.0" xyz="0.0 0.0 -0.020"/>
      <geometry>
        <box size="0.05 0.05 0.05"/>
      </geometry>
      <material name="blue"/>
    </visual>
    <collision>
      <origin rpy="0.0 0.0 0.0" xyz="0.0 0.0 -0.020"/>
      <geometry>
        <box size="0.05 0.05 0.05"/>
      </geometry>
      <material name="blue"/>
    </collision>
  </link>
  <!-- /LINKS -->
  <!-- JOINTS -->
  <!-- shoulder yaw -->
  <joint name="j_arm1_1" type="revolute">
    <parent link="torso_2"/>
    <child link="arm1_1"/>
    <origin rpy="0.0 0.0 -0.523602668986" xyz="0.04576 0.169137 0.190626"/>
    <axis xyz="0 0.984807753012 0.173648177667"/>
    <limit effort="147" lower="-3.403" upper="1.658" velocity="5.7"/>
  </joint>
  <!-- /shoulder yaw -->
  <!-- shoulder roll -->
  <joint name="j_arm1_2" type="revolute">
    <parent link="arm1_1"/>
    <child link="arm1_2"/>
    <origin xyz="-0.09115 0.06106 0.010766"/>
    <axis xyz="-1 0 0"/>
    <limit effort="147" lower="-3.49" upper="0" velocity="5.7"/>
  </joint>
  <!-- /shoulder roll -->
  <!-- shoulder pitch-->
  <joint name="j_arm1_3" type="revolute">
    <parent link="arm1_2"/>
    <child link="arm1_3"/>
    <origin xyz="0.09115 0.0 -0.21915"/>
    <axis xyz="0 0 -1"/>
    <limit effort="147" lower="-2.618" upper="2.618" velocity="8.2"/>
  </joint>
  <!-- /shoulder pitch -->
  <!-- elbow yaw -->
  <joint name="j_arm1_4" type="revolute">
    <parent link="arm1_3"/>
    <child link="arm1_4"/>
    <origin xyz="0.04 0.05615 -0.074"/>
    <axis xyz="0 1 0"/>
    <limit effort="147" lower="-2.530" upper="0.349" velocity="8.2"/>
  </joint>
  <!-- /elbow yaw -->
  <!-- elbow pitch-->
  <joint name="j_arm1_5" type="revolute">
    <parent link="arm1_4"/>
    <child link="arm1_5"/>
    <origin xyz="-0.015 -0.05615 -0.061"/>
    <axis xyz="0 0 -1"/>
    <limit effort="55" lower="-2.618" upper="2.618" velocity="11.6"/>
  </joint>
  <!-- /elbow pitch-->
  <!-- wrist yaw-->
  <joint name="j_arm1_6" type="revolute">
    <parent link="arm1_5"/>
    <child link="arm1_6"/>
    <origin xyz="0.0 0.049 -0.18"/>
    <axis xyz="0 1 0"/>
    <limit effort="55" lower="-1.570" upper="1.570" velocity="11.6"/>
  </joint>
  <!-- /wrist yaw-->
  <!-- wrist pitch-->
  <joint name="j_arm1_7" type="revolute">
    <parent link="arm1_6"/>
    <child link="arm1_7"/>
    <origin xyz="0.0 -0.049 -0.169"/>
    <axis xyz="0 0 -1"/>
    <limit effort="27" lower="-2.618" upper="2.618" velocity="20.3"/>
  </joint>
  <!-- wrist pitch-->
  <!-- force-troque sensor -->
  <transmission name="t_j_arm1_1">
    <type> transmission_interface/SimpleTransmission</type>
    <joint name="j_arm1_1">
      <hardwareInterface>EffortJointInterface</hardwareInterface>
    </joint>
    <actuator name="motor_j_arm1_1">
      <hardwareInterface>EffortJointInterface</hardwareInterface>
      <machanicalReduction>1</machanicalReduction>
    </actuator>
    <robotNamespace>/centauro</robotNamespace>
  </transmission>
  <transmission name="t_j_arm1_2">
    <type> transmission_interface/SimpleTransmission</type>
    <joint name="j_arm1_2">
      <hardwareInterface>EffortJointInterface</hardwareInterface>
    </joint>
    <actuator name="motor_j_arm1_2">
      <hardwareInterface>EffortJointInterface</hardwareInterface>
      <machanicalReduction>1</machanicalReduction>
    </actuator>
    <robotNamespace>/centauro</robotNamespace>
  </transmission>
  <transmission name="t_j_arm1_3">
    <type> transmission_interface/SimpleTransmission</type>
    <joint name="j_arm1_3">
      <hardwareInterface>EffortJointInterface</hardwareInterface>
    </joint>
    <actuator name="motor_j_arm1_3">
      <hardwareInterface>EffortJointInterface</hardwareInterface>
      <machanicalReduction>1</machanicalReduction>
    </actuator>
    <robotNamespace>/centauro</robotNamespace>
  </transmission>
  <transmission name="t_j_arm1_4">
    <type> transmission_interface/SimpleTransmission</type>
    <joint name="j_arm1_4">
      <hardwareInterface>EffortJointInterface</hardwareInterface>
    </joint>
    <actuator name="motor_j_arm1_4">
      <hardwareInterface>EffortJointInterface</hardwareInterface>
      <machanicalReduction>1</machanicalReduction>
    </actuator>
    <robotNamespace>/centauro</robotNamespace>
  </transmission>
  <transmission name="t_j_arm1_5">
    <type> transmission_interface/SimpleTransmission</type>
    <joint name="j_arm1_5">
      <hardwareInterface>EffortJointInterface</hardwareInterface>
    </joint>
    <actuator name="motor_j_arm1_5">
      <hardwareInterface>EffortJointInterface</hardwareInterface>
      <machanicalReduction>1</machanicalReduction>
    </actuator>
    <robotNamespace>/centauro</robotNamespace>
  </transmission>
  <transmission name="t_j_arm1_6">
    <type> transmission_interface/SimpleTransmission</type>
    <joint name="j_arm1_6">
      <hardwareInterface>EffortJointInterface</hardwareInterface>
    </joint>
    <actuator name="motor_j_arm1_6">
      <hardwareInterface>EffortJointInterface</hardwareInterface>
      <machanicalReduction>1</machanicalReduction>
    </actuator>
    <robotNamespace>/centauro</robotNamespace>
  </transmission>
  <transmission name="t_j_arm1_7">
    <type> transmission_interface/SimpleTransmission</type>
    <joint name="j_arm1_7">
      <hardwareInterface>EffortJointInterface</hardwareInterface>
    </joint>
    <actuator name="motor_j_arm1_7">
      <hardwareInterface>EffortJointInterface</hardwareInterface>
      <machanicalReduction>1</machanicalReduction>
    </actuator>
    <robotNamespace>/centauro</robotNamespace>
  </transmission>
  <!-- /actuators -->
  <!-- end-effector -->
  <!-- links -->
  <link name="arm1_8">
    <inertial>
      <origin rpy="0 0 0" xyz="0.001 0.0 0.006"/>
      <mass value="0.15"/>
      <inertia ixx="0.0002" ixy="0.0" ixz="0.0" iyy="0.0002" iyz="0.0" izz="1e-05"/>
      <!--          <inertia ixx="0.003"  ixy="0"  ixz="0" iyy="0.0025" iyz="0" izz="0.00016900" /> -->
    </inertial>
    <visual>
      <origin rpy="-3.14159265316 -0.0 -0.0" xyz="-1.9971412865e-11 3.9418704065e-12 -0.056579685"/>
      <geometry>
        <cylinder length="0.09496663" radius="0.0276743"/>
      </geometry>
      <material name="grey"/>
    </visual>
    <collision>
      <origin rpy="-3.14159265316 -0.0 -0.0" xyz="-1.9971412865e-11 3.9418704065e-12 -0.056579685"/>
      <geometry>
        <cylinder length="0.09496663" radius="0.0276743"/>
      </geometry>
    </collision>
  </link>
  <!-- /links -->
  <!-- joints -->
  <joint name="j_arm1_8" type="revolute">
    <parent link="arm1_7"/>
    <child link="arm1_8"/>
    <origin rpy="0.0 3.14159265359 -1.5707963268" xyz="0.0 0.0 -0.0405"/>
    <axis xyz="1 0 0"/>
    <limit effort="0" lower="0.0" upper="0" velocity="0"/>
  </joint>
   --&gt;

  <!-- /joints -->
  <!-- /end-effector -->
  <!-- LINKS -->
  <!-- shoulder yaw-roll-->
  <link name="arm2_1">
    <inertial>
      <origin xyz="-0.0031005886 -0.040324584 0.007451937"/>
      <mass value="1.5583338"/>
      <inertia ixx="0.0032318636" ixy="-4.24587e-05" ixz="4.91626e-05" iyy="0.00275718" iyz="0.0002387056" izz="0.004275047"/>
    </inertial>
    <visual>
      <origin rpy="-1.43215510177 1.49033190729 -1.3529023596" xyz="-0.0048142 -0.05214035 0.009074915"/>
      <geometry>
        <cylinder length="0.0751108222021" radius="0.0704036"/>
      </geometry>
      <material name="blue"/>
    </visual>
    <collision>
      <origin rpy="-1.43215510177 1.49033190729 -1.3529023596" xyz="-0.0048142 -0.05214035 0.009074915"/>
      <geometry>
        <cylinder length="0.0751108222021" radius="0.0704036"/>
      </geometry>
      <material name="blue"/>
    </collision>
  </link>
  <!-- shoulder yaw-roll-->
  <!-- shoulder roll-pitch-->
  <link name="arm2_2">
    <inertial>
      <origin xyz="0.05105435 -0.00011109 -0.07643596"/>
      <mass value="1.515061"/>
      <inertia ixx="0.01029558" ixy="-2.846e-05" ixz="0.0036567" iyy="0.01178018" iyz="-2.088e-05" izz="0.00386123"/>
    </inertial>
    <visual>
      <origin rpy="-3.14155533114 0.292918451701 -3.14133964661" xyz="0.0709568 7.98629e-06 -0.08709620665"/>
      <geometry>
        <cylinder length="0.181861949629" radius="0.0715161"/>
      </geometry>
      <material name="grey"/>
    </visual>
    <collision>
      <origin rpy="-3.14155533114 0.292918451701 -3.14133964661" xyz="0.0709568 7.98629e-06 -0.08709620665"/>
      <geometry>
        <cylinder length="0.181861949629" radius="0.0715161"/>
      </geometry>
      <material name="grey"/>
    </collision>
  </link>
  <!-- shoulder roll-pitch-->
  <!-- shoulder-elbow -->
  <link name="arm2_3">
    <inertial>
      <origin xyz="0.01207624 -0.00322013 -0.03427312"/>
      <mass value="1.5088101"/>
      <inertia ixx="0.00469819" ixy="0.00026547" ixz="0.00077706" iyy="0.00501755" iyz="-0.00029679" izz="0.00310954"/>
    </inertial>
    <visual>
      <origin rpy="3.12082286426 0.376309803205 3.03261579115" xyz="0.011726993 -0.000587176 -0.036774245"/>
      <geometry>
        <cylinder length="0.0663641129654" radius="0.0864441"/>
      </geometry>
      <material name="blue"/>
    </visual>
    <collision>
      <origin rpy="3.12082286426 0.376309803205 3.03261579115" xyz="0.011726993 -0.000587176 -0.036774245"/>
      <geometry>
        <cylinder length="0.0663641129654" radius="0.0864441"/>
      </geometry>
      <material name="blue"/>
    </collision>
  </link>
  <!-- /shoulder-elbow -->
  <!-- elbow yaw-pitch -->
  <link name="arm2_4">
    <inertial>
      <origin xyz="0.010147552 0.029928537 -0.032528288"/>
      <mass value="0.96297329"/>
      <inertia ixx="0.0026493567" ixy="-5.1632e-06" ixz="0.0001292309" iyy="0.0023470955" iyz="0.0007895755" izz="0.0012213063"/>
    </inertial>
    <visual>
      <origin rpy="0.495925898415 0.203809792245 0.0517669672272" xyz="-0.007494375 0.03766645 -0.032153375"/>
      <geometry>
        <cylinder length="0.086188245518" radius="0.0644525"/>
      </geometry>
      <material name="grey"/>
    </visual>
    <collision>
      <origin rpy="0.495925898415 0.203809792245 0.0517669672272" xyz="-0.007494375 0.03766645 -0.032153375"/>
      <geometry>
        <cylinder length="0.086188245518" radius="0.0644525"/>
      </geometry>
      <material name="grey"/>
    </collision>
  </link>
  <!-- /elbow yaw-pitch -->
  <!-- elbow-wrist -->
  <link name="arm2_5">
    <inertial>
      <origin xyz="-0.0001574443 -0.0041320907 -0.10756614"/>
      <mass value="1.4703698"/>
      <inertia ixx="0.0064160453" ixy="-1.96382e-05" ixz="2.49912e-05" iyy="0.0062016367" iyz="0.0001987903" izz="0.0017091658"/>
    </inertial>
    <visual>
      <origin rpy="0.0568462554593 0.000100286628987 2.85122752006e-06" xyz="-1.864335e-05 -0.002166045 -0.1129697"/>
      <geometry>
        <cylinder length="0.117011611001" radius="0.066519"/>
      </geometry>
      <material name="blue"/>
    </visual>
    <collision>
      <origin rpy="0.0568462554593 0.000100286628987 2.85122752006e-06" xyz="-1.864335e-05 -0.002166045 -0.1129697"/>
      <geometry>
        <cylinder length="0.117011611001" radius="0.066519"/>
      </geometry>
      <material name="blue"/>
    </collision>
  </link>
  <!-- /elbow-wrist -->
  <!-- wrist yaw-pitch -->
  <link name="arm2_6">
    <inertial>
      <origin xyz="3.23645e-05 0.035947237 -0.080878061"/>
      <mass value="0.94693868"/>
      <inertia ixx="0.0036896582" ixy="-2.63667e-05" ixz="1.4005e-06" iyy="0.0034146283" iyz="0.0008268103" izz="0.0010790183"/>
    </inertial>
    <visual>
      <origin rpy="-2.84203235611 -0.00109442040711 0.00725209173511" xyz="-6.44753e-05 0.0278815 -0.067420365"/>
      <geometry>
        <cylinder length="0.145199624103" radius="0.0470691"/>
      </geometry>
      <material name="grey"/>
    </visual>
    <collision>
      <origin rpy="-2.84203235611 -0.00109442040711 0.00725209173511" xyz="-6.44753e-05 0.0278815 -0.067420365"/>
      <geometry>
        <cylinder length="0.145199624103" radius="0.0470691"/>
      </geometry>
      <material name="grey"/>
    </collision>
  </link>
  <!-- /wrist yaw-pitch -->
  <link name="arm2_7">
    <inertial>
      <origin xyz="2.46596e-05 0.0001467705 -0.0052993013"/>
      <mass value="0.55981036"/>
      <inertia ixx="0.0004360175" ixy="-1.397e-07" ixz="-1.382e-07" iyy="0.0004299166" iyz="1.4752e-06" izz="0.0004522224"/>
    </inertial>
    <visual>
      <origin rpy="0.0 0.0 0.0" xyz="0.0 0.0 -0.020"/>
      <geometry>
        <box size="0.05 0.05 0.05"/>
      </geometry>
      <material name="blue"/>
    </visual>
    <collision>
      <origin rpy="0.0 0.0 0.0" xyz="0.0 0.0 -0.020"/>
      <geometry>
        <box size="0.05 0.05 0.05"/>
      </geometry>
      <material name="blue"/>
    </collision>
  </link>
  <!-- /LINKS -->
  <!-- JOINTS -->
  <!-- shoulder yaw -->
  <joint name="j_arm2_1" type="revolute">
    <parent link="torso_2"/>
    <child link="arm2_1"/>
    <origin rpy="0.0 0.0 0.523602668986" xyz="0.04576 -0.169137 0.190626"/>
    <axis xyz="0 -0.984807753012 0.173648177667"/>
    <limit effort="147" lower="-1.658" upper="3.403" velocity="5.7"/>
  </joint>
  <!-- /shoulder yaw -->
  <!-- shoulder roll -->
  <joint name="j_arm2_2" type="revolute">
    <parent link="arm2_1"/>
    <child link="arm2_2"/>
    <origin xyz="-0.09115 -0.06106 0.010766"/>
    <axis xyz="-1 0 0"/>
    <limit effort="147" lower="0" upper="3.49" velocity="5.7"/>
  </joint>
  <!-- /shoulder roll -->
  <!-- shoulder pitch-->
  <joint name="j_arm2_3" type="revolute">
    <parent link="arm2_2"/>
    <child link="arm2_3"/>
    <origin xyz="0.09115 0.0 -0.21915"/>
    <axis xyz="0 0 -1"/>
    <limit effort="147" lower="-2.618" upper="2.618" velocity="8.2"/>
  </joint>
  <!-- /shoulder pitch -->
  <!-- elbow yaw -->
  <joint name="j_arm2_4" type="revolute">
    <parent link="arm2_3"/>
    <child link="arm2_4"/>
    <origin xyz="0.04 -0.05615 -0.074"/>
    <axis xyz="0 -1 0"/>
    <limit effort="147" lower="-0.349" upper="2.530" velocity="8.2"/>
  </joint>
  <!-- /elbow yaw -->
  <!-- elbow pitch-->
  <joint name="j_arm2_5" type="revolute">
    <parent link="arm2_4"/>
    <child link="arm2_5"/>
    <origin xyz="-0.015 0.05615 -0.061"/>
    <axis xyz="0 0 -1"/>
    <limit effort="55" lower="-2.618" upper="2.618" velocity="11.6"/>
  </joint>
  <!-- /elbow pitch-->
  <!-- wrist yaw-->
  <joint name="j_arm2_6" type="revolute">
    <parent link="arm2_5"/>
    <child link="arm2_6"/>
    <origin xyz="0.0 -0.049 -0.18"/>
    <axis xyz="0 -1 0"/>
    <limit effort="55" lower="-1.570" upper="1.570" velocity="11.6"/>
  </joint>
  <!-- /wrist yaw-->
  <!-- wrist pitch-->
  <joint name="j_arm2_7" type="revolute">
    <parent link="arm2_6"/>
    <child link="arm2_7"/>
    <origin xyz="0.0 0.049 -0.169"/>
    <axis xyz="0 0 -1"/>
    <limit effort="27" lower="-2.618" upper="2.618" velocity="20.3"/>
  </joint>
  <!-- wrist pitch-->
  <!-- force-troque sensor -->
  <transmission name="t_j_arm2_1">
    <type> transmission_interface/SimpleTransmission</type>
    <joint name="j_arm2_1">
      <hardwareInterface>EffortJointInterface</hardwareInterface>
    </joint>
    <actuator name="motor_j_arm2_1">
      <hardwareInterface>EffortJointInterface</hardwareInterface>
      <machanicalReduction>1</machanicalReduction>
    </actuator>
    <robotNamespace>/centauro</robotNamespace>
  </transmission>
  <transmission name="t_j_arm2_2">
    <type> transmission_interface/SimpleTransmission</type>
    <joint name="j_arm2_2">
      <hardwareInterface>EffortJointInterface</hardwareInterface>
    </joint>
    <actuator name="motor_j_arm2_2">
      <hardwareInterface>EffortJointInterface</hardwareInterface>
      <machanicalReduction>1</machanicalReduction>
    </actuator>
    <robotNamespace>/centauro</robotNamespace>
  </transmission>
  <transmission name="t_j_arm2_3">
    <type> transmission_interface/SimpleTransmission</type>
    <joint name="j_arm2_3">
      <hardwareInterface>EffortJointInterface</hardwareInterface>
    </joint>
    <actuator name="motor_j_arm2_3">
      <hardwareInterface>EffortJointInterface</hardwareInterface>
      <machanicalReduction>1</machanicalReduction>
    </actuator>
    <robotNamespace>/centauro</robotNamespace>
  </transmission>
  <transmission name="t_j_arm2_4">
    <type> transmission_interface/SimpleTransmission</type>
    <joint name="j_arm2_4">
      <hardwareInterface>EffortJointInterface</hardwareInterface>
    </joint>
    <actuator name="motor_j_arm2_4">
      <hardwareInterface>EffortJointInterface</hardwareInterface>
      <machanicalReduction>1</machanicalReduction>
    </actuator>
    <robotNamespace>/centauro</robotNamespace>
  </transmission>
  <transmission name="t_j_arm2_5">
    <type> transmission_interface/SimpleTransmission</type>
    <joint name="j_arm2_5">
      <hardwareInterface>EffortJointInterface</hardwareInterface>
    </joint>
    <actuator name="motor_j_arm2_5">
      <hardwareInterface>EffortJointInterface</hardwareInterface>
      <machanicalReduction>1</machanicalReduction>
    </actuator>
    <robotNamespace>/centauro</robotNamespace>
  </transmission>
  <transmission name="t_j_arm2_6">
    <type> transmission_interface/SimpleTransmission</type>
    <joint name="j_arm2_6">
      <hardwareInterface>EffortJointInterface</hardwareInterface>
    </joint>
    <actuator name="motor_j_arm2_6">
      <hardwareInterface>EffortJointInterface</hardwareInterface>
      <machanicalReduction>1</machanicalReduction>
    </actuator>
    <robotNamespace>/centauro</robotNamespace>
  </transmission>
  <transmission name="t_j_arm2_7">
    <type> transmission_interface/SimpleTransmission</type>
    <joint name="j_arm2_7">
      <hardwareInterface>EffortJointInterface</hardwareInterface>
    </joint>
    <actuator name="motor_j_arm2_7">
      <hardwareInterface>EffortJointInterface</hardwareInterface>
      <machanicalReduction>1</machanicalReduction>
    </actuator>
    <robotNamespace>/centauro</robotNamespace>
  </transmission>
  <!-- /actuators -->
  <!-- end-effector -->
  <!-- links -->
  <link name="arm2_8">
    <inertial>
      <origin rpy="0 0 0" xyz="0.001 0.0 0.006"/>
      <mass value="0.15"/>
      <inertia ixx="0.0002" ixy="0.0" ixz="0.0" iyy="0.0002" iyz="0.0" izz="1e-05"/>
      <!--          <inertia ixx="0.003"  ixy="0"  ixz="0" iyy="0.0025" iyz="0" izz="0.00016900" /> -->
    </inertial>
    <visual>
      <origin rpy="3.14159265316 -0.0 0.0" xyz="-1.9971412865e-11 -3.9418704065e-12 -0.056579685"/>
      <geometry>
        <cylinder length="0.09496663" radius="0.0276743"/>
      </geometry>
      <material name="grey"/>
    </visual>
    <collision>
      <origin rpy="3.14159265316 -0.0 0.0" xyz="-1.9971412865e-11 -3.9418704065e-12 -0.056579685"/>
      <geometry>
        <cylinder length="0.09496663" radius="0.0276743"/>
      </geometry>
    </collision>
  </link>
  <!-- /links -->
  <!-- joints -->
  <joint name="j_arm2_8" type="revolute">
    <parent link="arm2_7"/>
    <child link="arm2_8"/>
    <origin rpy="0.0 3.14159265359 -1.5707963268" xyz="0.0 0.0 -0.0405"/>
    <axis xyz="1 0 0"/>
    <limit effort="0" lower="0.0" upper="0" velocity="0"/>
  </joint>
   --&gt;

  <!-- /joints -->
  <!-- /end-effector -->
  <!-- /arms -->
  <!-- /legs -->
</robot>
