<?xml version="1.0" ?>
<!-- =================================================================================== -->
<!-- |    This document was autogenerated by xacro from centauro.urdf.xacro            | -->
<!-- |    EDITING THIS FILE BY HAND IS NOT RECOMMENDED                                 | -->
<!-- =================================================================================== -->
<robot name="centauro" xmlns:xacro="http://www.ros.org/wiki/xacro">
  <!-- /constants -->
  <!-- Here all arguments from launch file are evaluated to the final xacro poropeties.
     Also all the parameter dependencies are resolved-->
  <material name="grey">
    <color rgba="0.5 0.5 0.5 1"/>
  </material>
  <material name="dark_grey">
    <color rgba="0.3 0.3 0.3 1"/>
  </material>
  <material name="blue">
    <color rgba="0.0 0.2 0.3 1"/>
  </material>
  <material name="red">
    <color rgba="0.5 0.1 0.2 1"/>
  </material>
  <material name="black">
    <color rgba="0.0 0.0 0.0 1"/>
  </material>
  <!-- Here all arguments from launch file are evaluated to the final xacro poropeties.
     Also all the parameter dependencies are resolved-->
  <!-- load proper collision model -->
  <!-- load proper collision model -->
  <!-- Here all arguments from launch file are evaluated to the final xacro poropeties.
     Also all the parameter dependencies are resolved-->
  <!-- load proper collision model -->
  <!-- load proper collision model -->
  <!-- /macro legs -->
  <!-- /macro arms -->
  <!-- /other files -->
  <!-- reference -->
  <link name="world"/>
  <link name="pelvis">
    <inertial>
      <origin xyz="-0.0704 0.0 -0.0416"/>
      <mass value="25.0"/>
      <inertia ixx="0.242311" ixy="0.0" ixz="0.0" iyy="1.338707" iyz="0.0" izz="1.369479"/>
    </inertial>
    <visual>
      <origin rpy="0.0 0.0 0.0" xyz="0 0 0"/>
      <geometry>
        <box size="0.70 0.40 0.20"/>
      </geometry>
      <material name="grey"/>
    </visual>
    <collision>
      <origin rpy="0.0 0.0 0.0" xyz="0 0 0"/>
      <geometry>
        <box size="0.70 0.40 0.20"/>
      </geometry>
      <material name="grey"/>
    </collision>
  </link>
  <joint name="reference" type="floating">
    <origin xyz="0.0 0.0 0.85"/>
    <parent link="world"/>
    <child link="pelvis"/>
  </joint>
  <!-- /reference  -->
  <!-- torso links -->
  <link name="torso_2">
    <inertial>
      <origin xyz="0.0047281261 0.00038307386 0.14972892"/>
      <mass value="4.5494226"/>
      <!-- mass  7: torso_1 (2) + torso_2 (5), head un_modelled -->
      <inertia ixx="0.063643392" ixy="8.939e-05" ixz="-0.00086873" iyy="0.02680235" iyz="-4.657e-05" izz="0.04743015"/>
    </inertial>
    <visual>
      <origin rpy="0.0 0.0 0.0" xyz="0.0 0 0.0"/>
      <geometry>
        <mesh filename="package://centauro/centauro_urdf/meshes/link1.stl" scale="0.001 0.001 0.001"/>
      </geometry>
      <material name="grey"/>
    </visual>
    <collision>
      <origin rpy="0.0 0.0 0.0" xyz="0.0 0 0.0"/>
      <geometry>
        <mesh filename="package://centauro/centauro_urdf/meshes/link1.stl" scale="0.001 0.001 0.001"/>
      </geometry>
      <material name="grey"/>
    </collision>
  </link>
  <link name="imu_link">
    <inertial>
      <mass value="0.0"/>
      <!-- mass  7: torso_1 (2) + torso_2 (5), head un_modelled -->
      <inertia ixx="0.0" ixy="0.0" ixz="0.0" iyy="0.0" iyz="0.0" izz="0.0"/>
    </inertial>
  </link>
  <!-- /torso links -->
  <!-- torso joints -->
  <joint name="torso_yaw" type="revolute">
    <parent link="pelvis"/>
    <origin xyz="0.3 0.0 0.1"/>
    <child link="torso_2"/>
    <axis xyz="0 0 1"/>
    <limit effort="147" lower="-2.618" upper="2.618" velocity="5.7"/>
    <!-- TODO -->
  </joint>
  <joint name="imu_joint" type="fixed">
    <parent link="pelvis"/>
    <origin xyz="-0.0704 0.0 -0.0416"/>
    <child link="imu_link"/>
  </joint>
  <!-- /torso joints -->
  <transmission name="t_torso_yaw">
    <type> transmission_interface/SimpleTransmission</type>
    <joint name="torso_yaw">
      <hardwareInterface>EffortJointInterface</hardwareInterface>
    </joint>
    <actuator name="motor_torso_yaw">
      <hardwareInterface>EffortJointInterface</hardwareInterface>
      <machanicalReduction>1</machanicalReduction>
    </actuator>
    <robotNamespace>/centauro</robotNamespace>
  </transmission>
  <!-- /torso actuators -->
  <!-- /torso -->
  <!-- LINKS -->
  <!-- shoulder yaw-roll-->
  <link name="arm1_1">
    <inertial>
      <origin xyz="-0.0031005886 0.040324584 0.007451937"/>
      <mass value="1.5583338"/>
      <inertia ixx="0.0032318636" ixy="4.24587e-05" ixz="4.91626e-05" iyy="0.00275718" iyz="-0.0002387056" izz="0.004275047"/>
    </inertial>
    <visual>
      <origin rpy="0.0 0.0 0.0" xyz="0.0 0.0 0.0"/>
      <geometry>
        <mesh filename="package://centauro/centauro_urdf/meshes/link2.stl" scale="0.001 -0.001 0.001"/>
      </geometry>
      <material name="blue"/>
    </visual>
    <collision>
      <origin rpy="0.0 0.0 0.0" xyz="0.0 0.0 0.0"/>
      <geometry>
        <mesh filename="package://centauro/centauro_urdf/meshes/link2.stl" scale="0.001 -0.001 0.001"/>
      </geometry>
      <material name="blue"/>
    </collision>
  </link>
  <!-- shoulder yaw-roll-->
  <!-- shoulder roll-pitch-->
  <link name="arm1_2">
    <inertial>
      <origin xyz="0.05105435 0.00011109 -0.07643596"/>
      <mass value="1.515061"/>
      <inertia ixx="0.01029558" ixy="2.846e-05" ixz="0.0036567" iyy="0.01178018" iyz="2.088e-05" izz="0.00386123"/>
    </inertial>
    <visual>
      <origin rpy="0.0 0.0 0.0" xyz="0.0 0.0 0.0"/>
      <geometry>
        <mesh filename="package://centauro/centauro_urdf/meshes/link3.stl" scale="0.001 -0.001 0.001"/>
      </geometry>
      <material name="grey"/>
    </visual>
    <collision>
      <origin rpy="0.0 0.0 0.0" xyz="0.0 0.0 0.0"/>
      <geometry>
        <mesh filename="package://centauro/centauro_urdf/meshes/link3.stl" scale="0.001 -0.001 0.001"/>
      </geometry>
      <material name="grey"/>
    </collision>
  </link>
  <!-- shoulder roll-pitch-->
  <!-- shoulder-elbow -->
  <link name="arm1_3">
    <inertial>
      <origin xyz="0.01207624 0.00322013 -0.03427312"/>
      <mass value="1.5088101"/>
      <inertia ixx="0.00469819" ixy="-0.00026547" ixz="0.00077706" iyy="0.00501755" iyz="0.00029679" izz="0.00310954"/>
    </inertial>
    <visual>
      <origin rpy="0.0 0.0 0.0" xyz="0.0 0.0 0.0"/>
      <geometry>
        <mesh filename="package://centauro/centauro_urdf/meshes/link4.stl" scale="0.001 -0.001 0.001"/>
      </geometry>
      <material name="blue"/>
    </visual>
    <collision>
      <origin rpy="0.0 0.0 0.0" xyz="0.0 0.0 0.0"/>
      <geometry>
        <mesh filename="package://centauro/centauro_urdf/meshes/link4.stl" scale="0.001 -0.001 0.001"/>
      </geometry>
      <material name="blue"/>
    </collision>
  </link>
  <!-- /shoulder-elbow -->
  <!-- elbow yaw-pitch -->
  <link name="arm1_4">
    <inertial>
      <origin xyz="0.010147552 -0.029928537 -0.032528288"/>
      <mass value="0.96297329"/>
      <inertia ixx="0.0026493567" ixy="5.1632e-06" ixz="0.0001292309" iyy="0.0023470955" iyz="-0.0007895755" izz="0.0012213063"/>
    </inertial>
    <visual>
      <origin rpy="0.0 0.0 0.0" xyz="0.0 0.0 0.0"/>
      <geometry>
        <mesh filename="package://centauro/centauro_urdf/meshes/link5.stl" scale="0.001 -0.001 0.001"/>
      </geometry>
      <material name="grey"/>
    </visual>
    <collision>
      <origin rpy="0.0 0.0 0.0" xyz="0.0 0.0 0.0"/>
      <geometry>
        <mesh filename="package://centauro/centauro_urdf/meshes/link5.stl" scale="0.001 -0.001 0.001"/>
      </geometry>
      <material name="grey"/>
    </collision>
  </link>
  <!-- /elbow yaw-pitch -->
  <!-- elbow-wrist -->
  <link name="arm1_5">
    <inertial>
      <origin xyz="-0.0001574443 0.0041320907 -0.10756614"/>
      <mass value="1.4703698"/>
      <inertia ixx="0.0064160453" ixy="1.96382e-05" ixz="2.49912e-05" iyy="0.0062016367" iyz="-0.0001987903" izz="0.0017091658"/>
    </inertial>
    <visual>
      <origin rpy="0.0 0.0 0.0" xyz="0.0 0.0 0.0"/>
      <geometry>
        <mesh filename="package://centauro/centauro_urdf/meshes/link6.stl" scale="0.001 -0.001 0.001"/>
      </geometry>
      <material name="blue"/>
    </visual>
    <collision>
      <origin rpy="0.0 0.0 0.0" xyz="0.0 0.0 0.0"/>
      <geometry>
        <mesh filename="package://centauro/centauro_urdf/meshes/link6.stl" scale="0.001 -0.001 0.001"/>
      </geometry>
      <material name="blue"/>
    </collision>
  </link>
  <!-- /elbow-wrist -->
  <!-- wrist yaw-pitch -->
  <link name="arm1_6">
    <inertial>
      <origin xyz="3.23645e-05 -0.035947237 -0.080878061"/>
      <mass value="0.94693868"/>
      <inertia ixx="0.0036896582" ixy="2.63667e-05" ixz="1.4005e-06" iyy="0.0034146283" iyz="-0.0008268103" izz="0.0010790183"/>
    </inertial>
    <visual>
      <origin rpy="0.0 0.0 0.0" xyz="0.0 0.0 0.0"/>
      <geometry>
        <mesh filename="package://centauro/centauro_urdf/meshes/link7.stl" scale="0.001 -0.001 0.001"/>
      </geometry>
      <material name="grey"/>
    </visual>
    <collision>
      <origin rpy="0.0 0.0 0.0" xyz="0.0 0.0 0.0"/>
      <geometry>
        <mesh filename="package://centauro/centauro_urdf/meshes/link7.stl" scale="0.001 -0.001 0.001"/>
      </geometry>
      <material name="grey"/>
    </collision>
  </link>
  <!-- /wrist yaw-pitch -->
  <link name="arm1_7">
    <inertial>
      <origin xyz="2.46596e-05 -0.0001467705 -0.0052993013"/>
      <mass value="0.55981036"/>
      <inertia ixx="0.0004360175" ixy="1.397e-07" ixz="-1.382e-07" iyy="0.0004299166" iyz="-1.4752e-06" izz="0.0004522224"/>
    </inertial>
    <visual>
      <origin rpy="0.0 0.0 0.0" xyz="0.0 0.0 0.0"/>
      <geometry>
        <mesh filename="package://centauro/centauro_urdf/meshes/link8.stl" scale="0.001 -0.001 0.001"/>
      </geometry>
      <material name="blue"/>
    </visual>
    <collision>
      <origin rpy="0.0 0.0 0.0" xyz="0.0 0.0 0.0"/>
      <geometry>
        <mesh filename="package://centauro/centauro_urdf/meshes/link8.stl" scale="0.001 -0.001 0.001"/>
      </geometry>
      <material name="blue"/>
    </collision>
  </link>
  <!-- /LINKS -->
  <!-- JOINTS -->
  <!-- shoulder yaw -->
  <joint name="j_arm1_1" type="revolute">
    <parent link="torso_2"/>
    <child link="arm1_1"/>
    <origin rpy="0.0 0.0 -0.523602668986" xyz="0.04576 0.169137 0.190626"/>
    <axis xyz="0 0.984807753012 0.173648177667"/>
    <limit effort="147" lower="-3.403" upper="1.658" velocity="5.7"/>
  </joint>
  <!-- /shoulder yaw -->
  <!-- shoulder roll -->
  <joint name="j_arm1_2" type="revolute">
    <parent link="arm1_1"/>
    <child link="arm1_2"/>
    <origin xyz="-0.09115 0.06106 0.010766"/>
    <axis xyz="-1 0 0"/>
    <limit effort="147" lower="-3.49" upper="0" velocity="5.7"/>
  </joint>
  <!-- /shoulder roll -->
  <!-- shoulder pitch-->
  <joint name="j_arm1_3" type="revolute">
    <parent link="arm1_2"/>
    <child link="arm1_3"/>
    <origin xyz="0.09115 0.0 -0.21915"/>
    <axis xyz="0 0 -1"/>
    <limit effort="147" lower="-2.618" upper="2.618" velocity="8.2"/>
  </joint>
  <!-- /shoulder pitch -->
  <!-- elbow yaw -->
  <joint name="j_arm1_4" type="revolute">
    <parent link="arm1_3"/>
    <child link="arm1_4"/>
    <origin xyz="0.04 0.05615 -0.074"/>
    <axis xyz="0 1 0"/>
    <limit effort="147" lower="-2.530" upper="0.349" velocity="8.2"/>
  </joint>
  <!-- /elbow yaw -->
  <!-- elbow pitch-->
  <joint name="j_arm1_5" type="revolute">
    <parent link="arm1_4"/>
    <child link="arm1_5"/>
    <origin xyz="-0.015 -0.05615 -0.061"/>
    <axis xyz="0 0 -1"/>
    <limit effort="55" lower="-2.618" upper="2.618" velocity="11.6"/>
  </joint>
  <!-- /elbow pitch-->
  <!-- wrist yaw-->
  <joint name="j_arm1_6" type="revolute">
    <parent link="arm1_5"/>
    <child link="arm1_6"/>
    <origin xyz="0.0 0.049 -0.18"/>
    <axis xyz="0 1 0"/>
    <limit effort="55" lower="-1.570" upper="1.570" velocity="11.6"/>
  </joint>
  <!-- /wrist yaw-->
  <!-- wrist pitch-->
  <joint name="j_arm1_7" type="revolute">
    <parent link="arm1_6"/>
    <child link="arm1_7"/>
    <origin xyz="0.0 -0.049 -0.169"/>
    <axis xyz="0 0 -1"/>
    <limit effort="27" lower="-2.618" upper="2.618" velocity="20.3"/>
  </joint>
  <!-- wrist pitch-->
  <!-- force-troque sensor -->
  <transmission name="t_j_arm1_1">
    <type> transmission_interface/SimpleTransmission</type>
    <joint name="j_arm1_1">
      <hardwareInterface>EffortJointInterface</hardwareInterface>
    </joint>
    <actuator name="motor_j_arm1_1">
      <hardwareInterface>EffortJointInterface</hardwareInterface>
      <machanicalReduction>1</machanicalReduction>
    </actuator>
    <robotNamespace>/centauro</robotNamespace>
  </transmission>
  <transmission name="t_j_arm1_2">
    <type> transmission_interface/SimpleTransmission</type>
    <joint name="j_arm1_2">
      <hardwareInterface>EffortJointInterface</hardwareInterface>
    </joint>
    <actuator name="motor_j_arm1_2">
      <hardwareInterface>EffortJointInterface</hardwareInterface>
      <machanicalReduction>1</machanicalReduction>
    </actuator>
    <robotNamespace>/centauro</robotNamespace>
  </transmission>
  <transmission name="t_j_arm1_3">
    <type> transmission_interface/SimpleTransmission</type>
    <joint name="j_arm1_3">
      <hardwareInterface>EffortJointInterface</hardwareInterface>
    </joint>
    <actuator name="motor_j_arm1_3">
      <hardwareInterface>EffortJointInterface</hardwareInterface>
      <machanicalReduction>1</machanicalReduction>
    </actuator>
    <robotNamespace>/centauro</robotNamespace>
  </transmission>
  <transmission name="t_j_arm1_4">
    <type> transmission_interface/SimpleTransmission</type>
    <joint name="j_arm1_4">
      <hardwareInterface>EffortJointInterface</hardwareInterface>
    </joint>
    <actuator name="motor_j_arm1_4">
      <hardwareInterface>EffortJointInterface</hardwareInterface>
      <machanicalReduction>1</machanicalReduction>
    </actuator>
    <robotNamespace>/centauro</robotNamespace>
  </transmission>
  <transmission name="t_j_arm1_5">
    <type> transmission_interface/SimpleTransmission</type>
    <joint name="j_arm1_5">
      <hardwareInterface>EffortJointInterface</hardwareInterface>
    </joint>
    <actuator name="motor_j_arm1_5">
      <hardwareInterface>EffortJointInterface</hardwareInterface>
      <machanicalReduction>1</machanicalReduction>
    </actuator>
    <robotNamespace>/centauro</robotNamespace>
  </transmission>
  <transmission name="t_j_arm1_6">
    <type> transmission_interface/SimpleTransmission</type>
    <joint name="j_arm1_6">
      <hardwareInterface>EffortJointInterface</hardwareInterface>
    </joint>
    <actuator name="motor_j_arm1_6">
      <hardwareInterface>EffortJointInterface</hardwareInterface>
      <machanicalReduction>1</machanicalReduction>
    </actuator>
    <robotNamespace>/centauro</robotNamespace>
  </transmission>
  <transmission name="t_j_arm1_7">
    <type> transmission_interface/SimpleTransmission</type>
    <joint name="j_arm1_7">
      <hardwareInterface>EffortJointInterface</hardwareInterface>
    </joint>
    <actuator name="motor_j_arm1_7">
      <hardwareInterface>EffortJointInterface</hardwareInterface>
      <machanicalReduction>1</machanicalReduction>
    </actuator>
    <robotNamespace>/centauro</robotNamespace>
  </transmission>
  <!-- /actuators -->
  <!-- end-effector -->
  <!-- links -->
  <link name="arm1_8">
    <inertial>
      <origin rpy="0 0 0" xyz="0.001 0.0 0.006"/>
      <mass value="0.15"/>
      <inertia ixx="0.0002" ixy="0.0" ixz="0.0" iyy="0.0002" iyz="0.0" izz="1e-05"/>
      <!--          <inertia ixx="0.003"  ixy="0"  ixz="0" iyy="0.0025" iyz="0" izz="0.00016900" /> -->
    </inertial>
    <visual>
      <origin rpy="0.0 0.0 0.0" xyz="0.0 0.0 0.0"/>
      <geometry>
        <mesh filename="package://centauro/centauro_urdf/meshes/link9.stl" scale="0.001 -0.001 -0.001"/>
      </geometry>
      <material name="grey"/>
    </visual>
    <collision>
      <origin rpy="0.0 0.0 0.0" xyz="0.0 0.0 0.0"/>
      <geometry>
        <mesh filename="package://centauro/centauro_urdf/meshes/link9.stl" scale="0.001 -0.001 -0.001"/>
      </geometry>
    </collision>
  </link>
  <!-- /links -->
  <!-- joints -->
  <joint name="j_arm1_8" type="fixed">
    <parent link="arm1_7"/>
    <child link="arm1_8"/>
    <origin rpy="0.0 3.14159265359 -1.5707963268" xyz="0.0 0.0 -0.0405"/>
    <axis xyz="1 0 0"/>
    <limit effort="0" lower="0.0" upper="0" velocity="0"/>
  </joint>
   --&gt;

  <!-- /joints -->
  <!-- /end-effector -->
  <!-- LINKS -->
  <!-- shoulder yaw-roll-->
  <link name="arm2_1">
    <inertial>
      <origin xyz="-0.0031005886 -0.040324584 0.007451937"/>
      <mass value="1.5583338"/>
      <inertia ixx="0.0032318636" ixy="-4.24587e-05" ixz="4.91626e-05" iyy="0.00275718" iyz="0.0002387056" izz="0.004275047"/>
    </inertial>
    <visual>
      <origin rpy="0.0 0.0 0.0" xyz="0.0 0.0 0.0"/>
      <geometry>
        <mesh filename="package://centauro/centauro_urdf/meshes/link2.stl" scale="0.001 0.001 0.001"/>
      </geometry>
      <material name="blue"/>
    </visual>
    <collision>
      <origin rpy="0.0 0.0 0.0" xyz="0.0 0.0 0.0"/>
      <geometry>
        <mesh filename="package://centauro/centauro_urdf/meshes/link2.stl" scale="0.001 0.001 0.001"/>
      </geometry>
      <material name="blue"/>
    </collision>
  </link>
  <!-- shoulder yaw-roll-->
  <!-- shoulder roll-pitch-->
  <link name="arm2_2">
    <inertial>
      <origin xyz="0.05105435 -0.00011109 -0.07643596"/>
      <mass value="1.515061"/>
      <inertia ixx="0.01029558" ixy="-2.846e-05" ixz="0.0036567" iyy="0.01178018" iyz="-2.088e-05" izz="0.00386123"/>
    </inertial>
    <visual>
      <origin rpy="0.0 0.0 0.0" xyz="0.0 0.0 0.0"/>
      <geometry>
        <mesh filename="package://centauro/centauro_urdf/meshes/link3.stl" scale="0.001 0.001 0.001"/>
      </geometry>
      <material name="grey"/>
    </visual>
    <collision>
      <origin rpy="0.0 0.0 0.0" xyz="0.0 0.0 0.0"/>
      <geometry>
        <mesh filename="package://centauro/centauro_urdf/meshes/link3.stl" scale="0.001 0.001 0.001"/>
      </geometry>
      <material name="grey"/>
    </collision>
  </link>
  <!-- shoulder roll-pitch-->
  <!-- shoulder-elbow -->
  <link name="arm2_3">
    <inertial>
      <origin xyz="0.01207624 -0.00322013 -0.03427312"/>
      <mass value="1.5088101"/>
      <inertia ixx="0.00469819" ixy="0.00026547" ixz="0.00077706" iyy="0.00501755" iyz="-0.00029679" izz="0.00310954"/>
    </inertial>
    <visual>
      <origin rpy="0.0 0.0 0.0" xyz="0.0 0.0 0.0"/>
      <geometry>
        <mesh filename="package://centauro/centauro_urdf/meshes/link4.stl" scale="0.001 0.001 0.001"/>
      </geometry>
      <material name="blue"/>
    </visual>
    <collision>
      <origin rpy="0.0 0.0 0.0" xyz="0.0 0.0 0.0"/>
      <geometry>
        <mesh filename="package://centauro/centauro_urdf/meshes/link4.stl" scale="0.001 0.001 0.001"/>
      </geometry>
      <material name="blue"/>
    </collision>
  </link>
  <!-- /shoulder-elbow -->
  <!-- elbow yaw-pitch -->
  <link name="arm2_4">
    <inertial>
      <origin xyz="0.010147552 0.029928537 -0.032528288"/>
      <mass value="0.96297329"/>
      <inertia ixx="0.0026493567" ixy="-5.1632e-06" ixz="0.0001292309" iyy="0.0023470955" iyz="0.0007895755" izz="0.0012213063"/>
    </inertial>
    <visual>
      <origin rpy="0.0 0.0 0.0" xyz="0.0 0.0 0.0"/>
      <geometry>
        <mesh filename="package://centauro/centauro_urdf/meshes/link5.stl" scale="0.001 0.001 0.001"/>
      </geometry>
      <material name="grey"/>
    </visual>
    <collision>
      <origin rpy="0.0 0.0 0.0" xyz="0.0 0.0 0.0"/>
      <geometry>
        <mesh filename="package://centauro/centauro_urdf/meshes/link5.stl" scale="0.001 0.001 0.001"/>
      </geometry>
      <material name="grey"/>
    </collision>
  </link>
  <!-- /elbow yaw-pitch -->
  <!-- elbow-wrist -->
  <link name="arm2_5">
    <inertial>
      <origin xyz="-0.0001574443 -0.0041320907 -0.10756614"/>
      <mass value="1.4703698"/>
      <inertia ixx="0.0064160453" ixy="-1.96382e-05" ixz="2.49912e-05" iyy="0.0062016367" iyz="0.0001987903" izz="0.0017091658"/>
    </inertial>
    <visual>
      <origin rpy="0.0 0.0 0.0" xyz="0.0 0.0 0.0"/>
      <geometry>
        <mesh filename="package://centauro/centauro_urdf/meshes/link6.stl" scale="0.001 0.001 0.001"/>
      </geometry>
      <material name="blue"/>
    </visual>
    <collision>
      <origin rpy="0.0 0.0 0.0" xyz="0.0 0.0 0.0"/>
      <geometry>
        <mesh filename="package://centauro/centauro_urdf/meshes/link6.stl" scale="0.001 0.001 0.001"/>
      </geometry>
      <material name="blue"/>
    </collision>
  </link>
  <!-- /elbow-wrist -->
  <!-- wrist yaw-pitch -->
  <link name="arm2_6">
    <inertial>
      <origin xyz="3.23645e-05 0.035947237 -0.080878061"/>
      <mass value="0.94693868"/>
      <inertia ixx="0.0036896582" ixy="-2.63667e-05" ixz="1.4005e-06" iyy="0.0034146283" iyz="0.0008268103" izz="0.0010790183"/>
    </inertial>
    <visual>
      <origin rpy="0.0 0.0 0.0" xyz="0.0 0.0 0.0"/>
      <geometry>
        <mesh filename="package://centauro/centauro_urdf/meshes/link7.stl" scale="0.001 0.001 0.001"/>
      </geometry>
      <material name="grey"/>
    </visual>
    <collision>
      <origin rpy="0.0 0.0 0.0" xyz="0.0 0.0 0.0"/>
      <geometry>
        <mesh filename="package://centauro/centauro_urdf/meshes/link7.stl" scale="0.001 0.001 0.001"/>
      </geometry>
      <material name="grey"/>
    </collision>
  </link>
  <!-- /wrist yaw-pitch -->
  <link name="arm2_7">
    <inertial>
      <origin xyz="2.46596e-05 0.0001467705 -0.0052993013"/>
      <mass value="0.55981036"/>
      <inertia ixx="0.0004360175" ixy="-1.397e-07" ixz="-1.382e-07" iyy="0.0004299166" iyz="1.4752e-06" izz="0.0004522224"/>
    </inertial>
    <visual>
      <origin rpy="0.0 0.0 0.0" xyz="0.0 0.0 0.0"/>
      <geometry>
        <mesh filename="package://centauro/centauro_urdf/meshes/link8.stl" scale="0.001 0.001 0.001"/>
      </geometry>
      <material name="blue"/>
    </visual>
    <collision>
      <origin rpy="0.0 0.0 0.0" xyz="0.0 0.0 0.0"/>
      <geometry>
        <mesh filename="package://centauro/centauro_urdf/meshes/link8.stl" scale="0.001 0.001 0.001"/>
      </geometry>
      <material name="blue"/>
    </collision>
  </link>
  <!-- /LINKS -->
  <!-- JOINTS -->
  <!-- shoulder yaw -->
  <joint name="j_arm2_1" type="revolute">
    <parent link="torso_2"/>
    <child link="arm2_1"/>
    <origin rpy="0.0 0.0 0.523602668986" xyz="0.04576 -0.169137 0.190626"/>
    <axis xyz="0 -0.984807753012 0.173648177667"/>
    <limit effort="147" lower="-1.658" upper="3.403" velocity="5.7"/>
  </joint>
  <!-- /shoulder yaw -->
  <!-- shoulder roll -->
  <joint name="j_arm2_2" type="revolute">
    <parent link="arm2_1"/>
    <child link="arm2_2"/>
    <origin xyz="-0.09115 -0.06106 0.010766"/>
    <axis xyz="-1 0 0"/>
    <limit effort="147" lower="0" upper="3.49" velocity="5.7"/>
  </joint>
  <!-- /shoulder roll -->
  <!-- shoulder pitch-->
  <joint name="j_arm2_3" type="revolute">
    <parent link="arm2_2"/>
    <child link="arm2_3"/>
    <origin xyz="0.09115 0.0 -0.21915"/>
    <axis xyz="0 0 -1"/>
    <limit effort="147" lower="-2.618" upper="2.618" velocity="8.2"/>
  </joint>
  <!-- /shoulder pitch -->
  <!-- elbow yaw -->
  <joint name="j_arm2_4" type="revolute">
    <parent link="arm2_3"/>
    <child link="arm2_4"/>
    <origin xyz="0.04 -0.05615 -0.074"/>
    <axis xyz="0 -1 0"/>
    <limit effort="147" lower="-0.349" upper="2.530" velocity="8.2"/>
  </joint>
  <!-- /elbow yaw -->
  <!-- elbow pitch-->
  <joint name="j_arm2_5" type="revolute">
    <parent link="arm2_4"/>
    <child link="arm2_5"/>
    <origin xyz="-0.015 0.05615 -0.061"/>
    <axis xyz="0 0 -1"/>
    <limit effort="55" lower="-2.618" upper="2.618" velocity="11.6"/>
  </joint>
  <!-- /elbow pitch-->
  <!-- wrist yaw-->
  <joint name="j_arm2_6" type="revolute">
    <parent link="arm2_5"/>
    <child link="arm2_6"/>
    <origin xyz="0.0 -0.049 -0.18"/>
    <axis xyz="0 -1 0"/>
    <limit effort="55" lower="-1.570" upper="1.570" velocity="11.6"/>
  </joint>
  <!-- /wrist yaw-->
  <!-- wrist pitch-->
  <joint name="j_arm2_7" type="revolute">
    <parent link="arm2_6"/>
    <child link="arm2_7"/>
    <origin xyz="0.0 0.049 -0.169"/>
    <axis xyz="0 0 -1"/>
    <limit effort="27" lower="-2.618" upper="2.618" velocity="20.3"/>
  </joint>
  <!-- wrist pitch-->
  <!-- force-troque sensor -->
  <transmission name="t_j_arm2_1">
    <type> transmission_interface/SimpleTransmission</type>
    <joint name="j_arm2_1">
      <hardwareInterface>EffortJointInterface</hardwareInterface>
    </joint>
    <actuator name="motor_j_arm2_1">
      <hardwareInterface>EffortJointInterface</hardwareInterface>
      <machanicalReduction>1</machanicalReduction>
    </actuator>
    <robotNamespace>/centauro</robotNamespace>
  </transmission>
  <transmission name="t_j_arm2_2">
    <type> transmission_interface/SimpleTransmission</type>
    <joint name="j_arm2_2">
      <hardwareInterface>EffortJointInterface</hardwareInterface>
    </joint>
    <actuator name="motor_j_arm2_2">
      <hardwareInterface>EffortJointInterface</hardwareInterface>
      <machanicalReduction>1</machanicalReduction>
    </actuator>
    <robotNamespace>/centauro</robotNamespace>
  </transmission>
  <transmission name="t_j_arm2_3">
    <type> transmission_interface/SimpleTransmission</type>
    <joint name="j_arm2_3">
      <hardwareInterface>EffortJointInterface</hardwareInterface>
    </joint>
    <actuator name="motor_j_arm2_3">
      <hardwareInterface>EffortJointInterface</hardwareInterface>
      <machanicalReduction>1</machanicalReduction>
    </actuator>
    <robotNamespace>/centauro</robotNamespace>
  </transmission>
  <transmission name="t_j_arm2_4">
    <type> transmission_interface/SimpleTransmission</type>
    <joint name="j_arm2_4">
      <hardwareInterface>EffortJointInterface</hardwareInterface>
    </joint>
    <actuator name="motor_j_arm2_4">
      <hardwareInterface>EffortJointInterface</hardwareInterface>
      <machanicalReduction>1</machanicalReduction>
    </actuator>
    <robotNamespace>/centauro</robotNamespace>
  </transmission>
  <transmission name="t_j_arm2_5">
    <type> transmission_interface/SimpleTransmission</type>
    <joint name="j_arm2_5">
      <hardwareInterface>EffortJointInterface</hardwareInterface>
    </joint>
    <actuator name="motor_j_arm2_5">
      <hardwareInterface>EffortJointInterface</hardwareInterface>
      <machanicalReduction>1</machanicalReduction>
    </actuator>
    <robotNamespace>/centauro</robotNamespace>
  </transmission>
  <transmission name="t_j_arm2_6">
    <type> transmission_interface/SimpleTransmission</type>
    <joint name="j_arm2_6">
      <hardwareInterface>EffortJointInterface</hardwareInterface>
    </joint>
    <actuator name="motor_j_arm2_6">
      <hardwareInterface>EffortJointInterface</hardwareInterface>
      <machanicalReduction>1</machanicalReduction>
    </actuator>
    <robotNamespace>/centauro</robotNamespace>
  </transmission>
  <transmission name="t_j_arm2_7">
    <type> transmission_interface/SimpleTransmission</type>
    <joint name="j_arm2_7">
      <hardwareInterface>EffortJointInterface</hardwareInterface>
    </joint>
    <actuator name="motor_j_arm2_7">
      <hardwareInterface>EffortJointInterface</hardwareInterface>
      <machanicalReduction>1</machanicalReduction>
    </actuator>
    <robotNamespace>/centauro</robotNamespace>
  </transmission>
  <!-- /actuators -->
  <!-- end-effector -->
  <!-- links -->
  <link name="arm2_8">
    <inertial>
      <origin rpy="0 0 0" xyz="0.001 0.0 0.006"/>
      <mass value="0.15"/>
      <inertia ixx="0.0002" ixy="0.0" ixz="0.0" iyy="0.0002" iyz="0.0" izz="1e-05"/>
      <!--          <inertia ixx="0.003"  ixy="0"  ixz="0" iyy="0.0025" iyz="0" izz="0.00016900" /> -->
    </inertial>
    <visual>
      <origin rpy="0.0 0.0 0.0" xyz="0.0 0.0 0.0"/>
      <geometry>
        <mesh filename="package://centauro/centauro_urdf/meshes/link9.stl" scale="0.001 0.001 -0.001"/>
      </geometry>
      <material name="grey"/>
    </visual>
    <collision>
      <origin rpy="0.0 0.0 0.0" xyz="0.0 0.0 0.0"/>
      <geometry>
        <mesh filename="package://centauro/centauro_urdf/meshes/link9.stl" scale="0.001 0.001 -0.001"/>
      </geometry>
    </collision>
  </link>
  <!-- /links -->
  <!-- joints -->
  <joint name="j_arm2_8" type="fixed">
    <parent link="arm2_7"/>
    <child link="arm2_8"/>
    <origin rpy="0.0 3.14159265359 -1.5707963268" xyz="0.0 0.0 -0.0405"/>
    <axis xyz="1 0 0"/>
    <limit effort="0" lower="0.0" upper="0" velocity="0"/>
  </joint>
   --&gt;

  <!-- /joints -->
  <!-- /end-effector -->
  <!-- /arms -->
  <link name="hip1_1">
    <inertial>
      <origin xyz="0.0 0.0 -0.175"/>
      <!-- TODO -->
      <mass value="2.0"/>
      <!-- org: 2 -->
      <inertia ixx="0.006237" ixy="0.0" ixz="0.0" iyy="0.005925" iyz="-0.0" izz="0.002488"/>
      <!-- <inertia ixx="0.01" ixy="0.01" ixz="0.01" iyy="0.01" iyz="0.01" izz="0.01"/> -->
    </inertial>
    <visual>
      <origin xyz="0 0 -0.1"/>
      <geometry>
        <box size="0.05 0.05 0.2"/>
        <!-- OK: from hip-yaw to pelvis (0.1) + from plevis to hip-pitch (0.1)-->
      </geometry>
      <material name="grey"/>
    </visual>
    <visual>
      <origin rpy="0 0 0" xyz="0 0 0"/>
      <geometry>
        <cylinder length="0.1" radius="0.05"/>
      </geometry>
      <material name="grey"/>
    </visual>
    <collision>
      <origin xyz="0 0 -0.1"/>
      <geometry>
        <box size="0.05 0.05 0.15"/>
        <!-- OK: from hip-yaw to pelvis (0.1) + from plevis to hip-pitch (0.1)-->
      </geometry>
      <material name="grey"/>
    </collision>
    <!-- <collision>
		<origin xyz="0 0 0" rpy="0 0 0" />
		<geometry>
			<cylinder length="${motors_length}" radius="${motors_radius}"/>
		</geometry>
		<material name="grey"/>
	</collision> -->
  </link>
  <link name="hip2_1">
    <inertial>
      <origin xyz="0.0 0.0 -0.233333"/>
      <mass value="4.5"/>
      <!-- org: 4.5 -->
      <inertia ixx="0.037113" ixy="0.0" ixz="0.0" iyy="0.0368" iyz="-0.0" izz="0.003988"/>
      <!-- <inertia ixx="0.01" ixy="0.01" ixz="0.01" iyy="0.01" iyz="0.01" izz="0.01"/> -->
    </inertial>
    <visual>
      <origin xyz="0 0 -0.175"/>
      <geometry>
        <box size="0.05 0.05 0.35"/>
        <!-- OK -->
      </geometry>
      <material name="blue"/>
    </visual>
    <visual>
      <origin rpy="1.5707963268 0 0" xyz="0 0 0"/>
      <geometry>
        <cylinder length="0.1" radius="0.05"/>
      </geometry>
      <material name="blue"/>
    </visual>
    <collision>
      <origin xyz="0 0 -0.175"/>
      <geometry>
        <box size="0.05 0.05 0.3"/>
        <!-- OK -->
      </geometry>
      <material name="blue"/>
    </collision>
    <!-- <collision>
		<origin xyz="0 0 0" rpy="${PI/2} 0 0" />
		<geometry>
			<cylinder length="${motors_length}" radius="${motors_radius}"/>
		</geometry>
		<material name="blue"/>
	</collision> -->
  </link>
  <link name="knee_1">
    <inertial>
      <origin xyz="0.0 0.0 -0.15"/>
      <!-- TODO -->
      <mass value="3.5"/>
      <!-- org: 3.5, foot un modeled-->
      <inertia ixx="0.004433" ixy="0.0" ixz="0.0" iyy="0.004433" iyz="0.0" izz="0.0021"/>
      <!--	<inertia ixx="0.01" ixy="0.01" ixz="0.01" iyy="0.01" iyz="0.01" izz="0.01"/>  -->
    </inertial>
    <visual>
      <origin xyz="0 0 -0.125"/>
      <geometry>
        <box size="0.05 0.05 0.25"/>
        <!-- OK: foot un modeled-->
      </geometry>
      <material name="grey"/>
    </visual>
    <visual>
      <origin rpy="1.5707963268 0 0" xyz="0 0 0"/>
      <geometry>
        <cylinder length="0.1" radius="0.05"/>
      </geometry>
      <material name="blue"/>
    </visual>
    <visual>
      <origin xyz="0 0 -0.25"/>
      <geometry>
        <sphere radius="0.05"/>
      </geometry>
      <material name="blue"/>
    </visual>
    <collision>
      <origin xyz="0 0 -0.125"/>
      <geometry>
        <box size="0.05 0.05 0.2"/>
        <!-- OK: foot un modeled-->
      </geometry>
      <material name="grey"/>
    </collision>
    <!--	<collision>
		<origin xyz="0 0 0" rpy="${PI/2} 0 0" />
		<geometry>
			<cylinder length="${motors_length}" radius="${motors_radius}"/>
		</geometry>
		<material name="blue"/>
	</collision> -->
    <collision>
      <origin xyz="0 0 -0.25"/>
      <geometry>
        <sphere radius="0.05"/>
      </geometry>
      <material name="blue"/>
    </collision>
  </link>
  <!-- ftsensor -->
  <!--<link name="ft_foot_${leg_num}">
  <inertial>
    <mass value="0.001"/>
    <origin xyz="0 0 0"/>
    <inertia ixx="1.0E-6" ixy="0" ixz="0" iyy="1.0E-6" iyz="0" izz="1.0E-6"/>
  </inertial>
  <visual>
      <origin rpy="0 0 0" xyz="0 0 0"/>
      <geometry>
        <box size="0.01 0.01 0.01"/>
      </geometry>
  </visual>
</link>-->
  <!-- /wheels -->
  <joint name="hip_yaw_1" type="revolute">
    <parent link="pelvis"/>
    <child link="hip1_1"/>
    <origin rpy="0 0 1.5707963268" xyz="0.3 0.15 0"/>
    <axis xyz="0 0 -1"/>
    <limit effort="147" lower="-2.09" upper="2.09" velocity="6.5"/>
    <!-- TODO -->
  </joint>
  <joint name="hip_pitch_1" type="revolute">
    <parent link="hip1_1"/>
    <child link="hip2_1"/>
    <origin xyz="0.0 0.0 -0.2"/>
    <axis xyz="0 -1 0"/>
    <limit effort="330" lower="-3.14" upper="3.14" velocity="6.5"/>
    <!-- TODO -->
  </joint>
  <joint name="knee_pitch_1" type="revolute">
    <parent link="hip2_1"/>
    <child link="knee_1"/>
    <origin xyz="0.0 0.0 -0.35"/>
    <axis xyz="0 -1 0"/>
    <limit effort="330" lower="-3.14" upper="3.14" velocity="6.5"/>
    <!-- TODO -->
  </joint>
  <transmission name="t_hip_yaw_1">
    <type> transmission_interface/SimpleTransmission</type>
    <joint name="hip_yaw_1">
      <hardwareInterface>EffortJointInterface</hardwareInterface>
    </joint>
    <actuator name="motor_hip_yaw_1">
      <hardwareInterface>EffortJointInterface</hardwareInterface>
      <machanicalReduction>1</machanicalReduction>
    </actuator>
    <robotNamespace>/centauro</robotNamespace>
  </transmission>
  <transmission name="t_hip_pitch_1">
    <type> transmission_interface/SimpleTransmission</type>
    <joint name="hip_pitch_1">
      <hardwareInterface>EffortJointInterface</hardwareInterface>
    </joint>
    <actuator name="motor_hip_pitch_1">
      <hardwareInterface>EffortJointInterface</hardwareInterface>
      <machanicalReduction>1</machanicalReduction>
    </actuator>
    <robotNamespace>/centauro</robotNamespace>
  </transmission>
  <transmission name="t_knee_pitch_1">
    <type> transmission_interface/SimpleTransmission</type>
    <joint name="knee_pitch_1">
      <hardwareInterface>EffortJointInterface</hardwareInterface>
    </joint>
    <actuator name="motor_knee_pitch_1">
      <hardwareInterface>EffortJointInterface</hardwareInterface>
      <machanicalReduction>1</machanicalReduction>
    </actuator>
    <robotNamespace>/centauro</robotNamespace>
  </transmission>
  <!-- /actuators -->
  <link name="hip1_2">
    <inertial>
      <origin xyz="0.0 0.0 -0.175"/>
      <!-- TODO -->
      <mass value="2.0"/>
      <!-- org: 2 -->
      <inertia ixx="0.006237" ixy="0.0" ixz="0.0" iyy="0.005925" iyz="-0.0" izz="0.002488"/>
      <!-- <inertia ixx="0.01" ixy="0.01" ixz="0.01" iyy="0.01" iyz="0.01" izz="0.01"/> -->
    </inertial>
    <visual>
      <origin xyz="0 0 -0.1"/>
      <geometry>
        <box size="0.05 0.05 0.2"/>
        <!-- OK: from hip-yaw to pelvis (0.1) + from plevis to hip-pitch (0.1)-->
      </geometry>
      <material name="grey"/>
    </visual>
    <visual>
      <origin rpy="0 0 0" xyz="0 0 0"/>
      <geometry>
        <cylinder length="0.1" radius="0.05"/>
      </geometry>
      <material name="grey"/>
    </visual>
    <collision>
      <origin xyz="0 0 -0.1"/>
      <geometry>
        <box size="0.05 0.05 0.15"/>
        <!-- OK: from hip-yaw to pelvis (0.1) + from plevis to hip-pitch (0.1)-->
      </geometry>
      <material name="grey"/>
    </collision>
    <!-- <collision>
		<origin xyz="0 0 0" rpy="0 0 0" />
		<geometry>
			<cylinder length="${motors_length}" radius="${motors_radius}"/>
		</geometry>
		<material name="grey"/>
	</collision> -->
  </link>
  <link name="hip2_2">
    <inertial>
      <origin xyz="0.0 0.0 -0.233333"/>
      <mass value="4.5"/>
      <!-- org: 4.5 -->
      <inertia ixx="0.037113" ixy="0.0" ixz="0.0" iyy="0.0368" iyz="-0.0" izz="0.003988"/>
      <!-- <inertia ixx="0.01" ixy="0.01" ixz="0.01" iyy="0.01" iyz="0.01" izz="0.01"/> -->
    </inertial>
    <visual>
      <origin xyz="0 0 -0.175"/>
      <geometry>
        <box size="0.05 0.05 0.35"/>
        <!-- OK -->
      </geometry>
      <material name="blue"/>
    </visual>
    <visual>
      <origin rpy="1.5707963268 0 0" xyz="0 0 0"/>
      <geometry>
        <cylinder length="0.1" radius="0.05"/>
      </geometry>
      <material name="blue"/>
    </visual>
    <collision>
      <origin xyz="0 0 -0.175"/>
      <geometry>
        <box size="0.05 0.05 0.3"/>
        <!-- OK -->
      </geometry>
      <material name="blue"/>
    </collision>
    <!-- <collision>
		<origin xyz="0 0 0" rpy="${PI/2} 0 0" />
		<geometry>
			<cylinder length="${motors_length}" radius="${motors_radius}"/>
		</geometry>
		<material name="blue"/>
	</collision> -->
  </link>
  <link name="knee_2">
    <inertial>
      <origin xyz="0.0 0.0 -0.15"/>
      <!-- TODO -->
      <mass value="3.5"/>
      <!-- org: 3.5, foot un modeled-->
      <inertia ixx="0.004433" ixy="0.0" ixz="0.0" iyy="0.004433" iyz="0.0" izz="0.0021"/>
      <!--	<inertia ixx="0.01" ixy="0.01" ixz="0.01" iyy="0.01" iyz="0.01" izz="0.01"/>  -->
    </inertial>
    <visual>
      <origin xyz="0 0 -0.125"/>
      <geometry>
        <box size="0.05 0.05 0.25"/>
        <!-- OK: foot un modeled-->
      </geometry>
      <material name="grey"/>
    </visual>
    <visual>
      <origin rpy="1.5707963268 0 0" xyz="0 0 0"/>
      <geometry>
        <cylinder length="0.1" radius="0.05"/>
      </geometry>
      <material name="blue"/>
    </visual>
    <visual>
      <origin xyz="0 0 -0.25"/>
      <geometry>
        <sphere radius="0.05"/>
      </geometry>
      <material name="blue"/>
    </visual>
    <collision>
      <origin xyz="0 0 -0.125"/>
      <geometry>
        <box size="0.05 0.05 0.2"/>
        <!-- OK: foot un modeled-->
      </geometry>
      <material name="grey"/>
    </collision>
    <!--	<collision>
		<origin xyz="0 0 0" rpy="${PI/2} 0 0" />
		<geometry>
			<cylinder length="${motors_length}" radius="${motors_radius}"/>
		</geometry>
		<material name="blue"/>
	</collision> -->
    <collision>
      <origin xyz="0 0 -0.25"/>
      <geometry>
        <sphere radius="0.05"/>
      </geometry>
      <material name="blue"/>
    </collision>
  </link>
  <!-- ftsensor -->
  <!--<link name="ft_foot_${leg_num}">
  <inertial>
    <mass value="0.001"/>
    <origin xyz="0 0 0"/>
    <inertia ixx="1.0E-6" ixy="0" ixz="0" iyy="1.0E-6" iyz="0" izz="1.0E-6"/>
  </inertial>
  <visual>
      <origin rpy="0 0 0" xyz="0 0 0"/>
      <geometry>
        <box size="0.01 0.01 0.01"/>
      </geometry>
  </visual>
</link>-->
  <!-- /wheels -->
  <joint name="hip_yaw_2" type="revolute">
    <parent link="pelvis"/>
    <child link="hip1_2"/>
    <origin rpy="0 0 1.5707963268" xyz="0.3 -0.15 0"/>
    <axis xyz="0 0 1"/>
    <limit effort="147" lower="-2.09" upper="2.09" velocity="6.5"/>
    <!-- TODO -->
  </joint>
  <joint name="hip_pitch_2" type="revolute">
    <parent link="hip1_2"/>
    <child link="hip2_2"/>
    <origin xyz="0.0 0.0 -0.2"/>
    <axis xyz="0 1 0"/>
    <limit effort="330" lower="-3.14" upper="3.14" velocity="6.5"/>
    <!-- TODO -->
  </joint>
  <joint name="knee_pitch_2" type="revolute">
    <parent link="hip2_2"/>
    <child link="knee_2"/>
    <origin xyz="0.0 0.0 -0.35"/>
    <axis xyz="0 1 0"/>
    <limit effort="330" lower="-3.14" upper="3.14" velocity="6.5"/>
    <!-- TODO -->
  </joint>
  <transmission name="t_hip_yaw_2">
    <type> transmission_interface/SimpleTransmission</type>
    <joint name="hip_yaw_2">
      <hardwareInterface>EffortJointInterface</hardwareInterface>
    </joint>
    <actuator name="motor_hip_yaw_2">
      <hardwareInterface>EffortJointInterface</hardwareInterface>
      <machanicalReduction>1</machanicalReduction>
    </actuator>
    <robotNamespace>/centauro</robotNamespace>
  </transmission>
  <transmission name="t_hip_pitch_2">
    <type> transmission_interface/SimpleTransmission</type>
    <joint name="hip_pitch_2">
      <hardwareInterface>EffortJointInterface</hardwareInterface>
    </joint>
    <actuator name="motor_hip_pitch_2">
      <hardwareInterface>EffortJointInterface</hardwareInterface>
      <machanicalReduction>1</machanicalReduction>
    </actuator>
    <robotNamespace>/centauro</robotNamespace>
  </transmission>
  <transmission name="t_knee_pitch_2">
    <type> transmission_interface/SimpleTransmission</type>
    <joint name="knee_pitch_2">
      <hardwareInterface>EffortJointInterface</hardwareInterface>
    </joint>
    <actuator name="motor_knee_pitch_2">
      <hardwareInterface>EffortJointInterface</hardwareInterface>
      <machanicalReduction>1</machanicalReduction>
    </actuator>
    <robotNamespace>/centauro</robotNamespace>
  </transmission>
  <!-- /actuators -->
  <link name="hip1_3">
    <inertial>
      <origin xyz="0.0 0.0 -0.175"/>
      <!-- TODO -->
      <mass value="2.0"/>
      <!-- org: 2 -->
      <inertia ixx="0.006237" ixy="0.0" ixz="0.0" iyy="0.005925" iyz="-0.0" izz="0.002488"/>
      <!-- <inertia ixx="0.01" ixy="0.01" ixz="0.01" iyy="0.01" iyz="0.01" izz="0.01"/> -->
    </inertial>
    <visual>
      <origin xyz="0 0 -0.1"/>
      <geometry>
        <box size="0.05 0.05 0.2"/>
        <!-- OK: from hip-yaw to pelvis (0.1) + from plevis to hip-pitch (0.1)-->
      </geometry>
      <material name="grey"/>
    </visual>
    <visual>
      <origin rpy="0 0 0" xyz="0 0 0"/>
      <geometry>
        <cylinder length="0.1" radius="0.05"/>
      </geometry>
      <material name="grey"/>
    </visual>
    <collision>
      <origin xyz="0 0 -0.1"/>
      <geometry>
        <box size="0.05 0.05 0.15"/>
        <!-- OK: from hip-yaw to pelvis (0.1) + from plevis to hip-pitch (0.1)-->
      </geometry>
      <material name="grey"/>
    </collision>
    <!-- <collision>
		<origin xyz="0 0 0" rpy="0 0 0" />
		<geometry>
			<cylinder length="${motors_length}" radius="${motors_radius}"/>
		</geometry>
		<material name="grey"/>
	</collision> -->
  </link>
  <link name="hip2_3">
    <inertial>
      <origin xyz="0.0 0.0 -0.233333"/>
      <mass value="4.5"/>
      <!-- org: 4.5 -->
      <inertia ixx="0.037113" ixy="0.0" ixz="0.0" iyy="0.0368" iyz="-0.0" izz="0.003988"/>
      <!-- <inertia ixx="0.01" ixy="0.01" ixz="0.01" iyy="0.01" iyz="0.01" izz="0.01"/> -->
    </inertial>
    <visual>
      <origin xyz="0 0 -0.175"/>
      <geometry>
        <box size="0.05 0.05 0.35"/>
        <!-- OK -->
      </geometry>
      <material name="blue"/>
    </visual>
    <visual>
      <origin rpy="1.5707963268 0 0" xyz="0 0 0"/>
      <geometry>
        <cylinder length="0.1" radius="0.05"/>
      </geometry>
      <material name="blue"/>
    </visual>
    <collision>
      <origin xyz="0 0 -0.175"/>
      <geometry>
        <box size="0.05 0.05 0.3"/>
        <!-- OK -->
      </geometry>
      <material name="blue"/>
    </collision>
    <!-- <collision>
		<origin xyz="0 0 0" rpy="${PI/2} 0 0" />
		<geometry>
			<cylinder length="${motors_length}" radius="${motors_radius}"/>
		</geometry>
		<material name="blue"/>
	</collision> -->
  </link>
  <link name="knee_3">
    <inertial>
      <origin xyz="0.0 0.0 -0.15"/>
      <!-- TODO -->
      <mass value="3.5"/>
      <!-- org: 3.5, foot un modeled-->
      <inertia ixx="0.004433" ixy="0.0" ixz="0.0" iyy="0.004433" iyz="0.0" izz="0.0021"/>
      <!--	<inertia ixx="0.01" ixy="0.01" ixz="0.01" iyy="0.01" iyz="0.01" izz="0.01"/>  -->
    </inertial>
    <visual>
      <origin xyz="0 0 -0.125"/>
      <geometry>
        <box size="0.05 0.05 0.25"/>
        <!-- OK: foot un modeled-->
      </geometry>
      <material name="grey"/>
    </visual>
    <visual>
      <origin rpy="1.5707963268 0 0" xyz="0 0 0"/>
      <geometry>
        <cylinder length="0.1" radius="0.05"/>
      </geometry>
      <material name="blue"/>
    </visual>
    <visual>
      <origin xyz="0 0 -0.25"/>
      <geometry>
        <sphere radius="0.05"/>
      </geometry>
      <material name="blue"/>
    </visual>
    <collision>
      <origin xyz="0 0 -0.125"/>
      <geometry>
        <box size="0.05 0.05 0.2"/>
        <!-- OK: foot un modeled-->
      </geometry>
      <material name="grey"/>
    </collision>
    <!--	<collision>
		<origin xyz="0 0 0" rpy="${PI/2} 0 0" />
		<geometry>
			<cylinder length="${motors_length}" radius="${motors_radius}"/>
		</geometry>
		<material name="blue"/>
	</collision> -->
    <collision>
      <origin xyz="0 0 -0.25"/>
      <geometry>
        <sphere radius="0.05"/>
      </geometry>
      <material name="blue"/>
    </collision>
  </link>
  <!-- ftsensor -->
  <!--<link name="ft_foot_${leg_num}">
  <inertial>
    <mass value="0.001"/>
    <origin xyz="0 0 0"/>
    <inertia ixx="1.0E-6" ixy="0" ixz="0" iyy="1.0E-6" iyz="0" izz="1.0E-6"/>
  </inertial>
  <visual>
      <origin rpy="0 0 0" xyz="0 0 0"/>
      <geometry>
        <box size="0.01 0.01 0.01"/>
      </geometry>
  </visual>
</link>-->
  <!-- /wheels -->
  <joint name="hip_yaw_3" type="revolute">
    <parent link="pelvis"/>
    <child link="hip1_3"/>
    <origin rpy="0 0 1.5707963268" xyz="-0.3 -0.15 0"/>
    <axis xyz="0 0 1"/>
    <limit effort="147" lower="-2.09" upper="2.09" velocity="6.5"/>
    <!-- TODO -->
  </joint>
  <joint name="hip_pitch_3" type="revolute">
    <parent link="hip1_3"/>
    <child link="hip2_3"/>
    <origin xyz="0.0 0.0 -0.2"/>
    <axis xyz="0 1 0"/>
    <limit effort="330" lower="-3.14" upper="3.14" velocity="6.5"/>
    <!-- TODO -->
  </joint>
  <joint name="knee_pitch_3" type="revolute">
    <parent link="hip2_3"/>
    <child link="knee_3"/>
    <origin xyz="0.0 0.0 -0.35"/>
    <axis xyz="0 1 0"/>
    <limit effort="330" lower="-3.14" upper="3.14" velocity="6.5"/>
    <!-- TODO -->
  </joint>
  <transmission name="t_hip_yaw_3">
    <type> transmission_interface/SimpleTransmission</type>
    <joint name="hip_yaw_3">
      <hardwareInterface>EffortJointInterface</hardwareInterface>
    </joint>
    <actuator name="motor_hip_yaw_3">
      <hardwareInterface>EffortJointInterface</hardwareInterface>
      <machanicalReduction>1</machanicalReduction>
    </actuator>
    <robotNamespace>/centauro</robotNamespace>
  </transmission>
  <transmission name="t_hip_pitch_3">
    <type> transmission_interface/SimpleTransmission</type>
    <joint name="hip_pitch_3">
      <hardwareInterface>EffortJointInterface</hardwareInterface>
    </joint>
    <actuator name="motor_hip_pitch_3">
      <hardwareInterface>EffortJointInterface</hardwareInterface>
      <machanicalReduction>1</machanicalReduction>
    </actuator>
    <robotNamespace>/centauro</robotNamespace>
  </transmission>
  <transmission name="t_knee_pitch_3">
    <type> transmission_interface/SimpleTransmission</type>
    <joint name="knee_pitch_3">
      <hardwareInterface>EffortJointInterface</hardwareInterface>
    </joint>
    <actuator name="motor_knee_pitch_3">
      <hardwareInterface>EffortJointInterface</hardwareInterface>
      <machanicalReduction>1</machanicalReduction>
    </actuator>
    <robotNamespace>/centauro</robotNamespace>
  </transmission>
  <!-- /actuators -->
  <link name="hip1_4">
    <inertial>
      <origin xyz="0.0 0.0 -0.175"/>
      <!-- TODO -->
      <mass value="2.0"/>
      <!-- org: 2 -->
      <inertia ixx="0.006237" ixy="0.0" ixz="0.0" iyy="0.005925" iyz="-0.0" izz="0.002488"/>
      <!-- <inertia ixx="0.01" ixy="0.01" ixz="0.01" iyy="0.01" iyz="0.01" izz="0.01"/> -->
    </inertial>
    <visual>
      <origin xyz="0 0 -0.1"/>
      <geometry>
        <box size="0.05 0.05 0.2"/>
        <!-- OK: from hip-yaw to pelvis (0.1) + from plevis to hip-pitch (0.1)-->
      </geometry>
      <material name="grey"/>
    </visual>
    <visual>
      <origin rpy="0 0 0" xyz="0 0 0"/>
      <geometry>
        <cylinder length="0.1" radius="0.05"/>
      </geometry>
      <material name="grey"/>
    </visual>
    <collision>
      <origin xyz="0 0 -0.1"/>
      <geometry>
        <box size="0.05 0.05 0.15"/>
        <!-- OK: from hip-yaw to pelvis (0.1) + from plevis to hip-pitch (0.1)-->
      </geometry>
      <material name="grey"/>
    </collision>
    <!-- <collision>
		<origin xyz="0 0 0" rpy="0 0 0" />
		<geometry>
			<cylinder length="${motors_length}" radius="${motors_radius}"/>
		</geometry>
		<material name="grey"/>
	</collision> -->
  </link>
  <link name="hip2_4">
    <inertial>
      <origin xyz="0.0 0.0 -0.233333"/>
      <mass value="4.5"/>
      <!-- org: 4.5 -->
      <inertia ixx="0.037113" ixy="0.0" ixz="0.0" iyy="0.0368" iyz="-0.0" izz="0.003988"/>
      <!-- <inertia ixx="0.01" ixy="0.01" ixz="0.01" iyy="0.01" iyz="0.01" izz="0.01"/> -->
    </inertial>
    <visual>
      <origin xyz="0 0 -0.175"/>
      <geometry>
        <box size="0.05 0.05 0.35"/>
        <!-- OK -->
      </geometry>
      <material name="blue"/>
    </visual>
    <visual>
      <origin rpy="1.5707963268 0 0" xyz="0 0 0"/>
      <geometry>
        <cylinder length="0.1" radius="0.05"/>
      </geometry>
      <material name="blue"/>
    </visual>
    <collision>
      <origin xyz="0 0 -0.175"/>
      <geometry>
        <box size="0.05 0.05 0.3"/>
        <!-- OK -->
      </geometry>
      <material name="blue"/>
    </collision>
    <!-- <collision>
		<origin xyz="0 0 0" rpy="${PI/2} 0 0" />
		<geometry>
			<cylinder length="${motors_length}" radius="${motors_radius}"/>
		</geometry>
		<material name="blue"/>
	</collision> -->
  </link>
  <link name="knee_4">
    <inertial>
      <origin xyz="0.0 0.0 -0.15"/>
      <!-- TODO -->
      <mass value="3.5"/>
      <!-- org: 3.5, foot un modeled-->
      <inertia ixx="0.004433" ixy="0.0" ixz="0.0" iyy="0.004433" iyz="0.0" izz="0.0021"/>
      <!--	<inertia ixx="0.01" ixy="0.01" ixz="0.01" iyy="0.01" iyz="0.01" izz="0.01"/>  -->
    </inertial>
    <visual>
      <origin xyz="0 0 -0.125"/>
      <geometry>
        <box size="0.05 0.05 0.25"/>
        <!-- OK: foot un modeled-->
      </geometry>
      <material name="grey"/>
    </visual>
    <visual>
      <origin rpy="1.5707963268 0 0" xyz="0 0 0"/>
      <geometry>
        <cylinder length="0.1" radius="0.05"/>
      </geometry>
      <material name="blue"/>
    </visual>
    <visual>
      <origin xyz="0 0 -0.25"/>
      <geometry>
        <sphere radius="0.05"/>
      </geometry>
      <material name="blue"/>
    </visual>
    <collision>
      <origin xyz="0 0 -0.125"/>
      <geometry>
        <box size="0.05 0.05 0.2"/>
        <!-- OK: foot un modeled-->
      </geometry>
      <material name="grey"/>
    </collision>
    <!--	<collision>
		<origin xyz="0 0 0" rpy="${PI/2} 0 0" />
		<geometry>
			<cylinder length="${motors_length}" radius="${motors_radius}"/>
		</geometry>
		<material name="blue"/>
	</collision> -->
    <collision>
      <origin xyz="0 0 -0.25"/>
      <geometry>
        <sphere radius="0.05"/>
      </geometry>
      <material name="blue"/>
    </collision>
  </link>
  <!-- ftsensor -->
  <!--<link name="ft_foot_${leg_num}">
  <inertial>
    <mass value="0.001"/>
    <origin xyz="0 0 0"/>
    <inertia ixx="1.0E-6" ixy="0" ixz="0" iyy="1.0E-6" iyz="0" izz="1.0E-6"/>
  </inertial>
  <visual>
      <origin rpy="0 0 0" xyz="0 0 0"/>
      <geometry>
        <box size="0.01 0.01 0.01"/>
      </geometry>
  </visual>
</link>-->
  <!-- /wheels -->
  <joint name="hip_yaw_4" type="revolute">
    <parent link="pelvis"/>
    <child link="hip1_4"/>
    <origin rpy="0 0 1.5707963268" xyz="-0.3 0.15 0"/>
    <axis xyz="0 0 -1"/>
    <limit effort="147" lower="-2.09" upper="2.09" velocity="6.5"/>
    <!-- TODO -->
  </joint>
  <joint name="hip_pitch_4" type="revolute">
    <parent link="hip1_4"/>
    <child link="hip2_4"/>
    <origin xyz="0.0 0.0 -0.2"/>
    <axis xyz="0 -1 0"/>
    <limit effort="330" lower="-3.14" upper="3.14" velocity="6.5"/>
    <!-- TODO -->
  </joint>
  <joint name="knee_pitch_4" type="revolute">
    <parent link="hip2_4"/>
    <child link="knee_4"/>
    <origin xyz="0.0 0.0 -0.35"/>
    <axis xyz="0 -1 0"/>
    <limit effort="330" lower="-3.14" upper="3.14" velocity="6.5"/>
    <!-- TODO -->
  </joint>
  <transmission name="t_hip_yaw_4">
    <type> transmission_interface/SimpleTransmission</type>
    <joint name="hip_yaw_4">
      <hardwareInterface>EffortJointInterface</hardwareInterface>
    </joint>
    <actuator name="motor_hip_yaw_4">
      <hardwareInterface>EffortJointInterface</hardwareInterface>
      <machanicalReduction>1</machanicalReduction>
    </actuator>
    <robotNamespace>/centauro</robotNamespace>
  </transmission>
  <transmission name="t_hip_pitch_4">
    <type> transmission_interface/SimpleTransmission</type>
    <joint name="hip_pitch_4">
      <hardwareInterface>EffortJointInterface</hardwareInterface>
    </joint>
    <actuator name="motor_hip_pitch_4">
      <hardwareInterface>EffortJointInterface</hardwareInterface>
      <machanicalReduction>1</machanicalReduction>
    </actuator>
    <robotNamespace>/centauro</robotNamespace>
  </transmission>
  <transmission name="t_knee_pitch_4">
    <type> transmission_interface/SimpleTransmission</type>
    <joint name="knee_pitch_4">
      <hardwareInterface>EffortJointInterface</hardwareInterface>
    </joint>
    <actuator name="motor_knee_pitch_4">
      <hardwareInterface>EffortJointInterface</hardwareInterface>
      <machanicalReduction>1</machanicalReduction>
    </actuator>
    <robotNamespace>/centauro</robotNamespace>
  </transmission>
  <!-- /actuators -->
  <!-- /legs -->
</robot>
