<?xml version="1.0" ?>
<robot xmlns:xacro="http://www.ros.org/wiki/xacro">

<!-- links -->

   <link name="arm${arm_num}_8">
      <inertial>
         <origin xyz="0 0 0.10" rpy="0 0 0"/>
         <mass value="0.3"/>
         <inertia ixx="0.00024500"  ixy="0"  ixz="0" iyy="0.00024500" iyz="0" izz="0.00024500" />
      </inertial>

      <visual>
         <xacro:visual_model.soft_hand />
         <material name="grey"/>
      </visual>

      <collision>
         <xacro:collision_model.soft_hand />
      </collision>
   </link>
<!-- /links -->

   <joint name="j_arm${arm_num}_8" type="revolute">
      <parent link="arm${arm_num}_7"/>
      <child link="arm${arm_num}_8"/>
      <origin xyz="0 0 -0.0405" rpy="0 ${PI} ${-PI/2}"/>
      <axis xyz="1 0 0" />
      <limit velocity="6.5" effort="400" lower="0.0" upper="1.57075" />
   </joint> -->
<!-- /joints -->

<!-- actuators -->
   <xacro:position_actuator joint="j_arm${arm_num}_8" />
<!-- /actuators -->


</robot>
