<?xml version="1.0" ?>
<!-- =================================================================================== -->
<!-- |    This document was autogenerated by xacro from centauro_floating_arm.urdf.xacro | -->
<!-- |    EDITING THIS FILE BY HAND IS NOT RECOMMENDED                                 | -->
<!-- =================================================================================== -->
<robot name="centauro" xmlns:xacro="http://www.ros.org/wiki/xacro">
  <!-- /constants -->
  <!-- Here all arguments from launch file are evaluated to the final xacro poropeties.
     Also all the parameter dependencies are resolved-->
  <!-- Here all arguments from launch file are evaluated to the final xacro poropeties.
     Also all the parameter dependencies are resolved-->
  <!--xacro:if value="${arm_sensors}">
  <xacro:force-torque_sensor joint="j_arm1_7" robot="centauro"/>
  <xacro:if value="${arms}">
    <xacro:force-torque_sensor joint="j_arm2_7" robot="centauro"/>
  </xacro:if>
</xacro:if-->
  <gazebo reference="j_arm1_7">
    <sensor name="left_arm_ft" type="force_torque">
      <force_torque>
        <frame>sensor</frame>
        <measure_direction>child_to_parent</measure_direction>
      </force_torque>
      <always_on>true</always_on>
      <visualize>true</visualize>
      <update_rate>1000</update_rate>
      <pose>0 0 -0.0565 0 0 0</pose>
    </sensor>
  </gazebo>
  <gazebo reference="j_arm2_7">
    <sensor name="right_arm_ft" type="force_torque">
      <force_torque>
        <frame>sensor</frame>
        <measure_direction>child_to_parent</measure_direction>
      </force_torque>
      <always_on>true</always_on>
      <visualize>true</visualize>
      <update_rate>1000</update_rate>
      <pose>0 0 -0.0565 0 0 0</pose>
    </sensor>
  </gazebo>
  <link name="left_arm_ft"/>
  <link name="right_arm_ft"/>
  <joint name="l_arm_ft_joint" type="fixed">
    <parent link="arm1_7"/>
    <child link="left_arm_ft"/>
    <origin rpy="0 0 0" xyz="0 0 -0.0565"/>
  </joint>
  <joint name="r_arm_ft_joint" type="fixed">
    <parent link="arm2_7"/>
    <child link="right_arm_ft"/>
    <origin rpy="0 0 0" xyz="0 0 -0.0565"/>
  </joint>
  <!-- ROS CONTROLLER -->
  <!--	<gazebo>
		<plugin name="gazebo_ros_control" filename="libgazebo_ros_control.so">
			<robotNamespace>/centauro</robotNamespace>
			<robotSimType>gazebo_ros_control/DefaultRobotHWSim</robotSimType>
		</plugin>

	</gazebo>-->
  <!-- /ROS CONTROLLER -->
  <!--  XBOT CONTROLLER -->
  <gazebo>
    <plugin filename="libGazeboXBotPlugin.so" name="gazebo_xbot_plugin">
      <path_to_config_file>configs/ADVR_shared/centauro/configs/config_centauro.yaml</path_to_config_file>
    </plugin>
  </gazebo>
  <!-- /XBOT CONTROLLER -->
  <gazebo reference="imu_link">
    <sensor name="imu_link" type="imu">
      <always_on>1</always_on>
      <update_rate>500</update_rate>
      <visualize>true</visualize>
      <topic>__default_topic__</topic>
      <imu>
        <!--
        <noise>
        <type>gaussian</type>
        <rate>
            <mean>0.0</mean>
            <stddev>2e-4</stddev>
            <bias_mean>0.0000075</bias_mean>
            <bias_stddev>0.0000008</bias_stddev>
        </rate>
        <accel>
            <mean>0.0</mean>
            <stddev>1.7e-2</stddev>
            <bias_mean>0.1</bias_mean>
            <bias_stddev>0.001</bias_stddev>
        </accel>
        </noise>
        -->
      </imu>
    </sensor>
  </gazebo>
  <!-- /CONTACT SENSORS -->
  <!-- FORCE-TORQUE SENSORS -->
  <!--<gazebo>
    <plugin name="ft_sensor" filename="libgazebo_ros_ft_sensor.so">
        <updateRate>100.0</updateRate>
        <topicName>ft_sensor_1</topicName>
        <jointName>foot_fixed_joint_1</jointName>
    </plugin>
</gazebo>-->
  <!-- The ft_sensor plugin -->
  <!--<gazebo>
    <plugin name="ft_sensor" filename="libgazebo_ros_ft_sensor.so">
        <updateRate>100.0</updateRate>
        <topicName>ft_sensor_2</topicName>
        <jointName>foot_fixed_joint_2</jointName>
    </plugin>
</gazebo>-->
  <!-- The ft_sensor plugin -->
  <!--<gazebo>
    <plugin name="ft_sensor" filename="libgazebo_ros_ft_sensor.so">
        <updateRate>100.0</updateRate>
        <topicName>ft_sensor_3</topicName>
        <jointName>foot_fixed_joint_3</jointName>
    </plugin>
</gazebo>-->
  <!-- The ft_sensor plugin -->
  <!--<gazebo>
    <plugin name="ft_sensor" filename="libgazebo_ros_ft_sensor.so">
        <updateRate>100.0</updateRate>
        <topicName>ft_sensor_4</topicName>
        <jointName>foot_fixed_joint_4</jointName>
    </plugin>
</gazebo>-->
  <!-- FORCE-TORQUE SENSORS -->
  <!-- /LEG SENSORS -->
  <!-- VISUALiZATION AND FRICTION -->
  <gazebo reference="base_link">
    <material>Gazebo/Red</material>
  </gazebo>
  <gazebo reference="load">
    <material>Gazebo/OrangeTransparent</material>
  </gazebo>
  <gazebo reference="pelvis">
    <material>Gazebo/OrangeTransparent</material>
    <mu1>0</mu1>
    <mu2>0</mu2>
  </gazebo>
  <gazebo reference="torso_1">
    <mu1>1</mu1>
    <mu2>1</mu2>
    <material>Gazebo/Grey</material>
  </gazebo>
  <gazebo reference="torso_2">
    <material>Gazebo/OrangeTransparent</material>
    <mu1>0</mu1>
    <mu2>0</mu2>
  </gazebo>
  <gazebo reference="hip1_1">
    <material>Gazebo/Lane_1</material>
    <mu1>0</mu1>
    <mu2>0</mu2>
  </gazebo>
  <gazebo reference="hip1_2">
    <material>Gazebo/Lane_1 </material>
    <mu1>0</mu1>
    <mu2>0</mu2>
  </gazebo>
  <gazebo reference="hip1_3">
    <material>Gazebo/Lane_1</material>
    <mu1>0</mu1>
    <mu2>0</mu2>
  </gazebo>
  <gazebo reference="hip1_4">
    <material>Gazebo/Lane_1</material>
    <mu1>0</mu1>
    <mu2>0</mu2>
  </gazebo>
  <gazebo reference="hip2_1">
    <material>Gazebo/OrangeTransparent </material>
    <mu1>0</mu1>
    <mu2>0</mu2>
  </gazebo>
  <gazebo reference="hip2_2">
    <material>Gazebo/OrangeTransparent</material>
    <mu1>0</mu1>
    <mu2>0</mu2>
  </gazebo>
  <gazebo reference="hip2_3">
    <material>Gazebo/OrangeTransparent </material>
    <mu1>0</mu1>
    <mu2>0</mu2>
  </gazebo>
  <gazebo reference="hip2_4">
    <material>Gazebo/OrangeTransparent </material>
    <mu1>0</mu1>
    <mu2>0</mu2>
  </gazebo>
  <gazebo reference="knee_1">
    <material>Gazebo/Lane_1 </material>
    <mu1>0</mu1>
    <mu2>0</mu2>
  </gazebo>
  <gazebo reference="knee_2">
    <material>Gazebo/Lane_1 </material>
    <mu1>0</mu1>
    <mu2>0</mu2>
  </gazebo>
  <gazebo reference="knee_3">
    <material>Gazebo/Lane_1 </material>
    <mu1>0</mu1>
    <mu2>0</mu2>
  </gazebo>
  <gazebo reference="knee_4">
    <material>Gazebo/Lane_1 </material>
    <mu1>0</mu1>
    <mu2>0</mu2>
  </gazebo>
  <gazebo reference="ankle1_1">
    <material>Gazebo/OrangeTransparent</material>
    <mu1>0</mu1>
    <mu2>0</mu2>
  </gazebo>
  <gazebo reference="ankle1_2">
    <material>Gazebo/OrangeTransparent  </material>
    <mu1>0</mu1>
    <mu2>0</mu2>
  </gazebo>
  <gazebo reference="ankle1_3">
    <material>Gazebo/OrangeTransparent </material>
    <mu1>0</mu1>
    <mu2>0</mu2>
  </gazebo>
  <gazebo reference="ankle1_4">
    <material>Gazebo/OrangeTransparent  </material>
    <mu1>0</mu1>
    <mu2>0</mu2>
  </gazebo>
  <gazebo reference="ankle2_1">
    <material> Gazebo/Lane_1 </material>
    <mu1>0</mu1>
    <mu2>0</mu2>
  </gazebo>
  <gazebo reference="ankle2_2">
    <material>Gazebo/Lane_1 </material>
    <mu1>0</mu1>
    <mu2>0</mu2>
  </gazebo>
  <gazebo reference="ankle2_3">
    <material>Gazebo/Lane_1</material>
    <mu1>0</mu1>
    <mu2>0</mu2>
  </gazebo>
  <gazebo reference="ankle2_4">
    <material>Gazebo/Lane_1</material>
    <mu1>0</mu1>
    <mu2>0</mu2>
  </gazebo>
  <gazebo reference="wheel_1">
    <material>Gazebo/Residential </material>
    <collision>
      <surface>
        <friction>
          <!--                                        <torsional>
                                                <coefficient> 0.5 </coefficient>
                                                <use_patch_radius>true</use_patch_radius>
                                                <patch_radius>0.2</patch_radius>
                                        </torsional>-->
          <ode>
            <mu>0.5</mu>
            <mu2>0.5</mu2>
          </ode>
          <bullet>
            <friction>0.5</friction>
            <friction2>0.5</friction2>
          </bullet>
        </friction>
        <contact>
          <ode>
            <!--                                               <soft_cfm>0.007</soft_cfm>
                                        <soft_erp>0.25</soft_erp>-->
            <kp>2100000</kp>
            <kd>1</kd>
            <!--                                                <max_vel>100</max_vel>-->
          </ode>
          <bullet>
            <soft_cfm>0.007</soft_cfm>
            <soft_erp>0.25</soft_erp>
            <kp>1000000</kp>
            <kd>5</kd>
            <split_impulse>0.01</split_impulse>
          </bullet>
        </contact>
      </surface>
    </collision>
  </gazebo>
  <gazebo reference="wheel_2">
    <material>Gazebo/Residential</material>
    <collision>
      <surface>
        <friction>
          <!--                                        <torsional>
                                                <coefficient> 0.5 </coefficient>
                                                <use_patch_radius>true</use_patch_radius>
                                                <patch_radius>0.2</patch_radius>
                                        </torsional>-->
          <ode>
            <mu>0.5</mu>
            <mu2>0.5</mu2>
          </ode>
          <bullet>
            <friction>0.5</friction>
            <friction2>0.5</friction2>
          </bullet>
        </friction>
        <contact>
          <ode>
            <!--                                               <soft_cfm>0.007</soft_cfm>
                                        <soft_erp>0.25</soft_erp>-->
            <kp>2100000</kp>
            <kd>1</kd>
            <!--                                                <max_vel>100</max_vel>-->
          </ode>
          <bullet>
            <soft_cfm>0.007</soft_cfm>
            <soft_erp>0.25</soft_erp>
            <kp>1000000</kp>
            <kd>5</kd>
            <split_impulse>0.01</split_impulse>
          </bullet>
        </contact>
      </surface>
    </collision>
  </gazebo>
  <gazebo reference="wheel_3">
    <material>Gazebo/Residential </material>
    <collision>
      <surface>
        <friction>
          <!--                                        <torsional>
                                                <coefficient> 0.5 </coefficient>
                                                <use_patch_radius>true</use_patch_radius>
                                                <patch_radius>0.2</patch_radius>
                                        </torsional>-->
          <ode>
            <mu>0.5</mu>
            <mu2>0.5</mu2>
          </ode>
          <bullet>
            <friction>0.5</friction>
            <friction2>0.5</friction2>
          </bullet>
        </friction>
        <contact>
          <ode>
            <!--                                               <soft_cfm>0.007</soft_cfm>
                                        <soft_erp>0.25</soft_erp>-->
            <kp>2100000</kp>
            <kd>1</kd>
            <!--                                                <max_vel>100</max_vel>-->
          </ode>
          <bullet>
            <soft_cfm>0.007</soft_cfm>
            <soft_erp>0.25</soft_erp>
            <kp>1000000</kp>
            <kd>5</kd>
            <split_impulse>0.01</split_impulse>
          </bullet>
        </contact>
      </surface>
    </collision>
  </gazebo>
  <gazebo reference="wheel_4">
    <material>Gazebo/Residential</material>
    <collision>
      <surface>
        <friction>
          <!--                                        <torsional>
                                                <coefficient> 0.5 </coefficient>
                                                <use_patch_radius>true</use_patch_radius>
                                                <patch_radius>0.2</patch_radius>
                                        </torsional>-->
          <ode>
            <mu>0.5</mu>
            <mu2>0.5</mu2>
          </ode>
          <bullet>
            <friction>0.5</friction>
            <friction2>0.5</friction2>
          </bullet>
        </friction>
        <contact>
          <ode>
            <!--                                               <soft_cfm>0.007</soft_cfm>
                                                <soft_erp>0.25</soft_erp>-->
            <kp>2100000</kp>
            <kd>1</kd>
            <!--                                                <max_vel>100</max_vel>-->
          </ode>
          <bullet>
            <soft_cfm>0.007</soft_cfm>
            <soft_erp>0.25</soft_erp>
            <kp>1000000</kp>
            <kd>5</kd>
            <split_impulse>0.01</split_impulse>
          </bullet>
        </contact>
      </surface>
    </collision>
  </gazebo>
  <gazebo reference="arm1_1">
    <material>Gazebo/Lane_1 </material>
    <mu1>0</mu1>
    <mu2>0</mu2>
  </gazebo>
  <gazebo reference="arm2_1">
    <material>Gazebo/Lane_1 </material>
    <mu1>0</mu1>
    <mu2>0</mu2>
  </gazebo>
  <gazebo reference="arm1_2">
    <material>Gazebo/OrangeTransparent </material>
    <mu1>0</mu1>
    <mu2>0</mu2>
  </gazebo>
  <gazebo reference="arm2_2">
    <material>Gazebo/OrangeTransparent</material>
    <mu1>0</mu1>
    <mu2>0</mu2>
  </gazebo>
  <gazebo reference="arm1_3">
    <material>Gazebo/Lane_1 </material>
    <mu1>0</mu1>
    <mu2>0</mu2>
  </gazebo>
  <gazebo reference="arm2_3">
    <material>Gazebo/Lane_1 </material>
    <mu1>0</mu1>
    <mu2>0</mu2>
  </gazebo>
  <gazebo reference="arm1_4">
    <material>Gazebo/OrangeTransparent </material>
    <mu1>0</mu1>
    <mu2>0</mu2>
  </gazebo>
  <gazebo reference="arm2_4">
    <material>Gazebo/OrangeTransparent </material>
    <mu1>0</mu1>
    <mu2>0</mu2>
  </gazebo>
  <gazebo reference="arm1_5">
    <material>Gazebo/Lane_1 </material>
    <mu1>0</mu1>
    <mu2>0</mu2>
  </gazebo>
  <gazebo reference="arm2_5">
    <material>Gazebo/Lane_1 </material>
    <mu1>0</mu1>
    <mu2>0</mu2>
  </gazebo>
  <gazebo reference="arm1_6">
    <material>Gazebo/OrangeTransparent </material>
    <mu1>0</mu1>
    <mu2>0</mu2>
  </gazebo>
  <gazebo reference="arm2_6">
    <material>Gazebo/OrangeTransparent </material>
    <mu1>0</mu1>
    <mu2>0</mu2>
  </gazebo>
  <gazebo reference="arm1_7">
    <material>Gazebo/Lane_1 </material>
    <mu1>0</mu1>
    <mu2>0</mu2>
  </gazebo>
  <gazebo reference="arm2_7">
    <material>Gazebo/Lane_1 </material>
    <mu1>0</mu1>
    <mu2>0</mu2>
  </gazebo>
  <gazebo reference="arm1_8">
    <material>Gazebo/OrangeTransparent </material>
    <kp>1000000.0</kp>
    <kd>100.0</kd>
    <mu1>1.0</mu1>
    <mu2>1.0</mu2>
    <fdir1>1 0 0</fdir1>
    <maxVel>1.0</maxVel>
    <minDepth>0.0</minDepth>
  </gazebo>
  <gazebo reference="arm2_8">
    <material>Gazebo/OrangeTransparent </material>
    <kp>1000000.0</kp>
    <kd>100.0</kd>
    <mu1>1.0</mu1>
    <mu2>1.0</mu2>
    <fdir1>1 0 0</fdir1>
    <maxVel>1.0</maxVel>
    <minDepth>0.0</minDepth>
  </gazebo>
  <!--     JOINTS -->
  <gazebo reference="torso_yaw">
    <dynamics damping="0.0" friction="0"/>
    <provideFeedback>1</provideFeedback>
    <physics>
      <ode>
        <implicit_spring_damper>1</implicit_spring_damper>
      </ode>
    </physics>
  </gazebo>
  <gazebo reference="j_arm2_1">
    <dynamics damping="0.0" friction="0"/>
    <provideFeedback>1</provideFeedback>
    <physics>
      <ode>
        <implicit_spring_damper>1</implicit_spring_damper>
      </ode>
    </physics>
  </gazebo>
  <gazebo reference="j_arm1_1">
    <dynamics damping="0.0" friction="0"/>
    <provideFeedback>1</provideFeedback>
    <physics>
      <ode>
        <implicit_spring_damper>1</implicit_spring_damper>
      </ode>
    </physics>
  </gazebo>
  <gazebo reference="j_arm2_1">
    <dynamics damping="0.0" friction="0"/>
    <provideFeedback>1</provideFeedback>
    <physics>
      <ode>
        <implicit_spring_damper>1</implicit_spring_damper>
      </ode>
    </physics>
  </gazebo>
  <gazebo reference="j_arm1_2">
    <dynamics damping="0.0" friction="0"/>
    <provideFeedback>1</provideFeedback>
    <physics>
      <ode>
        <implicit_spring_damper>1</implicit_spring_damper>
      </ode>
    </physics>
  </gazebo>
  <gazebo reference="j_arm2_2">
    <dynamics damping="0.0" friction="0"/>
    <provideFeedback>1</provideFeedback>
    <physics>
      <ode>
        <implicit_spring_damper>1</implicit_spring_damper>
      </ode>
    </physics>
  </gazebo>
  <gazebo reference="j_arm1_3">
    <dynamics damping="0.0" friction="0"/>
    <provideFeedback>1</provideFeedback>
    <physics>
      <ode>
        <implicit_spring_damper>1</implicit_spring_damper>
      </ode>
    </physics>
  </gazebo>
  <gazebo reference="j_arm2_3">
    <dynamics damping="0.0" friction="0"/>
    <provideFeedback>1</provideFeedback>
    <implicitSpringDamper>1</implicitSpringDamper>
  </gazebo>
  <gazebo reference="j_arm1_4">
    <dynamics damping="0.0" friction="0"/>
    <provideFeedback>1</provideFeedback>
    <physics>
      <ode>
        <implicit_spring_damper>1</implicit_spring_damper>
      </ode>
    </physics>
  </gazebo>
  <gazebo reference="j_arm2_4">
    <dynamics damping="0.0" friction="0"/>
    <provideFeedback>1</provideFeedback>
    <physics>
      <ode>
        <implicit_spring_damper>1</implicit_spring_damper>
      </ode>
    </physics>
  </gazebo>
  <gazebo reference="j_arm1_5">
    <dynamics damping="0.0" friction="0"/>
    <provideFeedback>1</provideFeedback>
    <physics>
      <ode>
        <implicit_spring_damper>1</implicit_spring_damper>
      </ode>
    </physics>
  </gazebo>
  <gazebo reference="j_arm2_5">
    <dynamics damping="0.0" friction="0"/>
    <provideFeedback>1</provideFeedback>
    <physics>
      <ode>
        <implicit_spring_damper>1</implicit_spring_damper>
      </ode>
    </physics>
  </gazebo>
  <gazebo reference="j_arm1_6">
    <dynamics damping="0.0" friction="0"/>
    <provideFeedback>1</provideFeedback>
    <physics>
      <ode>
        <implicit_spring_damper>1</implicit_spring_damper>
      </ode>
    </physics>
  </gazebo>
  <gazebo reference="j_arm2_6">
    <dynamics damping="0.0" friction="0"/>
    <provideFeedback>1</provideFeedback>
    <physics>
      <ode>
        <implicit_spring_damper>1</implicit_spring_damper>
      </ode>
    </physics>
  </gazebo>
  <gazebo reference="j_arm1_7">
    <dynamics damping="0.0" friction="0"/>
    <provideFeedback>1</provideFeedback>
    <physics>
      <ode>
        <implicit_spring_damper>1</implicit_spring_damper>
      </ode>
    </physics>
  </gazebo>
  <gazebo reference="j_arm2_7">
    <dynamics damping="0.0" friction="0"/>
    <provideFeedback>1</provideFeedback>
    <physics>
      <ode>
        <implicit_spring_damper>1</implicit_spring_damper>
      </ode>
    </physics>
  </gazebo>
  <gazebo reference="hip_yaw_1">
    <dynamics damping="0.0" friction="0"/>
    <provideFeedback>1</provideFeedback>
    <physics>
      <ode>
        <implicit_spring_damper>1</implicit_spring_damper>
      </ode>
    </physics>
  </gazebo>
  <gazebo reference="hip_yaw_2">
    <dynamics damping="0.0" friction="0"/>
    <provideFeedback>1</provideFeedback>
    <physics>
      <ode>
        <implicit_spring_damper>1</implicit_spring_damper>
      </ode>
    </physics>
  </gazebo>
  <gazebo reference="hip_yaw_3">
    <dynamics damping="0.0" friction="0"/>
    <provideFeedback>1</provideFeedback>
    <physics>
      <ode>
        <implicit_spring_damper>1</implicit_spring_damper>
      </ode>
    </physics>
  </gazebo>
  <gazebo reference="hip_yaw_4">
    <dynamics damping="0.0" friction="0"/>
    <provideFeedback>1</provideFeedback>
    <physics>
      <ode>
        <implicit_spring_damper>1</implicit_spring_damper>
      </ode>
    </physics>
  </gazebo>
  <gazebo reference="hip_pitch_1">
    <dynamics damping="0.0" friction="0"/>
    <provideFeedback>1</provideFeedback>
    <physics>
      <ode>
        <implicit_spring_damper>1</implicit_spring_damper>
      </ode>
    </physics>
  </gazebo>
  <gazebo reference="hip_pitch_2">
    <dynamics damping="0.0" friction="0"/>
    <provideFeedback>1</provideFeedback>
    <physics>
      <ode>
        <implicit_spring_damper>1</implicit_spring_damper>
      </ode>
    </physics>
  </gazebo>
  <gazebo reference="hip_pitch_3">
    <dynamics damping="0.0" friction="0"/>
    <provideFeedback>1</provideFeedback>
    <physics>
      <ode>
        <implicit_spring_damper>1</implicit_spring_damper>
      </ode>
    </physics>
  </gazebo>
  <gazebo reference="hip_pitch_4">
    <dynamics damping="0.0" friction="0"/>
    <provideFeedback>1</provideFeedback>
    <physics>
      <ode>
        <implicit_spring_damper>1</implicit_spring_damper>
      </ode>
    </physics>
  </gazebo>
  <gazebo reference="knee_pitch_1">
    <dynamics damping="0.0" friction="0"/>
    <provideFeedback>1</provideFeedback>
    <physics>
      <ode>
        <implicit_spring_damper>1</implicit_spring_damper>
      </ode>
    </physics>
  </gazebo>
  <gazebo reference="knee_pitch_2">
    <dynamics damping="0.0" friction="0"/>
    <provideFeedback>1</provideFeedback>
    <physics>
      <ode>
        <implicit_spring_damper>1</implicit_spring_damper>
      </ode>
    </physics>
  </gazebo>
  <gazebo reference="knee_pitch_3">
    <dynamics damping="0.0" friction="0"/>
    <provideFeedback>1</provideFeedback>
    <physics>
      <ode>
        <implicit_spring_damper>1</implicit_spring_damper>
      </ode>
    </physics>
  </gazebo>
  <gazebo reference="knee_pitch_4">
    <dynamics damping="0.0" friction="0"/>
    <provideFeedback>1</provideFeedback>
    <physics>
      <ode>
        <implicit_spring_damper>1</implicit_spring_damper>
      </ode>
    </physics>
  </gazebo>
  <gazebo reference="wheel_hip_1">
    <material>Gazebo/Black</material>
  </gazebo>
  <gazebo reference="wheel_hip_2">
    <material>Gazebo/Black</material>
  </gazebo>
  <gazebo reference="wheel_hip_3">
    <material>Gazebo/Black</material>
  </gazebo>
  <gazebo reference="wheel_hip_4">
    <material>Gazebo/Black</material>
  </gazebo>
  <gazebo reference="wheel_hip_reference_1">
    <material>Gazebo/Blue</material>
  </gazebo>
  <gazebo reference="wheel_hip_reference_2">
    <material>Gazebo/Blue</material>
  </gazebo>
  <gazebo reference="wheel_hip_reference_3">
    <material>Gazebo/Blue</material>
  </gazebo>
  <gazebo reference="wheel_hip_reference_4">
    <material>Gazebo/Blue</material>
  </gazebo>
  <gazebo reference="wheel_knee_1">
    <material>Gazebo/Black</material>
  </gazebo>
  <gazebo reference="wheel_knee_2">
    <material>Gazebo/Black</material>
  </gazebo>
  <gazebo reference="wheel_knee_3">
    <material>Gazebo/Black</material>
  </gazebo>
  <gazebo reference="wheel_knee_4">
    <material>Gazebo/Black</material>
  </gazebo>
  <gazebo reference="wheel_knee_reference_1">
    <material>Gazebo/Blue</material>
  </gazebo>
  <gazebo reference="wheel_knee_reference_2">
    <material>Gazebo/Blue</material>
  </gazebo>
  <gazebo reference="wheel_knee_reference_3">
    <material>Gazebo/Blue</material>
  </gazebo>
  <gazebo reference="wheel_knee_reference_4">
    <material>Gazebo/Blue</material>
  </gazebo>
  <!-- /VISUALiZATION AND FRICTION -->
  <material name="grey">
    <color rgba="0.5 0.5 0.5 1"/>
  </material>
  <material name="dark_grey">
    <color rgba="0.3 0.3 0.3 1"/>
  </material>
  <material name="blue">
    <color rgba="0.0 0.2 0.3 1"/>
  </material>
  <material name="red">
    <color rgba="0.5 0.1 0.2 1"/>
  </material>
  <material name="black">
    <color rgba="0.0 0.0 0.0 1"/>
  </material>
  <!-- Here all arguments from launch file are evaluated to the final xacro poropeties.
     Also all the parameter dependencies are resolved-->
  <!-- load proper collision model -->
  <!-- load proper collision model -->
  <!-- Here all arguments from launch file are evaluated to the final xacro poropeties.
     Also all the parameter dependencies are resolved-->
  <!-- load proper collision model -->
  <!-- load proper collision model -->
  <!-- /macro arms -->
  <!-- /other files -->
  <!-- reference -->
  <link name="world"/>
  <link name="base_link"/>
  <link name="load">
    <visual>
      <origin rpy="0 0 0" xyz="0.0 0.0 0.0"/>
      <geometry>
        <box size="0.1 0.2 0.4"/>
      </geometry>
    </visual>
    <collision>
      <origin rpy="0 0 0" xyz="0.0 0.0 0.0"/>
      <geometry>
        <box size="0.1 0.2 0.4"/>
      </geometry>
    </collision>
    <inertial>
      <origin rpy="0 0 0" xyz="0.0 0.0 0.0"/>
      <mass value="20"/>
      <inertia ixx="0.2" ixy="0.0" ixz="0.0" iyy="0.2" iyz="0.0" izz="0.1"/>
    </inertial>
  </link>
  <joint name="floating_base" type="floating">
    <origin rpy="0 0 0" xyz="0.0 0.0 0.6"/>
    <parent link="world"/>
    <child link="base_link"/>
  </joint>
  <joint name="load_joint" type="fixed">
    <origin rpy="0 0 0" xyz="0.04 0.0 0.4"/>
    <parent link="base_link"/>
    <child link="load"/>
  </joint>
  <!-- torso links -->
  <link name="torso_2">
    <inertial>
      <origin xyz="0.0047281261 0.00038307386 0.14972892"/>
      <mass value="4.5494226"/>
      <!-- mass  7: torso_1 (2) + torso_2 (5), head un_modelled -->
      <inertia ixx="0.063643392" ixy="8.939e-05" ixz="-0.00086873" iyy="0.02680235" iyz="-4.657e-05" izz="0.04743015"/>
    </inertial>
    <visual>
      <origin rpy="0.0 0.0 0.0" xyz="0.0 0 0.0"/>
      <geometry>
        <mesh filename="package://centauro/centauro_urdf/meshes/link1.stl" scale="0.001 0.001 0.001"/>
      </geometry>
    </visual>
    <collision>
      <origin rpy="0.0 0.0 0.0" xyz="0.0 0 0.0"/>
      <geometry>
        <mesh filename="package://centauro/centauro_urdf/meshes/convex_hull/link1.stl" scale="0.001 0.001 0.001"/>
      </geometry>
    </collision>
  </link>
  <link name="imu_link">
    <inertial>
      <mass value="0.0"/>
      <!-- mass  7: torso_1 (2) + torso_2 (5), head un_modelled -->
      <inertia ixx="0.0" ixy="0.0" ixz="0.0" iyy="0.0" iyz="0.0" izz="0.0"/>
    </inertial>
  </link>
  <!-- /torso links -->
  <!-- torso joints -->
  <joint name="base_joint" type="fixed">
    <parent link="base_link"/>
    <child link="torso_2"/>
    <origin rpy="0 0 0" xyz="0 0 0"/>
  </joint>
  <joint name="imu_joint" type="fixed">
    <parent link="torso_2"/>
    <child link="imu_link"/>
    <origin xyz="-0.0704 0.0 -0.0416"/>
  </joint>
  <!-- /torso -->
  <!-- LINKS -->
  <!-- shoulder yaw-roll-->
  <link name="arm1_1">
    <inertial>
      <origin xyz="-0.0031005886 0.040324584 0.007451937"/>
      <mass value="1.5583338"/>
      <inertia ixx="0.0032318636" ixy="4.24587e-05" ixz="4.91626e-05" iyy="0.00275718" iyz="-0.0002387056" izz="0.004275047"/>
    </inertial>
    <visual>
      <origin rpy="0.0 0.0 0.0" xyz="0.0 0.0 0.0"/>
      <geometry>
        <mesh filename="package://centauro/centauro_urdf/meshes/link2.stl" scale="0.001 -0.001 0.001"/>
      </geometry>
      <material name="dark_grey"/>
    </visual>
    <collision>
      <origin rpy="0.0 0.0 0.0" xyz="0.0 0.0 0.0"/>
      <geometry>
        <mesh filename="package://centauro/centauro_urdf/meshes/convex_hull/link2.stl" scale="0.001 -0.001 0.001"/>
      </geometry>
    </collision>
  </link>
  <!-- shoulder yaw-roll-->
  <!-- shoulder roll-pitch-->
  <link name="arm1_2">
    <inertial>
      <origin xyz="0.05105435 0.00011109 -0.07643596"/>
      <mass value="1.515061"/>
      <inertia ixx="0.01029558" ixy="2.846e-05" ixz="0.0036567" iyy="0.01178018" iyz="2.088e-05" izz="0.00386123"/>
    </inertial>
    <visual>
      <origin rpy="0.0 0.0 0.0" xyz="0.0 0.0 0.0"/>
      <geometry>
        <mesh filename="package://centauro/centauro_urdf/meshes/link3.stl" scale="0.001 -0.001 0.001"/>
      </geometry>
    </visual>
    <collision>
      <origin rpy="0.0 0.0 0.0" xyz="0.0 0.0 0.0"/>
      <geometry>
        <mesh filename="package://centauro/centauro_urdf/meshes/convex_hull/link3.stl" scale="0.001 -0.001 0.001"/>
      </geometry>
    </collision>
  </link>
  <!-- shoulder roll-pitch-->
  <!-- shoulder-elbow -->
  <link name="arm1_3">
    <inertial>
      <origin xyz="0.01207624 0.00322013 -0.03427312"/>
      <mass value="1.5088101"/>
      <inertia ixx="0.00469819" ixy="-0.00026547" ixz="0.00077706" iyy="0.00501755" iyz="0.00029679" izz="0.00310954"/>
    </inertial>
    <visual>
      <origin rpy="0.0 0.0 0.0" xyz="0.0 0.0 0.0"/>
      <geometry>
        <mesh filename="package://centauro/centauro_urdf/meshes/link4.stl" scale="0.001 -0.001 0.001"/>
      </geometry>
      <material name="dark_grey"/>
    </visual>
    <collision>
      <origin rpy="0.0 0.0 0.0" xyz="0.0 0.0 0.0"/>
      <geometry>
        <mesh filename="package://centauro/centauro_urdf/meshes/convex_hull/link4.stl" scale="0.001 -0.001 0.001"/>
      </geometry>
    </collision>
  </link>
  <!-- /shoulder-elbow -->
  <!-- elbow yaw-pitch -->
  <link name="arm1_4">
    <inertial>
      <origin xyz="0.010147552 -0.029928537 -0.032528288"/>
      <mass value="0.96297329"/>
      <inertia ixx="0.0026493567" ixy="5.1632e-06" ixz="0.0001292309" iyy="0.0023470955" iyz="-0.0007895755" izz="0.0012213063"/>
    </inertial>
    <visual>
      <origin rpy="0.0 0.0 0.0" xyz="0.0 0.0 0.0"/>
      <geometry>
        <mesh filename="package://centauro/centauro_urdf/meshes/link5.stl" scale="0.001 -0.001 0.001"/>
      </geometry>
    </visual>
    <collision>
      <origin rpy="0.0 0.0 0.0" xyz="0.0 0.0 0.0"/>
      <geometry>
        <mesh filename="package://centauro/centauro_urdf/meshes/convex_hull/link5.stl" scale="0.001 -0.001 0.001"/>
      </geometry>
    </collision>
  </link>
  <!-- /elbow yaw-pitch -->
  <!-- elbow-wrist -->
  <link name="arm1_5">
    <inertial>
      <origin xyz="-0.0001574443 0.0041320907 -0.10756614"/>
      <mass value="1.4703698"/>
      <inertia ixx="0.0064160453" ixy="1.96382e-05" ixz="2.49912e-05" iyy="0.0062016367" iyz="-0.0001987903" izz="0.0017091658"/>
    </inertial>
    <visual>
      <origin rpy="0.0 0.0 0.0" xyz="0.0 0.0 0.0"/>
      <geometry>
        <mesh filename="package://centauro/centauro_urdf/meshes/link6.stl" scale="0.001 -0.001 0.001"/>
      </geometry>
      <material name="dark_grey"/>
    </visual>
    <collision>
      <origin rpy="0.0 0.0 0.0" xyz="0.0 0.0 0.0"/>
      <geometry>
        <mesh filename="package://centauro/centauro_urdf/meshes/convex_hull/link6.stl" scale="0.001 -0.001 0.001"/>
      </geometry>
    </collision>
  </link>
  <!-- /elbow-wrist -->
  <!-- wrist yaw-pitch -->
  <link name="arm1_6">
    <inertial>
      <origin xyz="3.23645e-05 -0.035947237 -0.080878061"/>
      <mass value="0.94693868"/>
      <inertia ixx="0.0036896582" ixy="2.63667e-05" ixz="1.4005e-06" iyy="0.0034146283" iyz="-0.0008268103" izz="0.0010790183"/>
    </inertial>
    <visual>
      <origin rpy="0.0 0.0 0.0" xyz="0.0 0.0 0.0"/>
      <geometry>
        <mesh filename="package://centauro/centauro_urdf/meshes/link7.stl" scale="0.001 -0.001 0.001"/>
      </geometry>
    </visual>
    <collision>
      <origin rpy="0.0 0.0 0.0" xyz="0.0 0.0 0.0"/>
      <geometry>
        <mesh filename="package://centauro/centauro_urdf/meshes/convex_hull/link7.stl" scale="0.001 -0.001 0.001"/>
      </geometry>
    </collision>
  </link>
  <!-- /wrist yaw-pitch -->
  <link name="arm1_7">
    <inertial>
      <origin xyz="2.46596e-05 -0.0001467705 -0.0052993013"/>
      <mass value="0.55981036"/>
      <inertia ixx="0.0004360175" ixy="1.397e-07" ixz="-1.382e-07" iyy="0.0004299166" iyz="-1.4752e-06" izz="0.0004522224"/>
    </inertial>
    <visual>
      <origin rpy="0.0 0.0 0.0" xyz="0.0 0.0 0.0"/>
      <geometry>
        <mesh filename="package://centauro/centauro_urdf/meshes/link8.stl" scale="0.001 -0.001 0.001"/>
      </geometry>
      <material name="dark_grey"/>
    </visual>
    <collision>
      <origin rpy="0.0 0.0 0.0" xyz="0.0 0.0 0.0"/>
      <geometry>
        <mesh filename="package://centauro/centauro_urdf/meshes/convex_hull/link8.stl" scale="0.001 -0.001 0.001"/>
      </geometry>
    </collision>
  </link>
  <!-- /LINKS -->
  <!-- JOINTS -->
  <!-- shoulder yaw -->
  <joint name="j_arm1_1" type="revolute">
    <parent link="torso_2"/>
    <child link="arm1_1"/>
    <origin rpy="0.0 0.0 -0.523602668986" xyz="0.04576 0.169137 0.190626"/>
    <axis xyz="0 0.984807753012 0.173648177667"/>
    <!--          <limit lower="-3.403" upper="1.658" effort="147" velocity="5.7"/> -->
    <limit effort="147" lower="-3.0" upper="3.0" velocity="5.7"/>
  </joint>
  <!-- /shoulder yaw -->
  <!-- shoulder roll -->
  <joint name="j_arm1_2" type="revolute">
    <parent link="arm1_1"/>
    <child link="arm1_2"/>
    <origin xyz="-0.09115 0.06106 0.010766"/>
    <axis xyz="-1 0 0"/>
    <!--          <limit lower="-3.49" upper="0" effort="147" velocity="5.7"/> -->
    <limit effort="147" lower="-3.0" upper="3.0" velocity="5.7"/>
  </joint>
  <!-- /shoulder roll -->
  <!-- shoulder pitch-->
  <joint name="j_arm1_3" type="revolute">
    <parent link="arm1_2"/>
    <child link="arm1_3"/>
    <origin xyz="0.09115 0.0 -0.21915"/>
    <axis xyz="0 0 -1"/>
    <!--       <limit lower="-2.618" upper="2.618" effort="147" velocity="8.2"/> -->
    <limit effort="147" lower="-3.0" upper="3.0" velocity="5.7"/>
  </joint>
  <!-- /shoulder pitch -->
  <!-- elbow yaw -->
  <joint name="j_arm1_4" type="revolute">
    <parent link="arm1_3"/>
    <child link="arm1_4"/>
    <origin xyz="0.04 0.05615 -0.074"/>
    <axis xyz="0 1 0"/>
    <!--          <limit lower="-2.530" upper="0.349" effort="147" velocity="8.2"/> -->
    <limit effort="147" lower="-3.0" upper="3.0" velocity="5.7"/>
  </joint>
  <!-- /elbow yaw -->
  <!-- elbow pitch-->
  <joint name="j_arm1_5" type="revolute">
    <parent link="arm1_4"/>
    <child link="arm1_5"/>
    <origin xyz="-0.015 -0.05615 -0.061"/>
    <axis xyz="0 0 -1"/>
    <!--       <limit lower="-2.618" upper="2.618" effort="55" velocity="11.6"/> -->
    <limit effort="147" lower="-3.0" upper="3.0" velocity="5.7"/>
  </joint>
  <!-- /elbow pitch-->
  <!-- wrist yaw-->
  <joint name="j_arm1_6" type="revolute">
    <parent link="arm1_5"/>
    <child link="arm1_6"/>
    <origin xyz="0.0 0.049 -0.18"/>
    <axis xyz="0 1 0"/>
    <!--       <limit lower="-1.570" upper="1.570" effort="55" velocity="11.6"/> -->
    <limit effort="147" lower="-3.0" upper="3.0" velocity="5.7"/>
  </joint>
  <!-- /wrist yaw-->
  <!-- wrist pitch-->
  <joint name="j_arm1_7" type="revolute">
    <parent link="arm1_6"/>
    <child link="arm1_7"/>
    <origin xyz="0.0 -0.049 -0.169"/>
    <axis xyz="0 0 -1"/>
    <!--       <limit lower="-2.618" upper="2.618" effort="27" velocity="20.3"/> -->
    <limit effort="147" lower="-3.0" upper="3.0" velocity="5.7"/>
  </joint>
  <!-- wrist pitch-->
  <!-- force-troque sensor -->
  <transmission name="t_j_arm1_1">
    <type> transmission_interface/SimpleTransmission</type>
    <joint name="j_arm1_1">
      <hardwareInterface>EffortJointInterface</hardwareInterface>
    </joint>
    <actuator name="motor_j_arm1_1">
      <hardwareInterface>EffortJointInterface</hardwareInterface>
      <machanicalReduction>1</machanicalReduction>
    </actuator>
    <robotNamespace>/centauro</robotNamespace>
  </transmission>
  <transmission name="t_j_arm1_2">
    <type> transmission_interface/SimpleTransmission</type>
    <joint name="j_arm1_2">
      <hardwareInterface>EffortJointInterface</hardwareInterface>
    </joint>
    <actuator name="motor_j_arm1_2">
      <hardwareInterface>EffortJointInterface</hardwareInterface>
      <machanicalReduction>1</machanicalReduction>
    </actuator>
    <robotNamespace>/centauro</robotNamespace>
  </transmission>
  <transmission name="t_j_arm1_3">
    <type> transmission_interface/SimpleTransmission</type>
    <joint name="j_arm1_3">
      <hardwareInterface>EffortJointInterface</hardwareInterface>
    </joint>
    <actuator name="motor_j_arm1_3">
      <hardwareInterface>EffortJointInterface</hardwareInterface>
      <machanicalReduction>1</machanicalReduction>
    </actuator>
    <robotNamespace>/centauro</robotNamespace>
  </transmission>
  <transmission name="t_j_arm1_4">
    <type> transmission_interface/SimpleTransmission</type>
    <joint name="j_arm1_4">
      <hardwareInterface>EffortJointInterface</hardwareInterface>
    </joint>
    <actuator name="motor_j_arm1_4">
      <hardwareInterface>EffortJointInterface</hardwareInterface>
      <machanicalReduction>1</machanicalReduction>
    </actuator>
    <robotNamespace>/centauro</robotNamespace>
  </transmission>
  <transmission name="t_j_arm1_5">
    <type> transmission_interface/SimpleTransmission</type>
    <joint name="j_arm1_5">
      <hardwareInterface>EffortJointInterface</hardwareInterface>
    </joint>
    <actuator name="motor_j_arm1_5">
      <hardwareInterface>EffortJointInterface</hardwareInterface>
      <machanicalReduction>1</machanicalReduction>
    </actuator>
    <robotNamespace>/centauro</robotNamespace>
  </transmission>
  <transmission name="t_j_arm1_6">
    <type> transmission_interface/SimpleTransmission</type>
    <joint name="j_arm1_6">
      <hardwareInterface>EffortJointInterface</hardwareInterface>
    </joint>
    <actuator name="motor_j_arm1_6">
      <hardwareInterface>EffortJointInterface</hardwareInterface>
      <machanicalReduction>1</machanicalReduction>
    </actuator>
    <robotNamespace>/centauro</robotNamespace>
  </transmission>
  <transmission name="t_j_arm1_7">
    <type> transmission_interface/SimpleTransmission</type>
    <joint name="j_arm1_7">
      <hardwareInterface>EffortJointInterface</hardwareInterface>
    </joint>
    <actuator name="motor_j_arm1_7">
      <hardwareInterface>EffortJointInterface</hardwareInterface>
      <machanicalReduction>1</machanicalReduction>
    </actuator>
    <robotNamespace>/centauro</robotNamespace>
  </transmission>
  <!-- /actuators -->
  <!-- end-effector -->
  <!-- links -->
  <link name="arm1_8">
    <visual>
      <geometry>
        <box size="0.3 0.1 0.02"/>
        <!--box size="0.3 0.04 0.3"/-->
        <!--cylinder length="0.3" radius="0.02"/-->
      </geometry>
    </visual>
    <collision>
      <geometry>
        <box size="0.3 0.1 0.02"/>
        <!--box size="0.3 0.04 0.3"/-->
        <!--cylinder length="0.3" radius="0.02"/-->
      </geometry>
    </collision>
    <inertial>
      <mass value="0.01"/>
      <inertia ixx="0.001" ixy="0.0" ixz="0.0" iyy="0.001" iyz="0.0" izz="0.001"/>
    </inertial>
  </link>
  <!-- /links -->
  <!--xacro:if value="${arm_num == 1}">
        <joint name="j_arm${arm_num}_8" type="fixed">
            <parent link="arm${arm_num}_7"/>
            <child link="arm${arm_num}_8"/>
            <origin xyz="0 0 -0.05" rpy="0 0 0.0"/>
        </joint>
    </xacro:if>

    <xacro:if value="${arm_num == 2}">
        <joint name="j_arm${arm_num}_8" type="fixed">
            <parent link="arm${arm_num}_7"/>
            <child link="arm${arm_num}_8"/>
            <origin xyz="0 0 -0.05" rpy="0 0 -0.0"/>
        </joint>
    </xacro:if-->
  <!--origin xyz="0 0 -0.0605" rpy="0 1.5707 0.5"/-->
  <!--origin xyz="0 0 -0.0605" rpy="0 1.5707 -0.5"/-->
  <!-- /joints -->
  <joint name="j_arm1_8" type="fixed">
    <parent link="arm1_7"/>
    <child link="arm1_8"/>
    <origin rpy="0 0 0" xyz="0 0 -0.05"/>
  </joint>
  <!-- /end-effector -->
  <!-- LINKS -->
  <!-- shoulder yaw-roll-->
  <link name="arm2_1">
    <inertial>
      <origin xyz="-0.0031005886 -0.040324584 0.007451937"/>
      <mass value="1.5583338"/>
      <inertia ixx="0.0032318636" ixy="-4.24587e-05" ixz="4.91626e-05" iyy="0.00275718" iyz="0.0002387056" izz="0.004275047"/>
    </inertial>
    <visual>
      <origin rpy="0.0 0.0 0.0" xyz="0.0 0.0 0.0"/>
      <geometry>
        <mesh filename="package://centauro/centauro_urdf/meshes/link2.stl" scale="0.001 0.001 0.001"/>
      </geometry>
      <material name="dark_grey"/>
    </visual>
    <collision>
      <origin rpy="0.0 0.0 0.0" xyz="0.0 0.0 0.0"/>
      <geometry>
        <mesh filename="package://centauro/centauro_urdf/meshes/convex_hull/link2.stl" scale="0.001 0.001 0.001"/>
      </geometry>
    </collision>
  </link>
  <!-- shoulder yaw-roll-->
  <!-- shoulder roll-pitch-->
  <link name="arm2_2">
    <inertial>
      <origin xyz="0.05105435 -0.00011109 -0.07643596"/>
      <mass value="1.515061"/>
      <inertia ixx="0.01029558" ixy="-2.846e-05" ixz="0.0036567" iyy="0.01178018" iyz="-2.088e-05" izz="0.00386123"/>
    </inertial>
    <visual>
      <origin rpy="0.0 0.0 0.0" xyz="0.0 0.0 0.0"/>
      <geometry>
        <mesh filename="package://centauro/centauro_urdf/meshes/link3.stl" scale="0.001 0.001 0.001"/>
      </geometry>
    </visual>
    <collision>
      <origin rpy="0.0 0.0 0.0" xyz="0.0 0.0 0.0"/>
      <geometry>
        <mesh filename="package://centauro/centauro_urdf/meshes/convex_hull/link3.stl" scale="0.001 0.001 0.001"/>
      </geometry>
    </collision>
  </link>
  <!-- shoulder roll-pitch-->
  <!-- shoulder-elbow -->
  <link name="arm2_3">
    <inertial>
      <origin xyz="0.01207624 -0.00322013 -0.03427312"/>
      <mass value="1.5088101"/>
      <inertia ixx="0.00469819" ixy="0.00026547" ixz="0.00077706" iyy="0.00501755" iyz="-0.00029679" izz="0.00310954"/>
    </inertial>
    <visual>
      <origin rpy="0.0 0.0 0.0" xyz="0.0 0.0 0.0"/>
      <geometry>
        <mesh filename="package://centauro/centauro_urdf/meshes/link4.stl" scale="0.001 0.001 0.001"/>
      </geometry>
      <material name="dark_grey"/>
    </visual>
    <collision>
      <origin rpy="0.0 0.0 0.0" xyz="0.0 0.0 0.0"/>
      <geometry>
        <mesh filename="package://centauro/centauro_urdf/meshes/convex_hull/link4.stl" scale="0.001 0.001 0.001"/>
      </geometry>
    </collision>
  </link>
  <!-- /shoulder-elbow -->
  <!-- elbow yaw-pitch -->
  <link name="arm2_4">
    <inertial>
      <origin xyz="0.010147552 0.029928537 -0.032528288"/>
      <mass value="0.96297329"/>
      <inertia ixx="0.0026493567" ixy="-5.1632e-06" ixz="0.0001292309" iyy="0.0023470955" iyz="0.0007895755" izz="0.0012213063"/>
    </inertial>
    <visual>
      <origin rpy="0.0 0.0 0.0" xyz="0.0 0.0 0.0"/>
      <geometry>
        <mesh filename="package://centauro/centauro_urdf/meshes/link5.stl" scale="0.001 0.001 0.001"/>
      </geometry>
    </visual>
    <collision>
      <origin rpy="0.0 0.0 0.0" xyz="0.0 0.0 0.0"/>
      <geometry>
        <mesh filename="package://centauro/centauro_urdf/meshes/convex_hull/link5.stl" scale="0.001 0.001 0.001"/>
      </geometry>
    </collision>
  </link>
  <!-- /elbow yaw-pitch -->
  <!-- elbow-wrist -->
  <link name="arm2_5">
    <inertial>
      <origin xyz="-0.0001574443 -0.0041320907 -0.10756614"/>
      <mass value="1.4703698"/>
      <inertia ixx="0.0064160453" ixy="-1.96382e-05" ixz="2.49912e-05" iyy="0.0062016367" iyz="0.0001987903" izz="0.0017091658"/>
    </inertial>
    <visual>
      <origin rpy="0.0 0.0 0.0" xyz="0.0 0.0 0.0"/>
      <geometry>
        <mesh filename="package://centauro/centauro_urdf/meshes/link6.stl" scale="0.001 0.001 0.001"/>
      </geometry>
      <material name="dark_grey"/>
    </visual>
    <collision>
      <origin rpy="0.0 0.0 0.0" xyz="0.0 0.0 0.0"/>
      <geometry>
        <mesh filename="package://centauro/centauro_urdf/meshes/convex_hull/link6.stl" scale="0.001 0.001 0.001"/>
      </geometry>
    </collision>
  </link>
  <!-- /elbow-wrist -->
  <!-- wrist yaw-pitch -->
  <link name="arm2_6">
    <inertial>
      <origin xyz="3.23645e-05 0.035947237 -0.080878061"/>
      <mass value="0.94693868"/>
      <inertia ixx="0.0036896582" ixy="-2.63667e-05" ixz="1.4005e-06" iyy="0.0034146283" iyz="0.0008268103" izz="0.0010790183"/>
    </inertial>
    <visual>
      <origin rpy="0.0 0.0 0.0" xyz="0.0 0.0 0.0"/>
      <geometry>
        <mesh filename="package://centauro/centauro_urdf/meshes/link7.stl" scale="0.001 0.001 0.001"/>
      </geometry>
    </visual>
    <collision>
      <origin rpy="0.0 0.0 0.0" xyz="0.0 0.0 0.0"/>
      <geometry>
        <mesh filename="package://centauro/centauro_urdf/meshes/convex_hull/link7.stl" scale="0.001 0.001 0.001"/>
      </geometry>
    </collision>
  </link>
  <!-- /wrist yaw-pitch -->
  <link name="arm2_7">
    <inertial>
      <origin xyz="2.46596e-05 0.0001467705 -0.0052993013"/>
      <mass value="0.55981036"/>
      <inertia ixx="0.0004360175" ixy="-1.397e-07" ixz="-1.382e-07" iyy="0.0004299166" iyz="1.4752e-06" izz="0.0004522224"/>
    </inertial>
    <visual>
      <origin rpy="0.0 0.0 0.0" xyz="0.0 0.0 0.0"/>
      <geometry>
        <mesh filename="package://centauro/centauro_urdf/meshes/link8.stl" scale="0.001 0.001 0.001"/>
      </geometry>
      <material name="dark_grey"/>
    </visual>
    <collision>
      <origin rpy="0.0 0.0 0.0" xyz="0.0 0.0 0.0"/>
      <geometry>
        <mesh filename="package://centauro/centauro_urdf/meshes/convex_hull/link8.stl" scale="0.001 0.001 0.001"/>
      </geometry>
    </collision>
  </link>
  <!-- /LINKS -->
  <!-- JOINTS -->
  <!-- shoulder yaw -->
  <joint name="j_arm2_1" type="revolute">
    <parent link="torso_2"/>
    <child link="arm2_1"/>
    <origin rpy="0.0 0.0 0.523602668986" xyz="0.04576 -0.169137 0.190626"/>
    <axis xyz="0 -0.984807753012 0.173648177667"/>
    <!--          <limit lower="-1.658" upper="3.403" effort="147" velocity="5.7"/> -->
    <limit effort="147" lower="-3.0" upper="3.0" velocity="5.7"/>
  </joint>
  <!-- /shoulder yaw -->
  <!-- shoulder roll -->
  <joint name="j_arm2_2" type="revolute">
    <parent link="arm2_1"/>
    <child link="arm2_2"/>
    <origin xyz="-0.09115 -0.06106 0.010766"/>
    <axis xyz="-1 0 0"/>
    <!--          <limit lower="0" upper="3.49" effort="147" velocity="5.7"/> -->
    <limit effort="147" lower="-3.0" upper="3.0" velocity="5.7"/>
  </joint>
  <!-- /shoulder roll -->
  <!-- shoulder pitch-->
  <joint name="j_arm2_3" type="revolute">
    <parent link="arm2_2"/>
    <child link="arm2_3"/>
    <origin xyz="0.09115 0.0 -0.21915"/>
    <axis xyz="0 0 -1"/>
    <!--       <limit lower="-2.618" upper="2.618" effort="147" velocity="8.2"/> -->
    <limit effort="147" lower="-3.0" upper="3.0" velocity="5.7"/>
  </joint>
  <!-- /shoulder pitch -->
  <!-- elbow yaw -->
  <joint name="j_arm2_4" type="revolute">
    <parent link="arm2_3"/>
    <child link="arm2_4"/>
    <origin xyz="0.04 -0.05615 -0.074"/>
    <axis xyz="0 -1 0"/>
    <!--          <limit lower="-0.349" upper="2.530" effort="147" velocity="8.2"/> -->
    <limit effort="147" lower="-3.0" upper="3.0" velocity="5.7"/>
  </joint>
  <!-- /elbow yaw -->
  <!-- elbow pitch-->
  <joint name="j_arm2_5" type="revolute">
    <parent link="arm2_4"/>
    <child link="arm2_5"/>
    <origin xyz="-0.015 0.05615 -0.061"/>
    <axis xyz="0 0 -1"/>
    <!--       <limit lower="-2.618" upper="2.618" effort="55" velocity="11.6"/> -->
    <limit effort="147" lower="-3.0" upper="3.0" velocity="5.7"/>
  </joint>
  <!-- /elbow pitch-->
  <!-- wrist yaw-->
  <joint name="j_arm2_6" type="revolute">
    <parent link="arm2_5"/>
    <child link="arm2_6"/>
    <origin xyz="0.0 -0.049 -0.18"/>
    <axis xyz="0 -1 0"/>
    <!--       <limit lower="-1.570" upper="1.570" effort="55" velocity="11.6"/> -->
    <limit effort="147" lower="-3.0" upper="3.0" velocity="5.7"/>
  </joint>
  <!-- /wrist yaw-->
  <!-- wrist pitch-->
  <joint name="j_arm2_7" type="revolute">
    <parent link="arm2_6"/>
    <child link="arm2_7"/>
    <origin xyz="0.0 0.049 -0.169"/>
    <axis xyz="0 0 -1"/>
    <!--       <limit lower="-2.618" upper="2.618" effort="27" velocity="20.3"/> -->
    <limit effort="147" lower="-3.0" upper="3.0" velocity="5.7"/>
  </joint>
  <!-- wrist pitch-->
  <!-- force-troque sensor -->
  <transmission name="t_j_arm2_1">
    <type> transmission_interface/SimpleTransmission</type>
    <joint name="j_arm2_1">
      <hardwareInterface>EffortJointInterface</hardwareInterface>
    </joint>
    <actuator name="motor_j_arm2_1">
      <hardwareInterface>EffortJointInterface</hardwareInterface>
      <machanicalReduction>1</machanicalReduction>
    </actuator>
    <robotNamespace>/centauro</robotNamespace>
  </transmission>
  <transmission name="t_j_arm2_2">
    <type> transmission_interface/SimpleTransmission</type>
    <joint name="j_arm2_2">
      <hardwareInterface>EffortJointInterface</hardwareInterface>
    </joint>
    <actuator name="motor_j_arm2_2">
      <hardwareInterface>EffortJointInterface</hardwareInterface>
      <machanicalReduction>1</machanicalReduction>
    </actuator>
    <robotNamespace>/centauro</robotNamespace>
  </transmission>
  <transmission name="t_j_arm2_3">
    <type> transmission_interface/SimpleTransmission</type>
    <joint name="j_arm2_3">
      <hardwareInterface>EffortJointInterface</hardwareInterface>
    </joint>
    <actuator name="motor_j_arm2_3">
      <hardwareInterface>EffortJointInterface</hardwareInterface>
      <machanicalReduction>1</machanicalReduction>
    </actuator>
    <robotNamespace>/centauro</robotNamespace>
  </transmission>
  <transmission name="t_j_arm2_4">
    <type> transmission_interface/SimpleTransmission</type>
    <joint name="j_arm2_4">
      <hardwareInterface>EffortJointInterface</hardwareInterface>
    </joint>
    <actuator name="motor_j_arm2_4">
      <hardwareInterface>EffortJointInterface</hardwareInterface>
      <machanicalReduction>1</machanicalReduction>
    </actuator>
    <robotNamespace>/centauro</robotNamespace>
  </transmission>
  <transmission name="t_j_arm2_5">
    <type> transmission_interface/SimpleTransmission</type>
    <joint name="j_arm2_5">
      <hardwareInterface>EffortJointInterface</hardwareInterface>
    </joint>
    <actuator name="motor_j_arm2_5">
      <hardwareInterface>EffortJointInterface</hardwareInterface>
      <machanicalReduction>1</machanicalReduction>
    </actuator>
    <robotNamespace>/centauro</robotNamespace>
  </transmission>
  <transmission name="t_j_arm2_6">
    <type> transmission_interface/SimpleTransmission</type>
    <joint name="j_arm2_6">
      <hardwareInterface>EffortJointInterface</hardwareInterface>
    </joint>
    <actuator name="motor_j_arm2_6">
      <hardwareInterface>EffortJointInterface</hardwareInterface>
      <machanicalReduction>1</machanicalReduction>
    </actuator>
    <robotNamespace>/centauro</robotNamespace>
  </transmission>
  <transmission name="t_j_arm2_7">
    <type> transmission_interface/SimpleTransmission</type>
    <joint name="j_arm2_7">
      <hardwareInterface>EffortJointInterface</hardwareInterface>
    </joint>
    <actuator name="motor_j_arm2_7">
      <hardwareInterface>EffortJointInterface</hardwareInterface>
      <machanicalReduction>1</machanicalReduction>
    </actuator>
    <robotNamespace>/centauro</robotNamespace>
  </transmission>
  <!-- /actuators -->
  <!-- end-effector -->
  <!-- links -->
  <link name="arm2_8">
    <visual>
      <geometry>
        <box size="0.3 0.1 0.02"/>
        <!--box size="0.3 0.04 0.3"/-->
        <!--cylinder length="0.3" radius="0.02"/-->
      </geometry>
    </visual>
    <collision>
      <geometry>
        <box size="0.3 0.1 0.02"/>
        <!--box size="0.3 0.04 0.3"/-->
        <!--cylinder length="0.3" radius="0.02"/-->
      </geometry>
    </collision>
    <inertial>
      <mass value="0.01"/>
      <inertia ixx="0.001" ixy="0.0" ixz="0.0" iyy="0.001" iyz="0.0" izz="0.001"/>
    </inertial>
  </link>
  <!-- /links -->
  <!--xacro:if value="${arm_num == 1}">
        <joint name="j_arm${arm_num}_8" type="fixed">
            <parent link="arm${arm_num}_7"/>
            <child link="arm${arm_num}_8"/>
            <origin xyz="0 0 -0.05" rpy="0 0 0.0"/>
        </joint>
    </xacro:if>

    <xacro:if value="${arm_num == 2}">
        <joint name="j_arm${arm_num}_8" type="fixed">
            <parent link="arm${arm_num}_7"/>
            <child link="arm${arm_num}_8"/>
            <origin xyz="0 0 -0.05" rpy="0 0 -0.0"/>
        </joint>
    </xacro:if-->
  <!--origin xyz="0 0 -0.0605" rpy="0 1.5707 0.5"/-->
  <!--origin xyz="0 0 -0.0605" rpy="0 1.5707 -0.5"/-->
  <!-- /joints -->
  <joint name="j_arm2_8" type="fixed">
    <parent link="arm2_7"/>
    <child link="arm2_8"/>
    <origin rpy="0 0 0" xyz="0 0 -0.05"/>
  </joint>
  <!-- /end-effector -->
  <!-- /arms -->
  <!-- /legs -->
</robot>

