<?xml version="1.0"?>
<robot name="centauro">
  <material name="grey">
    <color rgba="0.5 0.5 0.5 1.0"/>
  </material>
  <material name="dark_grey">
    <color rgba="0.3 0.3 0.3 1.0"/>
  </material>
  <material name="blue">
    <color rgba="0.0 0.2 0.3 1.0"/>
  </material>
  <material name="red">
    <color rgba="0.5 0.1 0.2 1.0"/>
  </material>
  <material name="black">
    <color rgba="0.0 0.0 0.0 1.0"/>
  </material>
  <link name="world"/>
  <link name="pelvis">
    <inertial>
      <origin xyz="0.0013890071 -0.0015989148 0.063101012"/>
      <mass value="16.097574"/>
      <inertia ixx="0.23912627" ixy="-0.0050541269" ixz="-0.019746055" iyy="0.71430078" iyz="0.0002131204" izz="0.81870448"/>
    </inertial>
    <visual>
      <origin xyz="0.0 0.0 0.0" rpy="0.0 0.0 0.0"/>
      <geometry>
        <mesh filename="package://centauro/centauro_urdf/meshes/simplified/pelvis.stl" scale="0.001 0.001 0.001"/>
      </geometry>
    </visual>
    <collision>
      <origin xyz="-0.005085 2.00284e-07 0.03057945" rpy="3.14158470812 1.54787296367 3.14158452386"/>
      <geometry>
        <cylinder radius="0.213204" length="0.385941397914"/>
      </geometry>
    </collision>
  </link>
  <link name="imu_link">
    <inertial>
      <mass value="0.0"/>
      <inertia ixx="0.0" ixy="0.0" ixz="0.0" iyy="0.0" iyz="0.0" izz="0.0"/>
    </inertial>
  </link>
  <joint name="imu_joint" type="fixed">
    <origin xyz="0.248316 0.0 0.015" rpy="0.0 0.0 0.0"/>
    <parent link="pelvis"/>
    <child link="imu_link"/>
  </joint>
  <joint name="reference" type="floating">
    <origin xyz="0.0 0.0 0.93445"/>
    <parent link="world"/>
    <child link="pelvis"/>
  </joint>
  <link name="torso_2">
    <inertial>
      <origin xyz="-0.019497794 0.0045317835 0.13768283"/>
      <mass value="11.492689"/>
      <inertia ixx="0.063643392" ixy="8.939e-05" ixz="-0.00086873" iyy="0.02680235" iyz="-4.657e-05" izz="0.04743015"/>
    </inertial>
    <visual>
      <origin xyz="0.0 0.0 0.0" rpy="0.0 0.0 0.0"/>
      <geometry>
        <mesh filename="package://centauro/centauro_urdf/meshes/simplified/link1.stl" scale="0.001 0.001 0.001"/>
      </geometry>
    </visual>
    <collision>
      <origin xyz="0.013239935 1.50245845e-05 0.1846655" rpy="-0.000238335444242 0.104581190719 -1.24740737196e-05"/>
      <geometry>
        <cylinder radius="0.200841" length="0.128018449088"/>
      </geometry>
    </collision>
  </link>
  <joint name="torso_yaw" type="revolute">
    <origin xyz="0.2 0.0 0.256"/>
    <axis xyz="0.0 0.0 1.0"/>
    <parent link="pelvis"/>
    <child link="torso_2"/>
    <limit effort="147.0" lower="-2.618" upper="2.618" velocity="5.7"/>
  </joint>
  <transmission name="t_torso_yaw">
    <type> transmission_interface/SimpleTransmission</type>
    <joint name="torso_yaw">
      <hardwareInterface>hardware_interface/EffortJointInterface</hardwareInterface>
    </joint>
    <actuator name="motor_torso_yaw"/>
  </transmission>
  <link name="neck_1">
    <inertial>
      <origin xyz="0.040479674 0.021377573 -0.014595112"/>
      <mass value="0.33878686"/>
      <inertia ixx="0.0003718568" ixy="-9.42983e-05" ixz="-2.80644e-05" iyy="0.0001886879" iyz="-1.54534e-05" izz="0.0005023443"/>
    </inertial>
    <visual>
      <origin xyz="0.0 0.0 0.0" rpy="0.0 0.0 0.0"/>
      <geometry>
        <mesh filename="package://centauro/centauro_urdf/meshes/simplified/neck_yaw.stl" scale="0.001 0.001 0.001"/>
      </geometry>
    </visual>
    <collision>
      <origin xyz="0.0425149 -0.0014473 -0.01248935" rpy="-1.57305341022 -0.00299119404279 0.00299795303785"/>
      <geometry>
        <cylinder radius="0.0257769" length="0.10965536987"/>
      </geometry>
    </collision>
  </link>
  <link name="neck_2">
    <inertial>
      <origin xyz="0.048466918 -0.059852318 -0.0085314894"/>
      <mass value="0.78526942"/>
      <inertia ixx="0.0004682345" ixy="-1.05438e-05" ixz="7.24398e-05" iyy="0.0002635246" iyz="1.6904e-06" izz="0.0003763351"/>
    </inertial>
    <visual>
      <origin xyz="0.0 0.0 0.0" rpy="0.0 0.0 0.0"/>
      <geometry>
        <mesh filename="package://centauro/centauro_urdf/meshes/simplified/neck_pitch.stl" scale="0.001 0.001 0.001"/>
      </geometry>
    </visual>
    <collision>
      <origin xyz="0.023829 -0.062319525 0.018136" rpy="-1.5996596279 0.0583612572025 -0.0600695290579"/>
      <geometry>
        <cylinder radius="0.0423975" length="0.111328782421"/>
      </geometry>
    </collision>
  </link>
  <link name="neck_3">
    <inertial>
      <origin xyz="0.048466918 -0.059852318 -0.0085314894"/>
      <mass value="0.78526942"/>
      <inertia ixx="0.0004682345" ixy="-1.05438e-05" ixz="7.24398e-05" iyy="0.0002635246" iyz="1.6904e-06" izz="0.0003763351"/>
    </inertial>
    <visual>
      <origin xyz="0.0 0.0 0.0" rpy="0.0 0.0 0.0"/>
      <geometry>
        <mesh filename="package://centauro/centauro_urdf/meshes/simplified/velodyne.stl" scale="0.001 0.001 0.001"/>
      </geometry>
    </visual>
    <collision>
      <origin xyz="-0.074374 -2.66794655e-08 -0.02476945" rpy="3.18868402297e-06 1.42695449915 2.76010263301e-06"/>
      <geometry>
        <cylinder radius="0.0519914" length="0.114524744064"/>
      </geometry>
    </collision>
  </link>
  <link name="camera_central">
    <inertial>
      <origin xyz="0.0 0.0 0.0"/>
      <mass value="0.1"/>
      <inertia ixx="1e-06" ixy="0.0" ixz="0.0" iyy="1e-06" iyz="0.0" izz="1e-06"/>
    </inertial>
  </link>
  <link name="camera_left">
    <inertial>
      <origin xyz="0.0 0.0 0.0"/>
      <mass value="0.1"/>
      <inertia ixx="1e-06" ixy="0.0" ixz="0.0" iyy="1e-06" iyz="0.0" izz="1e-06"/>
    </inertial>
  </link>
  <link name="camera_right">
    <inertial>
      <origin xyz="0.0 0.0 0.0"/>
      <mass value="0.1"/>
      <inertia ixx="1e-06" ixy="0.0" ixz="0.0" iyy="1e-06" iyz="0.0" izz="1e-06"/>
    </inertial>
  </link>
  <link name="kinect">
    <inertial>
      <origin xyz="0.0 0.0 0.0"/>
      <mass value="0.1"/>
      <inertia ixx="1e-06" ixy="0.0" ixz="0.0" iyy="1e-06" iyz="0.0" izz="1e-06"/>
    </inertial>
  </link>
  <link name="velodyne_mount">
    <inertial>
      <origin xyz="0.0 0.0 0.0"/>
      <mass value="0.1"/>
      <inertia ixx="1e-06" ixy="0.0" ixz="0.0" iyy="1e-06" iyz="0.0" izz="1e-06"/>
    </inertial>
  </link>
  <joint name="neck_yaw" type="revolute">
    <origin xyz="0.0 0.0 0.2795"/>
    <axis xyz="0.0 0.0 1.0"/>
    <parent link="torso_2"/>
    <child link="neck_1"/>
    <limit effort="35.0" lower="-0.78539816" upper="0.78539816" velocity="5.7"/>
    <dynamics friction="10.0"/>
  </joint>
  <joint name="neck_pitch" type="revolute">
    <origin xyz="0.054 0.0596 -0.0124975"/>
    <axis xyz="0.0 1.0 0.0"/>
    <parent link="neck_1"/>
    <child link="neck_2"/>
    <limit effort="35.0" lower="-0.34906585" upper="0.78539816" velocity="5.7"/>
    <dynamics friction="10.0"/>
  </joint>
  <joint name="neck_velodyne" type="continuous">
    <origin xyz="0.055 0.0 0.473262"/>
    <axis xyz="0.0 0.0 1.0"/>
    <parent link="torso_2"/>
    <child link="neck_3"/>
    <limit effort="35.0" velocity="5.7"/>
    <dynamics damping="0.2" friction="10.0"/>
  </joint>
  <transmission name="t_neck_yaw">
    <type> transmission_interface/SimpleTransmission</type>
    <joint name="neck_yaw">
      <hardwareInterface>hardware_interface/EffortJointInterface</hardwareInterface>
    </joint>
    <actuator name="motor_neck_yaw"/>
  </transmission>
  <transmission name="t_neck_pitch">
    <type> transmission_interface/SimpleTransmission</type>
    <joint name="neck_pitch">
      <hardwareInterface>hardware_interface/EffortJointInterface</hardwareInterface>
    </joint>
    <actuator name="motor_neck_pitch"/>
  </transmission>
  <transmission name="t_neck_velodyne">
    <type> transmission_interface/SimpleTransmission</type>
    <joint name="neck_velodyne">
      <hardwareInterface>hardware_interface/EffortJointInterface</hardwareInterface>
    </joint>
    <actuator name="motor_neck_velodyne"/>
  </transmission>
  <joint name="j_camera_central" type="fixed">
    <origin xyz="0.0559593 5e-12 0.390626" rpy="0.0 0.349065586018 0.0"/>
    <parent link="torso_2"/>
    <child link="camera_central"/>
  </joint>
  <joint name="j_camera_left" type="fixed">
    <origin xyz="0.0191392 0.0525845 0.390626" rpy="0.0 0.349065586018 1.2217302006"/>
    <parent link="torso_2"/>
    <child link="camera_left"/>
  </joint>
  <joint name="j_camera_right" type="fixed">
    <origin xyz="0.0191392 -0.0525845 0.390626" rpy="0.0 0.349065586018 -1.2217302006"/>
    <parent link="torso_2"/>
    <child link="camera_right"/>
  </joint>
  <joint name="j_kinect" type="fixed">
    <origin xyz="0.03 -0.0596 0.045855" rpy="0.0 0.0 0.0"/>
    <parent link="neck_2"/>
    <child link="kinect"/>
  </joint>
  <link name="kinect2_rgb_frame"/>
  <joint name="j_kinect2_rgb_frame" type="fixed">
    <origin xyz="0.05 -0.11 -0.035"/>
    <parent link="kinect"/>
    <child link="kinect2_rgb_frame"/>
  </joint>
  <link name="kinect2_rgb_optical_frame"/>
  <joint name="j_kinect_optical_frame" type="fixed">
    <origin rpy="-1.5707963268 0.0 -1.5707963268"/>
    <parent link="kinect2_rgb_frame"/>
    <child link="kinect2_rgb_optical_frame"/>
  </joint>
  <joint name="j_velodyne" type="fixed">
    <origin xyz="-0.138 0.0 -0.033" rpy="0.0 0.0 -3.14159265359"/>
    <parent link="neck_3"/>
    <child link="velodyne_mount"/>
  </joint>
  <link name="velodyne_calib"/>
  <joint name="velodyne_calib" type="fixed">
    <origin xyz="-0.175768 0.0 -0.034219" rpy="-1.57772 0.0128311 1.57073"/>
    <parent link="neck_3"/>
    <child link="velodyne_calib"/>
  </joint>
  <link name="DWYTorso"/>
  <joint name="torso_renaming" type="fixed">
    <origin xyz="0.0 0.0 -0.0385" rpy="0.0 0.0 0.0"/>
    <parent link="torso_2"/>
    <child link="DWYTorso"/>
  </joint>
  <link name="RShp">
    <inertial>
      <origin xyz="-0.0074457212 -0.03410796 0.00010978102" rpy="0.0 0.0 0.0"/>
      <mass value="1.9628675"/>
      <inertia ixx="0.0053547717" ixy="-0.00036428926" ixz="1.5089568e-05" iyy="0.0033923328" iyz="-5.5692312e-05" izz="0.0068921413"/>
    </inertial>
    <visual>
      <origin xyz="0.0 0.0 0.0" rpy="0.0 0.0 0.0"/>
      <geometry>
        <mesh filename="package://cogimon_urdf/meshes/ShoulderPitch.STL" scale="0.001 0.001 0.001"/>
      </geometry>
      <material name="green"/>
    </visual>
    <collision>
      <origin xyz="0.017831412 -0.05324115 2.3169e-05" rpy="1.69033471763 1.45264918315 1.5721974565"/>
      <geometry>
        <cylinder radius="0.0698859" length="0.0373976849456"/>
      </geometry>
    </collision>
  </link>
  <link name="RShr">
    <inertial>
      <origin xyz="0.058142302 -5.7450803e-05 -0.077477683" rpy="0.0 0.0 0.0"/>
      <mass value="1.8595811"/>
      <inertia ixx="0.013776643" ixy="-3.7788675e-05" ixz="0.0037690171" iyy="0.015677464" iyz="9.4893549e-06" izz="0.0046317657"/>
    </inertial>
    <visual>
      <origin xyz="0.0 0.0 0.0" rpy="0.0 0.0 0.0"/>
      <geometry>
        <mesh filename="package://cogimon_urdf/meshes/ShoulderRoll.STL" scale="0.001 0.001 0.001"/>
      </geometry>
      <material name="dark_grey"/>
    </visual>
    <collision>
      <origin xyz="0.0637382 -4.0386e-07 -0.06435918" rpy="-3.14158140766 0.430137396273 -3.14154117236"/>
      <geometry>
        <cylinder radius="0.0700645" length="0.127992690725"/>
      </geometry>
    </collision>
  </link>
  <link name="RShy">
    <inertial>
      <origin xyz="0.014625194 -0.0008172672 -0.028333545" rpy="0.0 0.0 0.0"/>
      <mass value="1.6678109"/>
      <inertia ixx="0.0064480435" ixy="0.00015639093" ixz="0.0012205359" iyy="0.0073372077" iyz="-8.9941532e-05" izz="0.0036738448"/>
    </inertial>
    <visual>
      <origin xyz="0.0 0.0 0.0" rpy="0.0 0.0 0.0"/>
      <geometry>
        <mesh filename="package://cogimon_urdf/meshes/ShoulderYaw.STL" scale="0.001 0.001 0.001"/>
      </geometry>
      <material name="green"/>
    </visual>
    <collision>
      <origin xyz="0.007307538565 0.004091138465 -0.03662884" rpy="-3.00242380361 0.242909821838 -2.10390753657"/>
      <geometry>
        <cylinder radius="0.0896121" length="0.060822526466"/>
      </geometry>
    </collision>
  </link>
  <link name="RElb">
    <inertial>
      <origin xyz="-0.0076833067 0.040302205 -0.043492779" rpy="0.0 0.0 0.0"/>
      <mass value="1.3157289"/>
      <inertia ixx="0.004330394" ixy="0.00011737391" ixz="-0.00041923199" iyy="0.0038539919" iyz="0.00079573038" izz="0.0017594689"/>
    </inertial>
    <visual>
      <origin xyz="0.0 0.0 0.0" rpy="0.0 0.0 0.0"/>
      <geometry>
        <mesh filename="package://cogimon_urdf/meshes/Elbow.STL" scale="0.001 0.001 0.001"/>
      </geometry>
      <material name="dark_grey"/>
    </visual>
    <collision>
      <origin xyz="-0.00746020465 0.0408499 -0.0404292381" rpy="0.338546052476 0.173378149403 0.0297040701886"/>
      <geometry>
        <cylinder radius="0.0600429" length="0.0871341857294"/>
      </geometry>
    </collision>
  </link>
  <link name="RForearm">
    <inertial>
      <origin xyz="-0.00011079615 -0.011590836 -0.07816026" rpy="0.0 0.0 0.0"/>
      <mass value="1.4908547"/>
      <inertia ixx="0.0085692128" ixy="-1.7856252e-05" ixz="1.9379365e-05" iyy="0.0077454159" iyz="0.00032860094" izz="0.0027441921"/>
    </inertial>
    <visual>
      <origin xyz="0.0 0.0 0.0" rpy="0.0 0.0 0.0"/>
      <geometry>
        <mesh filename="package://cogimon_urdf/meshes/Forearm.STL" scale="0.001 0.001 0.001"/>
      </geometry>
      <material name="green"/>
    </visual>
    <collision>
      <origin xyz="-3.798436e-06 -0.00576208 -0.082271" rpy="0.19504999679 0.000108974174582 1.06615287086e-05"/>
      <geometry>
        <cylinder radius="0.0804108" length="0.0843473974771"/>
      </geometry>
    </collision>
  </link>
  <link name="RWrMot2">
    <inertial>
      <origin xyz="-4.6502396e-06 0.038014094 -0.069926878" rpy="0.0 0.0 0.0"/>
      <mass value="1.1263612"/>
      <inertia ixx="0.0051871784" ixy="-2.724437e-05" ixz="2.2833496e-06" iyy="0.0048037789" iyz="0.00072165653" izz="0.0012771388"/>
    </inertial>
    <visual>
      <origin xyz="0.0 0.0 0.0" rpy="0.0 0.0 0.0"/>
      <geometry>
        <mesh filename="package://cogimon_urdf/meshes/ForearmPitch.STL" scale="0.001 0.001 0.001"/>
      </geometry>
      <material name="dark_grey"/>
    </visual>
    <collision>
      <origin xyz="1.10955e-06 0.04345545 -0.05749733" rpy="0.155924559424 -0.000643096653781 -5.02391105884e-05"/>
      <geometry>
        <cylinder radius="0.0583263" length="0.114251418714"/>
      </geometry>
    </collision>
  </link>
  <link name="RWrMot3">
    <inertial>
      <origin xyz="0.0 0.0 0.03127057" rpy="0.0 0.0 0.0"/>
      <mass value="0.27966428"/>
      <inertia ixx="0.00014415192" ixy="9.8651826e-08" ixz="0.0" iyy="0.0001441701" iyz="0.0" izz="6.0500616e-05"/>
    </inertial>
    <visual>
      <origin xyz="0.0 0.0 0.0" rpy="0.0 0.0 0.0"/>
      <geometry>
        <mesh filename="package://cogimon_urdf/meshes/ForearmYaw.STL" scale="0.001 0.001 0.001"/>
      </geometry>
      <material name="green"/>
    </visual>
    <collision>
      <origin xyz="0.0 0.0 0.0101335" rpy="1.57079632679 -0.262733020835 -0.262733020835"/>
      <geometry>
        <cylinder radius="0.0207073" length="0.00916730749359"/>
      </geometry>
    </collision>
  </link>
  <link name="r_wrist">
    <inertial>
      <origin xyz="8.2161929e-05 -0.0026334189 -0.016465877" rpy="0.0 0.0 0.0"/>
      <mass value="0.37827821"/>
      <inertia ixx="0.00023321716" ixy="-2.3681435e-06" ixz="-1.8039102e-06" iyy="0.00020626291" iyz="-3.158829e-05" izz="0.00027399881"/>
    </inertial>
    <visual>
      <origin xyz="0.0 0.0 0.0" rpy="3.14159265359 0.0 0.0"/>
      <geometry>
        <mesh filename="package://cogimon_urdf/meshes/Wrist.STL" scale="0.001 0.001 0.001"/>
      </geometry>
      <material name="dark_grey"/>
    </visual>
    <collision>
      <origin xyz="-5.947637e-09 -0.013199979631 -0.019569765" rpy="2.70790736799 -1.7440880556e-07 3.84233946897e-08"/>
      <geometry>
        <cylinder radius="0.0468649" length="0.0628232385677"/>
      </geometry>
    </collision>
  </link>
  <joint name="RShSag" type="revolute">
    <origin xyz="0.0457475 -0.169137 0.155126" rpy="-0.174533 0.0 0.5235988"/>
    <axis xyz="0.0 1.0 0.0"/>
    <parent link="DWYTorso"/>
    <child link="RShp"/>
    <limit effort="140.0" lower="-3.359" upper="1.606" velocity="6.283"/>
    <dynamics damping="3.0" friction="0.0"/>
  </joint>
  <joint name="RShLat" type="revolute">
    <origin xyz="-0.09015 -0.062 0.0" rpy="0.1745327 0.0 0.0"/>
    <axis xyz="1.0 0.0 0.0"/>
    <parent link="RShp"/>
    <child link="RShr"/>
    <limit effort="140.0" lower="-3.43" upper="0.0" velocity="6.283"/>
    <dynamics damping="3.0" friction="0.0"/>
  </joint>
  <joint name="RShYaw" type="revolute">
    <origin xyz="0.09015 0.0 -0.21815" rpy="0.0 0.0 0.0"/>
    <axis xyz="0.0 0.0 1.0"/>
    <parent link="RShr"/>
    <child link="RShy"/>
    <limit effort="120.0" lower="-2.55" upper="2.55" velocity="6.283"/>
    <dynamics damping="3.0" friction="0.0"/>
  </joint>
  <joint name="RElbj" type="revolute">
    <origin xyz="0.045 -0.05515 -0.074" rpy="0.0 0.0 0.0"/>
    <axis xyz="0.0 1.0 0.0"/>
    <parent link="RShy"/>
    <child link="RElb"/>
    <limit effort="120.0" lower="-2.488" upper="0.292" velocity="6.283"/>
    <dynamics damping="3.0" friction="0.0"/>
  </joint>
  <joint name="RForearmPlate" type="revolute">
    <origin xyz="-0.015 0.05515 -0.095" rpy="0.0 0.0 0.0"/>
    <axis xyz="0.0 0.0 1.0"/>
    <parent link="RElb"/>
    <child link="RForearm"/>
    <limit effort="35.0" lower="-2.55" upper="2.55" velocity="6.283"/>
    <dynamics damping="0.03" friction="0.0"/>
  </joint>
  <joint name="RWrj1" type="revolute">
    <origin xyz="0.0 -0.049 -0.156" rpy="0.0 0.0 0.0"/>
    <axis xyz="0.0 1.0 0.0"/>
    <parent link="RForearm"/>
    <child link="RWrMot2"/>
    <limit effort="35.0" lower="-1.542" upper="1.508" velocity="6.283"/>
    <dynamics damping="0.03" friction="0.0"/>
  </joint>
  <joint name="RWrj2" type="revolute">
    <origin xyz="0.0 0.049 -0.174" rpy="0.0 0.0 0.0"/>
    <axis xyz="0.0 0.0 1.0"/>
    <parent link="RWrMot2"/>
    <child link="RWrMot3"/>
    <limit effort="20.0" lower="-2.55" upper="2.55" velocity="6.283"/>
    <dynamics damping="0.03" friction="0.0"/>
  </joint>
  <joint name="r_wrist_joint" type="fixed">
    <origin xyz="0.0 0.0 0.0" rpy="0.0 0.0 0.0"/>
    <parent link="RWrMot3"/>
    <child link="r_wrist"/>
  </joint>
  <link name="LShp">
    <inertial>
      <origin xyz="-0.0074457212 0.03410796 0.00010978102" rpy="0.0 0.0 0.0"/>
      <mass value="1.9628675"/>
      <inertia ixx="0.0053547717" ixy="0.00036428926" ixz="1.5089568e-05" iyy="0.0033923328" iyz="5.5692312e-05" izz="0.0068921413"/>
    </inertial>
    <visual>
      <origin xyz="0.0 0.0 0.0" rpy="0.0 0.0 0.0"/>
      <geometry>
        <mesh filename="package://cogimon_urdf/meshes/ShoulderPitch.STL" scale="0.001 -0.001 0.001"/>
      </geometry>
      <material name="green"/>
    </visual>
    <collision>
      <origin xyz="0.017831412 0.05324115 2.3169e-05" rpy="-1.69033471763 1.45264918315 -1.5721974565"/>
      <geometry>
        <cylinder radius="0.0698859" length="0.0373976849456"/>
      </geometry>
    </collision>
  </link>
  <link name="LShr">
    <inertial>
      <origin xyz="0.058142302 5.7450803e-05 -0.077477683" rpy="0.0 0.0 0.0"/>
      <mass value="1.8595811"/>
      <inertia ixx="0.013776643" ixy="3.7788675e-05" ixz="0.0037690171" iyy="0.015677464" iyz="-9.4893549e-06" izz="0.0046317657"/>
    </inertial>
    <visual>
      <origin xyz="0.0 0.0 0.0" rpy="0.0 0.0 0.0"/>
      <geometry>
        <mesh filename="package://cogimon_urdf/meshes/ShoulderRoll.STL" scale="0.001 -0.001 0.001"/>
      </geometry>
      <material name="dark_grey"/>
    </visual>
    <collision>
      <origin xyz="0.0637382 4.0386e-07 -0.06435918" rpy="3.14158140766 0.430137396273 3.14154117236"/>
      <geometry>
        <cylinder radius="0.0700645" length="0.127992690725"/>
      </geometry>
    </collision>
  </link>
  <link name="LShy">
    <inertial>
      <origin xyz="0.014625194 0.0008172672 -0.028333545" rpy="0.0 0.0 0.0"/>
      <mass value="1.6678109"/>
      <inertia ixx="0.0064480435" ixy="-0.00015639093" ixz="0.0012205359" iyy="0.0073372077" iyz="8.9941532e-05" izz="0.0036738448"/>
    </inertial>
    <visual>
      <origin xyz="0.0 0.0 0.0" rpy="0.0 0.0 0.0"/>
      <geometry>
        <mesh filename="package://cogimon_urdf/meshes/ShoulderYaw.STL" scale="0.001 -0.001 0.001"/>
      </geometry>
      <material name="green"/>
    </visual>
    <collision>
      <origin xyz="0.007307538565 -0.004091138465 -0.03662884" rpy="3.00242380361 0.242909821838 2.10390753657"/>
      <geometry>
        <cylinder radius="0.0896121" length="0.060822526466"/>
      </geometry>
    </collision>
  </link>
  <link name="LElb">
    <inertial>
      <origin xyz="-0.0076833067 -0.040302205 -0.043492779" rpy="0.0 0.0 0.0"/>
      <mass value="1.3157289"/>
      <inertia ixx="0.004330394" ixy="-0.00011737391" ixz="-0.00041923199" iyy="0.0038539919" iyz="-0.00079573038" izz="0.0017594689"/>
    </inertial>
    <visual>
      <origin xyz="0.0 0.0 0.0" rpy="0.0 0.0 0.0"/>
      <geometry>
        <mesh filename="package://cogimon_urdf/meshes/Elbow.STL" scale="0.001 -0.001 0.001"/>
      </geometry>
      <material name="dark_grey"/>
    </visual>
    <collision>
      <origin xyz="-0.00746020465 -0.0408499 -0.0404292381" rpy="-0.338546052476 0.173378149403 -0.0297040701886"/>
      <geometry>
        <cylinder radius="0.0600429" length="0.0871341857294"/>
      </geometry>
    </collision>
  </link>
  <link name="LForearm">
    <inertial>
      <origin xyz="-0.00011079615 0.011590836 -0.07816026" rpy="0.0 0.0 0.0"/>
      <mass value="1.4908547"/>
      <inertia ixx="0.0085692128" ixy="1.7856252e-05" ixz="1.9379365e-05" iyy="0.0077454159" iyz="-0.00032860094" izz="0.0027441921"/>
    </inertial>
    <visual>
      <origin xyz="0.0 0.0 0.0" rpy="0.0 0.0 0.0"/>
      <geometry>
        <mesh filename="package://cogimon_urdf/meshes/Forearm.STL" scale="0.001 -0.001 0.001"/>
      </geometry>
      <material name="green"/>
    </visual>
    <collision>
      <origin xyz="-3.798436e-06 0.00576208 -0.082271" rpy="-0.19504999679 0.000108974174582 -1.06615287086e-05"/>
      <geometry>
        <cylinder radius="0.0804108" length="0.0843473974771"/>
      </geometry>
    </collision>
  </link>
  <link name="LWrMot2">
    <inertial>
      <origin xyz="-4.6502396e-06 -0.038014094 -0.069926878" rpy="0.0 0.0 0.0"/>
      <mass value="1.1263612"/>
      <inertia ixx="0.0051871784" ixy="2.724437e-05" ixz="2.2833496e-06" iyy="0.0048037789" iyz="-0.00072165653" izz="0.0012771388"/>
    </inertial>
    <visual>
      <origin xyz="0.0 0.0 0.0" rpy="0.0 0.0 0.0"/>
      <geometry>
        <mesh filename="package://cogimon_urdf/meshes/ForearmPitch.STL" scale="0.001 -0.001 0.001"/>
      </geometry>
      <material name="dark_grey"/>
    </visual>
    <collision>
      <origin xyz="1.10955e-06 -0.04345545 -0.05749733" rpy="-0.155924559424 -0.000643096653781 5.02391105884e-05"/>
      <geometry>
        <cylinder radius="0.0583263" length="0.114251418714"/>
      </geometry>
    </collision>
  </link>
  <link name="LWrMot3">
    <inertial>
      <origin xyz="0.0 0.0 0.03127057" rpy="0.0 0.0 0.0"/>
      <mass value="0.27966428"/>
      <inertia ixx="0.00014415192" ixy="9.8651826e-08" ixz="0.0" iyy="0.0001441701" iyz="0.0" izz="6.0500616e-05"/>
    </inertial>
    <visual>
      <origin xyz="0.0 0.0 0.0" rpy="0.0 0.0 0.0"/>
      <geometry>
        <mesh filename="package://cogimon_urdf/meshes/ForearmYaw.STL" scale="0.001 -0.001 0.001"/>
      </geometry>
      <material name="green"/>
    </visual>
    <collision>
      <origin xyz="0.0 0.0 0.0101335" rpy="-1.57079632679 -0.262733020835 0.262733020835"/>
      <geometry>
        <cylinder radius="0.0207073" length="0.00916730749359"/>
      </geometry>
    </collision>
  </link>
  <link name="l_wrist">
    <inertial>
      <origin xyz="8.2161929e-05 0.0026334189 -0.016465877" rpy="0.0 0.0 0.0"/>
      <mass value="0.37827821"/>
      <inertia ixx="0.00023321716" ixy="2.3681435e-06" ixz="-1.8039102e-06" iyy="0.00020626291" iyz="3.158829e-05" izz="0.00027399881"/>
    </inertial>
    <visual>
      <origin xyz="0.0 0.0 0.0" rpy="3.14159265359 0.0 0.0"/>
      <geometry>
        <mesh filename="package://cogimon_urdf/meshes/Wrist.STL" scale="0.001 -0.001 0.001"/>
      </geometry>
      <material name="dark_grey"/>
    </visual>
    <collision>
      <origin xyz="-5.947637e-09 0.013199979631 -0.019569765" rpy="-2.70790736799 -1.7440880556e-07 -3.84233946898e-08"/>
      <geometry>
        <cylinder radius="0.0468649" length="0.0628232385677"/>
      </geometry>
    </collision>
  </link>
  <joint name="LShSag" type="revolute">
    <origin xyz="0.0457475 0.169137 0.155126" rpy="0.174533 0.0 -0.5235988"/>
    <axis xyz="0.0 1.0 0.0"/>
    <parent link="DWYTorso"/>
    <child link="LShp"/>
    <limit effort="140.0" lower="-3.352" upper="1.603" velocity="6.283"/>
    <dynamics damping="3.0" friction="0.0"/>
  </joint>
  <joint name="LShLat" type="revolute">
    <origin xyz="-0.09015 0.062 0.0" rpy="-0.1745327 0.0 0.0"/>
    <axis xyz="1.0 0.0 0.0"/>
    <parent link="LShp"/>
    <child link="LShr"/>
    <limit effort="140.0" lower="0.0" upper="3.517" velocity="6.283"/>
    <dynamics damping="3.0" friction="0.0"/>
  </joint>
  <joint name="LShYaw" type="revolute">
    <origin xyz="0.09015 0.0 -0.21815" rpy="0.0 0.0 0.0"/>
    <axis xyz="0.0 0.0 1.0"/>
    <parent link="LShr"/>
    <child link="LShy"/>
    <limit effort="120.0" lower="-2.55" upper="2.55" velocity="6.283"/>
    <dynamics damping="3.0" friction="0.0"/>
  </joint>
  <joint name="LElbj" type="revolute">
    <origin xyz="0.045 0.05515 -0.074" rpy="0.0 0.0 0.0"/>
    <axis xyz="0.0 1.0 0.0"/>
    <parent link="LShy"/>
    <child link="LElb"/>
    <limit effort="120.0" lower="-2.492" upper="0.298" velocity="6.283"/>
    <dynamics damping="3.0" friction="0.0"/>
  </joint>
  <joint name="LForearmPlate" type="revolute">
    <origin xyz="-0.015 -0.05515 -0.095" rpy="0.0 0.0 0.0"/>
    <axis xyz="0.0 0.0 1.0"/>
    <parent link="LElb"/>
    <child link="LForearm"/>
    <limit effort="35.0" lower="-2.55" upper="2.55" velocity="6.283"/>
    <dynamics damping="0.03" friction="0.0"/>
  </joint>
  <joint name="LWrj1" type="revolute">
    <origin xyz="0.0 0.049 -0.156" rpy="0.0 0.0 0.0"/>
    <axis xyz="0.0 1.0 0.0"/>
    <parent link="LForearm"/>
    <child link="LWrMot2"/>
    <limit effort="35.0" lower="-1.562" upper="1.478" velocity="6.283"/>
    <dynamics damping="0.03" friction="0.0"/>
  </joint>
  <joint name="LWrj2" type="revolute">
    <origin xyz="0.0 -0.049 -0.174" rpy="0.0 0.0 0.0"/>
    <axis xyz="0.0 0.0 1.0"/>
    <parent link="LWrMot2"/>
    <child link="LWrMot3"/>
    <limit effort="20.0" lower="-2.55" upper="2.55" velocity="6.283"/>
    <dynamics damping="0.03" friction="0.0"/>
  </joint>
  <joint name="l_wrist_joint" type="fixed">
    <origin xyz="0.0 0.0 0.0" rpy="0.0 0.0 0.0"/>
    <parent link="LWrMot3"/>
    <child link="l_wrist"/>
  </joint>
  <link name="arm1_1"/>
  <link name="arm1_2"/>
  <link name="arm1_3"/>
  <link name="arm1_4"/>
  <link name="arm1_5"/>
  <link name="arm1_6"/>
  <link name="arm1_7"/>
  <link name="arm1_8"/>
  <link name="arm2_1"/>
  <link name="arm2_2"/>
  <link name="arm2_3"/>
  <link name="arm2_4"/>
  <link name="arm2_5"/>
  <link name="arm2_6"/>
  <link name="arm2_7"/>
  <link name="arm2_8"/>
  <joint name="jf1" type="fixed">
    <origin xyz="0.0 0.0 0.0" rpy="0.0 0.0 0.0"/>
    <parent link="LShp"/>
    <child link="arm1_1"/>
  </joint>
  <joint name="jf2" type="fixed">
    <origin xyz="0.0 0.0 0.0" rpy="0.0 0.0 0.0"/>
    <parent link="LShr"/>
    <child link="arm1_2"/>
  </joint>
  <joint name="jf3" type="fixed">
    <origin xyz="0.0 0.0 0.0" rpy="0.0 0.0 0.0"/>
    <parent link="LShy"/>
    <child link="arm1_3"/>
  </joint>
  <joint name="jf4" type="fixed">
    <origin xyz="0.0 0.0 0.0" rpy="0.0 0.0 0.0"/>
    <parent link="LElb"/>
    <child link="arm1_4"/>
  </joint>
  <joint name="jf5" type="fixed">
    <origin xyz="0.0 0.0 0.0" rpy="0.0 0.0 0.0"/>
    <parent link="LForearm"/>
    <child link="arm1_5"/>
  </joint>
  <joint name="jf6" type="fixed">
    <origin xyz="0.0 0.0 0.0" rpy="0.0 0.0 0.0"/>
    <parent link="LWrMot2"/>
    <child link="arm1_6"/>
  </joint>
  <joint name="jf7" type="fixed">
    <origin xyz="0.0 0.0 0.0" rpy="0.0 0.0 0.0"/>
    <parent link="LWrMot3"/>
    <child link="arm1_7"/>
  </joint>
  <joint name="jf8" type="fixed">
    <origin xyz="0.0 0.0 0.0" rpy="0.0 0.0 0.0"/>
    <parent link="arm1_7"/>
    <child link="arm1_8"/>
  </joint>
  <joint name="jf9" type="fixed">
    <origin xyz="0.0 0.0 0.0" rpy="0.0 0.0 0.0"/>
    <parent link="RShp"/>
    <child link="arm2_1"/>
  </joint>
  <joint name="jf10" type="fixed">
    <origin xyz="0.0 0.0 0.0" rpy="0.0 0.0 0.0"/>
    <parent link="RShr"/>
    <child link="arm2_2"/>
  </joint>
  <joint name="jf11" type="fixed">
    <origin xyz="0.0 0.0 0.0" rpy="0.0 0.0 0.0"/>
    <parent link="RShy"/>
    <child link="arm2_3"/>
  </joint>
  <joint name="jf12" type="fixed">
    <origin xyz="0.0 0.0 0.0" rpy="0.0 0.0 0.0"/>
    <parent link="RElb"/>
    <child link="arm2_4"/>
  </joint>
  <joint name="jf13" type="fixed">
    <origin xyz="0.0 0.0 0.0" rpy="0.0 0.0 0.0"/>
    <parent link="RForearm"/>
    <child link="arm2_5"/>
  </joint>
  <joint name="jf14" type="fixed">
    <origin xyz="0.0 0.0 0.0" rpy="0.0 0.0 0.0"/>
    <parent link="RWrMot2"/>
    <child link="arm2_6"/>
  </joint>
  <joint name="jf15" type="fixed">
    <origin xyz="0.0 0.0 0.0" rpy="0.0 0.0 0.0"/>
    <parent link="RWrMot3"/>
    <child link="arm2_7"/>
  </joint>
  <joint name="jf16" type="fixed">
    <origin xyz="0.0 0.0 0.0" rpy="0.0 0.0 0.0"/>
    <parent link="arm2_7"/>
    <child link="arm2_8"/>
  </joint>
  <link name="hip1_1">
    <inertial>
      <origin xyz="0.010214199 -0.018348359 0.038090987"/>
      <mass value="1.9194403"/>
      <inertia ixx="0.0047439572" ixy="0.0005747047" ixz="-0.0003784138" iyy="0.0040551878" iyz="0.0007407508" izz="0.0034146219"/>
    </inertial>
    <visual>
      <origin xyz="0.0 0.0 0.0" rpy="0.0 0.0 4.06442490005"/>
      <geometry>
        <mesh filename="package://centauro/centauro_urdf/meshes/simplified/hip-yaw.stl" scale="0.001 0.001 0.001"/>
      </geometry>
      <material name="dark_grey"/>
    </visual>
    <collision>
      <origin xyz="0.00414361009459 -0.00942977366404 0.0445" rpy="-0.688008183058 0.341686596351 -2.34221704554"/>
      <geometry>
        <cylinder radius="0.0653044" length="0.0345165338408"/>
      </geometry>
    </collision>
  </link>
  <link name="hip2_1">
    <inertial>
      <origin xyz="2.57966e-05 0.1810266 0.085669756"/>
      <mass value="2.7264471"/>
      <inertia ixx="0.04851869" ixy="-4.11894e-05" ixz="-1.68778e-05" iyy="0.004242055" iyz="0.0032243188" izz="0.04825583"/>
    </inertial>
    <visual>
      <origin xyz="0.0 0.0 0.0" rpy="0.0 0.0 0.0"/>
      <geometry>
        <mesh filename="package://centauro/centauro_urdf/meshes/simplified/hip-pitch.stl" scale="0.001 0.001 0.001"/>
      </geometry>
    </visual>
    <collision>
      <origin xyz="-7.776715e-05 0.138525195 0.0946021" rpy="-1.58451450634 -0.00059286983141 0.000601059225943"/>
      <geometry>
        <cylinder radius="0.0847444" length="0.292249159884"/>
      </geometry>
    </collision>
  </link>
  <link name="knee_1">
    <inertial>
      <origin xyz="0.10881667 0.0001089081 -0.022638996"/>
      <mass value="1.9356754"/>
      <inertia ixx="0.0030534242" ixy="-4.22079e-05" ixz="0.0013679297" iyy="0.019603321" iyz="6.9941e-06" izz="0.019849817"/>
    </inertial>
    <visual>
      <origin xyz="0.0 0.0 0.0" rpy="0.0 0.0 0.0"/>
      <geometry>
        <mesh filename="package://centauro/centauro_urdf/meshes/simplified/knee.stl" scale="0.001 0.001 0.001"/>
      </geometry>
      <material name="dark_grey"/>
    </visual>
    <collision>
      <origin xyz="0.0960997615 -1.20399085e-07 -0.0143914" rpy="3.18697533622e-05 1.53275172621 3.06797739369e-05"/>
      <geometry>
        <cylinder radius="0.066434" length="0.192525790304"/>
      </geometry>
    </collision>
  </link>
  <link name="ankle1_1">
    <inertial>
      <origin xyz="0.032137318 9.73572e-05 -0.0044222206"/>
      <mass value="1.2380744"/>
      <inertia ixx="0.0015610452" ixy="3.30597e-05" ixz="-0.0001314174" iyy="0.0037423211" iyz="-2.12589e-05" izz="0.0038312442"/>
    </inertial>
    <visual>
      <origin xyz="0.0 0.0 0.0" rpy="0.0 0.0 0.0"/>
      <geometry>
        <mesh filename="package://centauro/centauro_urdf/meshes/simplified/ankle-pitch.stl" scale="0.001 0.001 0.001"/>
      </geometry>
    </visual>
    <collision>
      <origin xyz="0.0211612445 4.557998e-05 -0.0015990485" rpy="0.0221576041577 1.48930565738 0.0204218598272"/>
      <geometry>
        <cylinder radius="0.0763963" length="0.0427933218169"/>
      </geometry>
    </collision>
  </link>
  <link name="ankle2_1">
    <inertial>
      <origin xyz="0.0004435803 0.0004389911 0.19392092"/>
      <mass value="1.1565926"/>
      <inertia ixx="0.0049019475" ixy="4.3032e-06" ixz="3.46491e-05" iyy="0.0038724162" iyz="1.7099e-05" izz="0.0021783198"/>
    </inertial>
    <visual>
      <origin xyz="0.0 0.0 0.0" rpy="0.0 0.0 0.0"/>
      <geometry>
        <mesh filename="package://centauro/centauro_urdf/meshes/simplified/ankle-yaw.stl" scale="0.001 0.001 0.001"/>
      </geometry>
      <material name="dark_grey"/>
    </visual>
    <collision>
      <origin xyz="-2.9005e-07 0.000850055 0.197663" rpy="-1.57079632679 0.00488849418735 -0.00488849418735"/>
      <geometry>
        <cylinder radius="0.101494" length="0.014473082934"/>
      </geometry>
    </collision>
  </link>
  <link name="wheel_1">
    <inertial>
      <origin xyz="0.0 0.0 0.0024271906"/>
      <mass value="1.7289003"/>
      <inertia ixx="0.0046864297" ixy="0.0" ixz="0.0" iyy="0.0046713489" iyz="0.0" izz="0.0053126029"/>
    </inertial>
    <visual>
      <origin xyz="0.0 0.0 0.0" rpy="0.0 0.0 0.0"/>
      <geometry>
        <mesh filename="package://centauro/centauro_urdf/meshes/simplified/wheel.stl" scale="0.001 0.001 0.001"/>
      </geometry>
      <material name="black"/>
    </visual>
    <collision>
      <origin xyz="-4.02799e-06 4.235e-07 2.504545e-06" rpy="1.56769917389 -0.0188362788811 -0.0187780336297"/>
      <geometry>
        <cylinder radius="0.08665" length="0.00108743512283"/>
      </geometry>
    </collision>
  </link>
  <joint name="hip_yaw_1" type="revolute">
    <origin xyz="0.25 0.125 -0.0566" rpy="3.14159265359 0.0 0.461416123228"/>
    <axis xyz="0.0 0.0 1.0"/>
    <parent link="pelvis"/>
    <child link="hip1_1"/>
    <limit effort="304.0" lower="-0.9432" upper="2.5138" velocity="8.8"/>
  </joint>
  <joint name="hip_pitch_1" type="revolute">
    <origin xyz="0.0 0.0 0.0625" rpy="1.57079632679 0.0 0.46141612323"/>
    <axis xyz="0.0 0.0 1.0"/>
    <parent link="hip1_1"/>
    <child link="hip2_1"/>
    <limit effort="304.0" lower="-2.0226" upper="2.02748" velocity="8.8"/>
  </joint>
  <joint name="knee_pitch_1" type="revolute">
    <origin xyz="0.0 0.3 -0.0036" rpy="3.14159265359 0.0 1.57079632679"/>
    <axis xyz="0.0 0.0 1.0"/>
    <parent link="hip2_1"/>
    <child link="knee_1"/>
    <limit effort="304.0" lower="-2.4056" upper="2.3994" velocity="8.8"/>
  </joint>
  <joint name="ankle_pitch_1" type="revolute">
    <origin xyz="0.2 0.0 -0.10015" rpy="3.14159265359 0.0 0.0"/>
    <axis xyz="0.0 0.0 1.0"/>
    <parent link="knee_1"/>
    <child link="ankle1_1"/>
    <limit effort="147.0" lower="-2.4056" upper="2.3184" velocity="8.1"/>
  </joint>
  <joint name="ankle_yaw_1" type="revolute">
    <origin xyz="0.0 0.0 0.0" rpy="1.57079632679 0.0 1.57079632679"/>
    <axis xyz="0.0 0.0 1.0"/>
    <parent link="ankle1_1"/>
    <child link="ankle2_1"/>
    <limit effort="35.0" lower="-2.5626" upper="2.5384" velocity="20.0"/>
  </joint>
  <joint name="j_wheel_1" type="continuous">
    <origin xyz="0.0 0.00085 0.23735" rpy="1.57079632679 0.0 3.14159265359"/>
    <axis xyz="0.0 0.0 1.0"/>
    <parent link="ankle2_1"/>
    <child link="wheel_1"/>
    <limit effort="35.0" velocity="20.0"/>
  </joint>
  <transmission name="t_hip_yaw_1">
    <type> transmission_interface/SimpleTransmission</type>
    <joint name="hip_yaw_1">
      <hardwareInterface>hardware_interface/EffortJointInterface</hardwareInterface>
    </joint>
    <actuator name="motor_hip_yaw_1"/>
  </transmission>
  <transmission name="t_hip_pitch_1">
    <type> transmission_interface/SimpleTransmission</type>
    <joint name="hip_pitch_1">
      <hardwareInterface>hardware_interface/EffortJointInterface</hardwareInterface>
    </joint>
    <actuator name="motor_hip_pitch_1"/>
  </transmission>
  <transmission name="t_knee_pitch_1">
    <type> transmission_interface/SimpleTransmission</type>
    <joint name="knee_pitch_1">
      <hardwareInterface>hardware_interface/EffortJointInterface</hardwareInterface>
    </joint>
    <actuator name="motor_knee_pitch_1"/>
  </transmission>
  <transmission name="t_ankle_pitch_1">
    <type> transmission_interface/SimpleTransmission</type>
    <joint name="ankle_pitch_1">
      <hardwareInterface>hardware_interface/EffortJointInterface</hardwareInterface>
    </joint>
    <actuator name="motor_ankle_pitch_1"/>
  </transmission>
  <transmission name="t_ankle_yaw_1">
    <type> transmission_interface/SimpleTransmission</type>
    <joint name="ankle_yaw_1">
      <hardwareInterface>hardware_interface/EffortJointInterface</hardwareInterface>
    </joint>
    <actuator name="motor_ankle_yaw_1"/>
  </transmission>
  <transmission name="t_j_wheel_1">
    <type> transmission_interface/SimpleTransmission</type>
    <joint name="j_wheel_1">
      <hardwareInterface>hardware_interface/EffortJointInterface</hardwareInterface>
    </joint>
    <actuator name="motor_j_wheel_1"/>
  </transmission>
  <link name="hip1_2">
    <inertial>
      <origin xyz="0.010214199 0.018348359 0.038090987"/>
      <mass value="1.9194403"/>
      <inertia ixx="0.0047439572" ixy="-0.0005747047" ixz="-0.0003784138" iyy="0.0040551878" iyz="-0.0007407508" izz="0.0034146219"/>
    </inertial>
    <visual>
      <origin xyz="0.0 0.0 0.0" rpy="0.0 0.0 0.0"/>
      <geometry>
        <mesh filename="package://centauro/centauro_urdf/meshes/simplified/hip-yaw.stl" scale="0.001 0.001 0.001"/>
      </geometry>
      <material name="dark_grey"/>
    </visual>
    <collision>
      <origin xyz="0.00414361009459 -0.00942977366404 0.0445" rpy="-0.688008183058 0.341686596351 -2.34221704554"/>
      <geometry>
        <cylinder radius="0.0653044" length="0.0345165338408"/>
      </geometry>
    </collision>
  </link>
  <link name="hip2_2">
    <inertial>
      <origin xyz="2.57966e-05 0.1810266 0.085669756"/>
      <mass value="2.7264471"/>
      <inertia ixx="0.04851869" ixy="-4.11894e-05" ixz="-1.68778e-05" iyy="0.004242055" iyz="0.0032243188" izz="0.04825583"/>
    </inertial>
    <visual>
      <origin xyz="0.0 0.0 0.0" rpy="0.0 0.0 0.0"/>
      <geometry>
        <mesh filename="package://centauro/centauro_urdf/meshes/simplified/hip-pitch.stl" scale="0.001 0.001 0.001"/>
      </geometry>
    </visual>
    <collision>
      <origin xyz="-7.776715e-05 0.138525195 0.0946021" rpy="-1.58451450634 -0.00059286983141 0.000601059225943"/>
      <geometry>
        <cylinder radius="0.0847444" length="0.292249159884"/>
      </geometry>
    </collision>
  </link>
  <link name="knee_2">
    <inertial>
      <origin xyz="0.10881667 0.0001089081 -0.022638996"/>
      <mass value="1.9356754"/>
      <inertia ixx="0.0030534242" ixy="-4.22079e-05" ixz="0.0013679297" iyy="0.019603321" iyz="6.9941e-06" izz="0.019849817"/>
    </inertial>
    <visual>
      <origin xyz="0.0 0.0 0.0" rpy="0.0 0.0 0.0"/>
      <geometry>
        <mesh filename="package://centauro/centauro_urdf/meshes/simplified/knee.stl" scale="0.001 0.001 0.001"/>
      </geometry>
      <material name="dark_grey"/>
    </visual>
    <collision>
      <origin xyz="0.0960997615 -1.20399085e-07 -0.0143914" rpy="3.18697533622e-05 1.53275172621 3.06797739369e-05"/>
      <geometry>
        <cylinder radius="0.066434" length="0.192525790304"/>
      </geometry>
    </collision>
  </link>
  <link name="ankle1_2">
    <inertial>
      <origin xyz="0.032137318 9.73572e-05 -0.0044222206"/>
      <mass value="1.2380744"/>
      <inertia ixx="0.0015610452" ixy="3.30597e-05" ixz="-0.0001314174" iyy="0.0037423211" iyz="-2.12589e-05" izz="0.0038312442"/>
    </inertial>
    <visual>
      <origin xyz="0.0 0.0 0.0" rpy="0.0 0.0 0.0"/>
      <geometry>
        <mesh filename="package://centauro/centauro_urdf/meshes/simplified/ankle-pitch.stl" scale="0.001 0.001 0.001"/>
      </geometry>
    </visual>
    <collision>
      <origin xyz="0.0211612445 4.557998e-05 -0.0015990485" rpy="0.0221576041577 1.48930565738 0.0204218598272"/>
      <geometry>
        <cylinder radius="0.0763963" length="0.0427933218169"/>
      </geometry>
    </collision>
  </link>
  <link name="ankle2_2">
    <inertial>
      <origin xyz="0.0004435803 0.0004389911 0.19392092"/>
      <mass value="1.1565926"/>
      <inertia ixx="0.0049019475" ixy="4.3032e-06" ixz="3.46491e-05" iyy="0.0038724162" iyz="1.7099e-05" izz="0.0021783198"/>
    </inertial>
    <visual>
      <origin xyz="0.0 0.0 0.0" rpy="0.0 0.0 0.0"/>
      <geometry>
        <mesh filename="package://centauro/centauro_urdf/meshes/simplified/ankle-yaw.stl" scale="0.001 0.001 0.001"/>
      </geometry>
      <material name="dark_grey"/>
    </visual>
    <collision>
      <origin xyz="-2.9005e-07 0.000850055 0.197663" rpy="-1.57079632679 0.00488849418735 -0.00488849418735"/>
      <geometry>
        <cylinder radius="0.101494" length="0.014473082934"/>
      </geometry>
    </collision>
  </link>
  <link name="wheel_2">
    <inertial>
      <origin xyz="0.0 0.0 0.0024271906"/>
      <mass value="1.7289003"/>
      <inertia ixx="0.0046864297" ixy="0.0" ixz="0.0" iyy="0.0046713489" iyz="0.0" izz="0.0053126029"/>
    </inertial>
    <visual>
      <origin xyz="0.0 0.0 0.0" rpy="0.0 0.0 0.0"/>
      <geometry>
        <mesh filename="package://centauro/centauro_urdf/meshes/simplified/wheel.stl" scale="0.001 0.001 0.001"/>
      </geometry>
      <material name="black"/>
    </visual>
    <collision>
      <origin xyz="-4.02799e-06 4.235e-07 2.504545e-06" rpy="1.56769917389 -0.0188362788811 -0.0187780336297"/>
      <geometry>
        <cylinder radius="0.08665" length="0.00108743512283"/>
      </geometry>
    </collision>
  </link>
  <joint name="hip_yaw_2" type="revolute">
    <origin xyz="0.25 -0.125 -0.0566" rpy="3.14159265359 0.0 -0.461416123228"/>
    <axis xyz="0.0 0.0 1.0"/>
    <parent link="pelvis"/>
    <child link="hip1_2"/>
    <limit effort="304.0" lower="-2.511" upper="0.943" velocity="8.8"/>
  </joint>
  <joint name="hip_pitch_2" type="revolute">
    <origin xyz="0.0 0.0 0.0625" rpy="1.57079632679 0.0 2.68017653036"/>
    <axis xyz="0.0 0.0 1.0"/>
    <parent link="hip1_2"/>
    <child link="hip2_2"/>
    <limit effort="304.0" lower="-2.0156" upper="2.0354" velocity="8.8"/>
  </joint>
  <joint name="knee_pitch_2" type="revolute">
    <origin xyz="0.0 0.3 -0.0036" rpy="3.14159265359 0.0 1.57079632679"/>
    <axis xyz="0.0 0.0 1.0"/>
    <parent link="hip2_2"/>
    <child link="knee_2"/>
    <limit effort="304.0" lower="-2.4006" upper="2.4034" velocity="8.8"/>
  </joint>
  <joint name="ankle_pitch_2" type="revolute">
    <origin xyz="0.2 0.0 -0.10015" rpy="3.14159265359 0.0 0.0"/>
    <axis xyz="0.0 0.0 1.0"/>
    <parent link="knee_2"/>
    <child link="ankle1_2"/>
    <limit effort="147.0" lower="-2.3266" upper="2.3914" velocity="8.1"/>
  </joint>
  <joint name="ankle_yaw_2" type="revolute">
    <origin xyz="0.0 0.0 0.0" rpy="1.57079632679 0.0 1.57079632679"/>
    <axis xyz="0.0 0.0 1.0"/>
    <parent link="ankle1_2"/>
    <child link="ankle2_2"/>
    <limit effort="35.0" lower="-2.5546" upper="2.5484" velocity="20.0"/>
  </joint>
  <joint name="j_wheel_2" type="continuous">
    <origin xyz="0.0 0.00085 0.23735" rpy="1.57079632679 0.0 3.14159265359"/>
    <axis xyz="0.0 0.0 1.0"/>
    <parent link="ankle2_2"/>
    <child link="wheel_2"/>
    <limit effort="35.0" velocity="20.0"/>
  </joint>
  <transmission name="t_hip_yaw_2">
    <type> transmission_interface/SimpleTransmission</type>
    <joint name="hip_yaw_2">
      <hardwareInterface>hardware_interface/EffortJointInterface</hardwareInterface>
    </joint>
    <actuator name="motor_hip_yaw_2"/>
  </transmission>
  <transmission name="t_hip_pitch_2">
    <type> transmission_interface/SimpleTransmission</type>
    <joint name="hip_pitch_2">
      <hardwareInterface>hardware_interface/EffortJointInterface</hardwareInterface>
    </joint>
    <actuator name="motor_hip_pitch_2"/>
  </transmission>
  <transmission name="t_knee_pitch_2">
    <type> transmission_interface/SimpleTransmission</type>
    <joint name="knee_pitch_2">
      <hardwareInterface>hardware_interface/EffortJointInterface</hardwareInterface>
    </joint>
    <actuator name="motor_knee_pitch_2"/>
  </transmission>
  <transmission name="t_ankle_pitch_2">
    <type> transmission_interface/SimpleTransmission</type>
    <joint name="ankle_pitch_2">
      <hardwareInterface>hardware_interface/EffortJointInterface</hardwareInterface>
    </joint>
    <actuator name="motor_ankle_pitch_2"/>
  </transmission>
  <transmission name="t_ankle_yaw_2">
    <type> transmission_interface/SimpleTransmission</type>
    <joint name="ankle_yaw_2">
      <hardwareInterface>hardware_interface/EffortJointInterface</hardwareInterface>
    </joint>
    <actuator name="motor_ankle_yaw_2"/>
  </transmission>
  <transmission name="t_j_wheel_2">
    <type> transmission_interface/SimpleTransmission</type>
    <joint name="j_wheel_2">
      <hardwareInterface>hardware_interface/EffortJointInterface</hardwareInterface>
    </joint>
    <actuator name="motor_j_wheel_2"/>
  </transmission>
  <link name="hip1_3">
    <inertial>
      <origin xyz="0.010214199 0.018348359 0.038090987"/>
      <mass value="1.9194403"/>
      <inertia ixx="0.0047439572" ixy="-0.0005747047" ixz="-0.0003784138" iyy="0.0040551878" iyz="-0.0007407508" izz="0.0034146219"/>
    </inertial>
    <visual>
      <origin xyz="0.0 0.0 0.0" rpy="0.0 0.0 0.0"/>
      <geometry>
        <mesh filename="package://centauro/centauro_urdf/meshes/simplified/hip-yaw.stl" scale="0.001 0.001 0.001"/>
      </geometry>
      <material name="dark_grey"/>
    </visual>
    <collision>
      <origin xyz="0.00414361009459 -0.00942977366404 0.0445" rpy="-0.688008183058 0.341686596351 -2.34221704554"/>
      <geometry>
        <cylinder radius="0.0653044" length="0.0345165338408"/>
      </geometry>
    </collision>
  </link>
  <link name="hip2_3">
    <inertial>
      <origin xyz="2.57966e-05 0.1810266 0.085669756"/>
      <mass value="2.7264471"/>
      <inertia ixx="0.04851869" ixy="-4.11894e-05" ixz="-1.68778e-05" iyy="0.004242055" iyz="0.0032243188" izz="0.04825583"/>
    </inertial>
    <visual>
      <origin xyz="0.0 0.0 0.0" rpy="0.0 0.0 0.0"/>
      <geometry>
        <mesh filename="package://centauro/centauro_urdf/meshes/simplified/hip-pitch.stl" scale="0.001 0.001 0.001"/>
      </geometry>
    </visual>
    <collision>
      <origin xyz="-7.776715e-05 0.138525195 0.0946021" rpy="-1.58451450634 -0.00059286983141 0.000601059225943"/>
      <geometry>
        <cylinder radius="0.0847444" length="0.292249159884"/>
      </geometry>
    </collision>
  </link>
  <link name="knee_3">
    <inertial>
      <origin xyz="0.10881667 0.0001089081 -0.022638996"/>
      <mass value="1.9356754"/>
      <inertia ixx="0.0030534242" ixy="-4.22079e-05" ixz="0.0013679297" iyy="0.019603321" iyz="6.9941e-06" izz="0.019849817"/>
    </inertial>
    <visual>
      <origin xyz="0.0 0.0 0.0" rpy="0.0 0.0 0.0"/>
      <geometry>
        <mesh filename="package://centauro/centauro_urdf/meshes/simplified/knee.stl" scale="0.001 0.001 0.001"/>
      </geometry>
      <material name="dark_grey"/>
    </visual>
    <collision>
      <origin xyz="0.0960997615 -1.20399085e-07 -0.0143914" rpy="3.18697533622e-05 1.53275172621 3.06797739369e-05"/>
      <geometry>
        <cylinder radius="0.066434" length="0.192525790304"/>
      </geometry>
    </collision>
  </link>
  <link name="ankle1_3">
    <inertial>
      <origin xyz="0.032137318 9.73572e-05 -0.0044222206"/>
      <mass value="1.2380744"/>
      <inertia ixx="0.0015610452" ixy="3.30597e-05" ixz="-0.0001314174" iyy="0.0037423211" iyz="-2.12589e-05" izz="0.0038312442"/>
    </inertial>
    <visual>
      <origin xyz="0.0 0.0 0.0" rpy="0.0 0.0 0.0"/>
      <geometry>
        <mesh filename="package://centauro/centauro_urdf/meshes/simplified/ankle-pitch.stl" scale="0.001 0.001 0.001"/>
      </geometry>
    </visual>
    <collision>
      <origin xyz="0.0211612445 4.557998e-05 -0.0015990485" rpy="0.0221576041577 1.48930565738 0.0204218598272"/>
      <geometry>
        <cylinder radius="0.0763963" length="0.0427933218169"/>
      </geometry>
    </collision>
  </link>
  <link name="ankle2_3">
    <inertial>
      <origin xyz="0.0004435803 0.0004389911 0.19392092"/>
      <mass value="1.1565926"/>
      <inertia ixx="0.0049019475" ixy="4.3032e-06" ixz="3.46491e-05" iyy="0.0038724162" iyz="1.7099e-05" izz="0.0021783198"/>
    </inertial>
    <visual>
      <origin xyz="0.0 0.0 0.0" rpy="0.0 0.0 0.0"/>
      <geometry>
        <mesh filename="package://centauro/centauro_urdf/meshes/simplified/ankle-yaw.stl" scale="0.001 0.001 0.001"/>
      </geometry>
      <material name="dark_grey"/>
    </visual>
    <collision>
      <origin xyz="-2.9005e-07 0.000850055 0.197663" rpy="-1.57079632679 0.00488849418735 -0.00488849418735"/>
      <geometry>
        <cylinder radius="0.101494" length="0.014473082934"/>
      </geometry>
    </collision>
  </link>
  <link name="wheel_3">
    <inertial>
      <origin xyz="0.0 0.0 0.0024271906"/>
      <mass value="1.7289003"/>
      <inertia ixx="0.0046864297" ixy="0.0" ixz="0.0" iyy="0.0046713489" iyz="0.0" izz="0.0053126029"/>
    </inertial>
    <visual>
      <origin xyz="0.0 0.0 0.0" rpy="0.0 0.0 0.0"/>
      <geometry>
        <mesh filename="package://centauro/centauro_urdf/meshes/simplified/wheel.stl" scale="0.001 0.001 0.001"/>
      </geometry>
      <material name="black"/>
    </visual>
    <collision>
      <origin xyz="-4.02799e-06 4.235e-07 2.504545e-06" rpy="1.56769917389 -0.0188362788811 -0.0187780336297"/>
      <geometry>
        <cylinder radius="0.08665" length="0.00108743512283"/>
      </geometry>
    </collision>
  </link>
  <joint name="hip_yaw_3" type="revolute">
    <origin xyz="-0.25 0.125 -0.0566" rpy="3.14159265359 0.0 2.68017653036"/>
    <axis xyz="0.0 0.0 1.0"/>
    <parent link="pelvis"/>
    <child link="hip1_3"/>
    <limit effort="304.0" lower="-2.51" upper="0.943" velocity="8.8"/>
  </joint>
  <joint name="hip_pitch_3" type="revolute">
    <origin xyz="0.0 0.0 0.0625" rpy="1.57079632679 0.0 2.68017653036"/>
    <axis xyz="0.0 0.0 1.0"/>
    <parent link="hip1_3"/>
    <child link="hip2_3"/>
    <limit effort="304.0" lower="-2.0126" upper="2.0384" velocity="8.8"/>
  </joint>
  <joint name="knee_pitch_3" type="revolute">
    <origin xyz="0.0 0.3 -0.0036" rpy="3.14159265359 0.0 1.57079632679"/>
    <axis xyz="0.0 0.0 1.0"/>
    <parent link="hip2_3"/>
    <child link="knee_3"/>
    <limit effort="304.0" lower="-2.4056" upper="2.4064" velocity="8.8"/>
  </joint>
  <joint name="ankle_pitch_3" type="revolute">
    <origin xyz="0.2 0.0 -0.10015" rpy="3.14159265359 0.0 0.0"/>
    <axis xyz="0.0 0.0 1.0"/>
    <parent link="knee_3"/>
    <child link="ankle1_3"/>
    <limit effort="147.0" lower="-2.4696" upper="2.4464" velocity="8.1"/>
  </joint>
  <joint name="ankle_yaw_3" type="revolute">
    <origin xyz="0.0 0.0 0.0" rpy="1.57079632679 0.0 1.57079632679"/>
    <axis xyz="0.0 0.0 1.0"/>
    <parent link="ankle1_3"/>
    <child link="ankle2_3"/>
    <limit effort="35.0" lower="-2.5606" upper="2.5454" velocity="20.0"/>
  </joint>
  <joint name="j_wheel_3" type="continuous">
    <origin xyz="0.0 0.00085 0.23735" rpy="1.57079632679 0.0 3.14159265359"/>
    <axis xyz="0.0 0.0 1.0"/>
    <parent link="ankle2_3"/>
    <child link="wheel_3"/>
    <limit effort="35.0" velocity="20.0"/>
  </joint>
  <transmission name="t_hip_yaw_3">
    <type> transmission_interface/SimpleTransmission</type>
    <joint name="hip_yaw_3">
      <hardwareInterface>hardware_interface/EffortJointInterface</hardwareInterface>
    </joint>
    <actuator name="motor_hip_yaw_3"/>
  </transmission>
  <transmission name="t_hip_pitch_3">
    <type> transmission_interface/SimpleTransmission</type>
    <joint name="hip_pitch_3">
      <hardwareInterface>hardware_interface/EffortJointInterface</hardwareInterface>
    </joint>
    <actuator name="motor_hip_pitch_3"/>
  </transmission>
  <transmission name="t_knee_pitch_3">
    <type> transmission_interface/SimpleTransmission</type>
    <joint name="knee_pitch_3">
      <hardwareInterface>hardware_interface/EffortJointInterface</hardwareInterface>
    </joint>
    <actuator name="motor_knee_pitch_3"/>
  </transmission>
  <transmission name="t_ankle_pitch_3">
    <type> transmission_interface/SimpleTransmission</type>
    <joint name="ankle_pitch_3">
      <hardwareInterface>hardware_interface/EffortJointInterface</hardwareInterface>
    </joint>
    <actuator name="motor_ankle_pitch_3"/>
  </transmission>
  <transmission name="t_ankle_yaw_3">
    <type> transmission_interface/SimpleTransmission</type>
    <joint name="ankle_yaw_3">
      <hardwareInterface>hardware_interface/EffortJointInterface</hardwareInterface>
    </joint>
    <actuator name="motor_ankle_yaw_3"/>
  </transmission>
  <transmission name="t_j_wheel_3">
    <type> transmission_interface/SimpleTransmission</type>
    <joint name="j_wheel_3">
      <hardwareInterface>hardware_interface/EffortJointInterface</hardwareInterface>
    </joint>
    <actuator name="motor_j_wheel_3"/>
  </transmission>
  <link name="hip1_4">
    <inertial>
      <origin xyz="0.010214199 -0.018348359 0.038090987"/>
      <mass value="1.9194403"/>
      <inertia ixx="0.0047439572" ixy="0.0005747047" ixz="-0.0003784138" iyy="0.0040551878" iyz="0.0007407508" izz="0.0034146219"/>
    </inertial>
    <visual>
      <origin xyz="0.0 0.0 0.0" rpy="0.0 0.0 4.06442490005"/>
      <geometry>
        <mesh filename="package://centauro/centauro_urdf/meshes/simplified/hip-yaw.stl" scale="0.001 0.001 0.001"/>
      </geometry>
      <material name="dark_grey"/>
    </visual>
    <collision>
      <origin xyz="0.00414361009459 -0.00942977366404 0.0445" rpy="-0.688008183058 0.341686596351 -2.34221704554"/>
      <geometry>
        <cylinder radius="0.0653044" length="0.0345165338408"/>
      </geometry>
    </collision>
  </link>
  <link name="hip2_4">
    <inertial>
      <origin xyz="2.57966e-05 0.1810266 0.085669756"/>
      <mass value="2.7264471"/>
      <inertia ixx="0.04851869" ixy="-4.11894e-05" ixz="-1.68778e-05" iyy="0.004242055" iyz="0.0032243188" izz="0.04825583"/>
    </inertial>
    <visual>
      <origin xyz="0.0 0.0 0.0" rpy="0.0 0.0 0.0"/>
      <geometry>
        <mesh filename="package://centauro/centauro_urdf/meshes/simplified/hip-pitch.stl" scale="0.001 0.001 0.001"/>
      </geometry>
    </visual>
    <collision>
      <origin xyz="-7.776715e-05 0.138525195 0.0946021" rpy="-1.58451450634 -0.00059286983141 0.000601059225943"/>
      <geometry>
        <cylinder radius="0.0847444" length="0.292249159884"/>
      </geometry>
    </collision>
  </link>
  <link name="knee_4">
    <inertial>
      <origin xyz="0.10881667 0.0001089081 -0.022638996"/>
      <mass value="1.9356754"/>
      <inertia ixx="0.0030534242" ixy="-4.22079e-05" ixz="0.0013679297" iyy="0.019603321" iyz="6.9941e-06" izz="0.019849817"/>
    </inertial>
    <visual>
      <origin xyz="0.0 0.0 0.0" rpy="0.0 0.0 0.0"/>
      <geometry>
        <mesh filename="package://centauro/centauro_urdf/meshes/simplified/knee.stl" scale="0.001 0.001 0.001"/>
      </geometry>
      <material name="dark_grey"/>
    </visual>
    <collision>
      <origin xyz="0.0960997615 -1.20399085e-07 -0.0143914" rpy="3.18697533622e-05 1.53275172621 3.06797739369e-05"/>
      <geometry>
        <cylinder radius="0.066434" length="0.192525790304"/>
      </geometry>
    </collision>
  </link>
  <link name="ankle1_4">
    <inertial>
      <origin xyz="0.032137318 9.73572e-05 -0.0044222206"/>
      <mass value="1.2380744"/>
      <inertia ixx="0.0015610452" ixy="3.30597e-05" ixz="-0.0001314174" iyy="0.0037423211" iyz="-2.12589e-05" izz="0.0038312442"/>
    </inertial>
    <visual>
      <origin xyz="0.0 0.0 0.0" rpy="0.0 0.0 0.0"/>
      <geometry>
        <mesh filename="package://centauro/centauro_urdf/meshes/simplified/ankle-pitch.stl" scale="0.001 0.001 0.001"/>
      </geometry>
    </visual>
    <collision>
      <origin xyz="0.0211612445 4.557998e-05 -0.0015990485" rpy="0.0221576041577 1.48930565738 0.0204218598272"/>
      <geometry>
        <cylinder radius="0.0763963" length="0.0427933218169"/>
      </geometry>
    </collision>
  </link>
  <link name="ankle2_4">
    <inertial>
      <origin xyz="0.0004435803 0.0004389911 0.19392092"/>
      <mass value="1.1565926"/>
      <inertia ixx="0.0049019475" ixy="4.3032e-06" ixz="3.46491e-05" iyy="0.0038724162" iyz="1.7099e-05" izz="0.0021783198"/>
    </inertial>
    <visual>
      <origin xyz="0.0 0.0 0.0" rpy="0.0 0.0 0.0"/>
      <geometry>
        <mesh filename="package://centauro/centauro_urdf/meshes/simplified/ankle-yaw.stl" scale="0.001 0.001 0.001"/>
      </geometry>
      <material name="dark_grey"/>
    </visual>
    <collision>
      <origin xyz="-2.9005e-07 0.000850055 0.197663" rpy="-1.57079632679 0.00488849418735 -0.00488849418735"/>
      <geometry>
        <cylinder radius="0.101494" length="0.014473082934"/>
      </geometry>
    </collision>
  </link>
  <link name="wheel_4">
    <inertial>
      <origin xyz="0.0 0.0 0.0024271906"/>
      <mass value="1.7289003"/>
      <inertia ixx="0.0046864297" ixy="0.0" ixz="0.0" iyy="0.0046713489" iyz="0.0" izz="0.0053126029"/>
    </inertial>
    <visual>
      <origin xyz="0.0 0.0 0.0" rpy="0.0 0.0 0.0"/>
      <geometry>
        <mesh filename="package://centauro/centauro_urdf/meshes/simplified/wheel.stl" scale="0.001 0.001 0.001"/>
      </geometry>
      <material name="black"/>
    </visual>
    <collision>
      <origin xyz="-4.02799e-06 4.235e-07 2.504545e-06" rpy="1.56769917389 -0.0188362788811 -0.0187780336297"/>
      <geometry>
        <cylinder radius="0.08665" length="0.00108743512283"/>
      </geometry>
    </collision>
  </link>
  <joint name="hip_yaw_4" type="revolute">
    <origin xyz="-0.25 -0.125 -0.0566" rpy="3.14159265359 0.0 3.60300877682"/>
    <axis xyz="0.0 0.0 1.0"/>
    <parent link="pelvis"/>
    <child link="hip1_4"/>
    <limit effort="304.0" lower="-0.9412" upper="2.5138" velocity="8.8"/>
  </joint>
  <joint name="hip_pitch_4" type="revolute">
    <origin xyz="0.0 0.0 0.0625" rpy="1.57079632679 0.0 0.46141612323"/>
    <axis xyz="0.0 0.0 1.0"/>
    <parent link="hip1_4"/>
    <child link="hip2_4"/>
    <limit effort="304.0" lower="-2.0326" upper="2.0524" velocity="8.8"/>
  </joint>
  <joint name="knee_pitch_4" type="revolute">
    <origin xyz="0.0 0.3 -0.0036" rpy="3.14159265359 0.0 1.57079632679"/>
    <axis xyz="0.0 0.0 1.0"/>
    <parent link="hip2_4"/>
    <child link="knee_4"/>
    <limit effort="304.0" lower="-2.4176" upper="2.3884" velocity="8.8"/>
  </joint>
  <joint name="ankle_pitch_4" type="revolute">
    <origin xyz="0.2 0.0 -0.10015" rpy="3.14159265359 0.0 0.0"/>
    <axis xyz="0.0 0.0 1.0"/>
    <parent link="knee_4"/>
    <child link="ankle1_4"/>
    <limit effort="147.0" lower="-2.3426" upper="2.3934" velocity="8.1"/>
  </joint>
  <joint name="ankle_yaw_4" type="revolute">
    <origin xyz="0.0 0.0 0.0" rpy="1.57079632679 0.0 1.57079632679"/>
    <axis xyz="0.0 0.0 1.0"/>
    <parent link="ankle1_4"/>
    <child link="ankle2_4"/>
    <limit effort="35.0" lower="-2.6046" upper="2.5514" velocity="20.0"/>
  </joint>
  <joint name="j_wheel_4" type="continuous">
    <origin xyz="0.0 0.00085 0.23735" rpy="1.57079632679 0.0 3.14159265359"/>
    <axis xyz="0.0 0.0 1.0"/>
    <parent link="ankle2_4"/>
    <child link="wheel_4"/>
    <limit effort="35.0" velocity="20.0"/>
  </joint>
  <transmission name="t_hip_yaw_4">
    <type> transmission_interface/SimpleTransmission</type>
    <joint name="hip_yaw_4">
      <hardwareInterface>hardware_interface/EffortJointInterface</hardwareInterface>
    </joint>
    <actuator name="motor_hip_yaw_4"/>
  </transmission>
  <transmission name="t_hip_pitch_4">
    <type> transmission_interface/SimpleTransmission</type>
    <joint name="hip_pitch_4">
      <hardwareInterface>hardware_interface/EffortJointInterface</hardwareInterface>
    </joint>
    <actuator name="motor_hip_pitch_4"/>
  </transmission>
  <transmission name="t_knee_pitch_4">
    <type> transmission_interface/SimpleTransmission</type>
    <joint name="knee_pitch_4">
      <hardwareInterface>hardware_interface/EffortJointInterface</hardwareInterface>
    </joint>
    <actuator name="motor_knee_pitch_4"/>
  </transmission>
  <transmission name="t_ankle_pitch_4">
    <type> transmission_interface/SimpleTransmission</type>
    <joint name="ankle_pitch_4">
      <hardwareInterface>hardware_interface/EffortJointInterface</hardwareInterface>
    </joint>
    <actuator name="motor_ankle_pitch_4"/>
  </transmission>
  <transmission name="t_ankle_yaw_4">
    <type> transmission_interface/SimpleTransmission</type>
    <joint name="ankle_yaw_4">
      <hardwareInterface>hardware_interface/EffortJointInterface</hardwareInterface>
    </joint>
    <actuator name="motor_ankle_yaw_4"/>
  </transmission>
  <transmission name="t_j_wheel_4">
    <type> transmission_interface/SimpleTransmission</type>
    <joint name="j_wheel_4">
      <hardwareInterface>hardware_interface/EffortJointInterface</hardwareInterface>
    </joint>
    <actuator name="motor_j_wheel_4"/>
  </transmission>
</robot>
