<?xml version="1.0"?>
<robot xmlns:xacro="http://www.ros.org/wiki/xacro">

<!--<xacro:include filename="$(find centauro)/centauro_urdf/urdf/sensors/kinect2.urdf.xacro"/> -->
<!-- head links -->

<link name="neck_1">
	<inertial>
		<origin xyz="${Neck_1_x} ${Neck_1_y} ${Neck_1_z}"/>
		<mass value="${Neck_1_mass}"/>
                <inertia ixx="${Neck_1_xx}" ixy="${Neck_1_xy}" ixz="${Neck_1_xz}" iyy="${Neck_1_yy}" iyz="${Neck_1_yz}" izz="${Neck_1_zz}"/>
        </inertial>

	<visual>
                <xacro:visual_model.neck_yaw />
	</visual>

	<collision>
                <xacro:collision_model.neck_yaw />
	</collision>
</link>

<link name="neck_2">
	<inertial>
		<origin xyz="${Neck_2_x} ${Neck_2_y} ${Neck_2_z}"/>
		<mass value="${Neck_2_mass}"/>
                <inertia ixx="${Neck_2_xx}" ixy="${Neck_2_xy}" ixz="${Neck_2_xz}" iyy="${Neck_2_yy}" iyz="${Neck_2_yz}" izz="${Neck_2_zz}"/>
        </inertial>

	<visual>
                <xacro:visual_model.neck_pitch />
	</visual>

	<collision>
                <xacro:collision_model.neck_pitch />
	</collision>
</link>

<link name="neck_3">
	<inertial>
		<origin xyz="${Neck_3_x} ${Neck_3_y} ${Neck_3_z}"/>
		<mass value="${Neck_3_mass}"/>
                <inertia ixx="${Neck_3_xx}" ixy="${Neck_3_xy}" ixz="${Neck_3_xz}" iyy="${Neck_3_yy}" iyz="${Neck_3_yz}" izz="${Neck_3_zz}"/>
        </inertial>

	<visual>
                <xacro:visual_model.velodyne />
	</visual>

	<collision>
                <xacro:collision_model.velodyne />
	</collision>
</link>
<!-- /head links -->
<!-- sensors links -->
<link name="camera_central">
	<inertial>
		<origin xyz="${Dummy_x} ${Dummy_y} ${Dummy_z}"/>
		<mass value="${Dummy_mass}"/>
                <inertia ixx="${Dummy_xx}" ixy="${Dummy_xy}" ixz="${Dummy_xz}" iyy="${Dummy_yy}" iyz="${Dummy_yz}" izz="${Dummy_zz}"/>
        </inertial>
</link>
<link name="camera_left">
	<inertial>
		<origin xyz="${Dummy_x} ${Dummy_y} ${Dummy_z}"/>
		<mass value="${Dummy_mass}"/>
                <inertia ixx="${Dummy_xx}" ixy="${Dummy_xy}" ixz="${Dummy_xz}" iyy="${Dummy_yy}" iyz="${Dummy_yz}" izz="${Dummy_zz}"/>
        </inertial>
</link>
<link name="camera_right">
	<inertial>
		<origin xyz="${Dummy_x} ${Dummy_y} ${Dummy_z}"/>
		<mass value="${Dummy_mass}"/>
                <inertia ixx="${Dummy_xx}" ixy="${Dummy_xy}" ixz="${Dummy_xz}" iyy="${Dummy_yy}" iyz="${Dummy_yz}" izz="${Dummy_zz}"/>
        </inertial>
</link>
<link name="kinect">
	<inertial>
		<origin xyz="${Dummy_x} ${Dummy_y} ${Dummy_z}"/>
		<mass value="${Dummy_mass}"/>
                <inertia ixx="${Dummy_xx}" ixy="${Dummy_xy}" ixz="${Dummy_xz}" iyy="${Dummy_yy}" iyz="${Dummy_yz}" izz="${Dummy_zz}"/>
        </inertial>
</link>
<link name="velodyne_mount">
	<inertial>
		<origin xyz="${Dummy_x} ${Dummy_y} ${Dummy_z}"/>
		<mass value="${Dummy_mass}"/>
                <inertia ixx="${Dummy_xx}" ixy="${Dummy_xy}" ixz="${Dummy_xz}" iyy="${Dummy_yy}" iyz="${Dummy_yz}" izz="${Dummy_zz}"/>
        </inertial>
</link>

<!-- /sensors links -->

<!-- head joints -->
<joint name="neck_yaw" type="revolute">
   <parent link="torso_2"/>
   <origin xyz="${Neck_1_Ox} ${Neck_1_Oy} ${Neck_1_Oz}"/>
   <child link="neck_1"/>
   <axis xyz="0 0 1"/>
   <limit lower="-0.78539816" upper="0.78539816" effort="35" velocity="5.7"/> <!-- TODO -->
   <dynamics friction="${friction}" />
</joint>

<joint name="neck_pitch" type="revolute">
   <parent link="neck_1"/>
   <origin xyz="${Neck_2_Ox} ${Neck_2_Oy} ${Neck_2_Oz}"/>
   <child link="neck_2"/>
   <axis xyz="0 1 0"/>
   <limit lower="-0.34906585" upper="0.78539816" effort="35" velocity="5.7"/> <!-- TODO -->
   <dynamics friction="${friction}" />
</joint>

<joint name="neck_velodyne" type="continuous">
   <parent link="torso_2"/>
   <origin xyz="${Neck_3_Ox} ${Neck_3_Oy} ${Neck_3_Oz}"/>
   <child link="neck_3"/>
   <axis xyz="0 0 1"/>
   <limit effort="35" velocity="5.7"/> <!-- TODO -->
   <dynamics friction="${friction}" damping="${damping_arms}" />
</joint>
<!-- /head joints -->
<xacro:if value="${head_actuators}">
   <!-- head actuators -->
   <xacro:position_actuator joint="neck_yaw" />
   <xacro:position_actuator joint="neck_pitch" />
   <xacro:position_actuator joint="neck_velodyne" />
   <!-- /head actuators -->
</xacro:if>



<!-- sensors transformations  -->
<joint name="j_camera_central" type="fixed">
   <parent link="torso_2"/>
   <origin xyz="${Camera_central_Ox} ${Camera_central_Oy} ${Camera_central_Oz}" rpy="${Camera_central_roll} ${Camera_central_pitch} ${Camera_central_yaw}"/>
   <child link="camera_central"/>
</joint>
<joint name="j_camera_left" type="fixed">
   <parent link="torso_2"/>
   <origin xyz="${Camera_left_Ox} ${Camera_left_Oy} ${Camera_left_Oz}" rpy="${Camera_left_roll} ${Camera_left_pitch} ${Camera_left_yaw}"/>
   <child link="camera_left"/>
</joint>
<joint name="j_camera_right" type="fixed">
   <parent link="torso_2"/>
   <origin xyz="${Camera_right_Ox} ${Camera_right_Oy} ${Camera_right_Oz}" rpy="${Camera_right_roll} ${Camera_right_pitch} ${Camera_right_yaw}"/>
   <child link="camera_right"/>
</joint>
<joint name="j_kinect" type="fixed">
   <parent link="neck_2"/>
   <origin xyz="${Kinect_Ox} ${Kinect_Oy} ${Kinect_Oz}" rpy="${Kinect_roll} ${Kinect_pitch} ${Kinect_yaw}"/>
   <child link="kinect"/>
</joint>

<link name="kinect2_rgb_frame" />
<joint name="j_kinect2_rgb_frame" type="fixed">
	<parent link="kinect" />
	<child link="kinect2_rgb_frame" />
	<origin xyz="0.050 -0.110 -0.035" />
</joint>

<link name="kinect2_rgb_optical_frame" />
<joint name="j_kinect_optical_frame" type="fixed">
	<parent link="kinect2_rgb_frame"/>
	<child link="kinect2_rgb_optical_frame" />
	<origin rpy=" -${PI/2} 0 -${PI/2}"/>
</joint>

<joint name="j_velodyne" type="fixed">
   <parent link="neck_3"/>
   <origin xyz="${Velodyne_Ox} ${Velodyne_Oy} ${Velodyne_Oz}" rpy="${Velodyne_roll} ${Velodyne_pitch} ${Velodyne_yaw}"/>
   <child link="velodyne_mount"/>
</joint>
<!-- Kinect simulation -->



<!-- /sensors transformations -->

</robot>
