<sdf version='1.6'>
  <world name='default'>
    <gravity>0 0 -9.81</gravity>
    <model name='ground_plane'>
      <static>1</static>
      <link name='link'>
        <collision name='collision'>
          <geometry>
            <plane>
              <normal>0 0 1</normal>
              <size>100 100</size>
            </plane>
          </geometry>
          <surface>
            <friction>
              <ode>
                <mu>1</mu>
                <mu2>1</mu2>
              </ode>
              <torsional>
                <ode/>
              </torsional>
            </friction>
            <contact>
              <ode/>
            </contact>
            <bounce/>
          </surface>
          <max_contacts>10</max_contacts>
        </collision>
        <visual name='visual'>
          <cast_shadows>0</cast_shadows>
          <geometry>
            <plane>
              <normal>0 0 1</normal>
              <size>100 100</size>
            </plane>
          </geometry>
          <material>
            <script>
              <uri>file://media/materials/scripts/gazebo.material</uri>
              <name>Gazebo/Grey</name>
            </script>
          </material>
        </visual>
        <self_collide>0</self_collide>
        <kinematic>0</kinematic>
      </link>
    </model>
    <light name='sun' type='directional'>
      <cast_shadows>1</cast_shadows>
      <pose frame=''>0 0 10 0 -0 0</pose>
      <diffuse>0.8 0.8 0.8 1</diffuse>
      <specular>0.2 0.2 0.2 1</specular>
      <attenuation>
        <range>1000</range>
        <constant>0.9</constant>
        <linear>0.01</linear>
        <quadratic>0.001</quadratic>
      </attenuation>
      <direction>-0.5 0.1 -0.9</direction>
    </light>
    <gui fullscreen='0'>
      <camera name='user_camera'>
        <pose frame=''>0.511719 -3.85138 3.16059 0 0.565796 1.38825</pose>
        <view_controller>orbit</view_controller>
        <projection_type>perspective</projection_type>
      </camera>
    </gui>
    <physics name='update_rate' default='0' type='ode'>
      <real_time_update_rate>4000</real_time_update_rate>
      <max_step_size>0.00025</max_step_size>
      <max_contacts>5</max_contacts>
      <bullet>
        <solver>
          <iters>100</iters>
          <sor>1.55</sor>
          <type>sequential_impulse</type>
        </solver>
        <constraints>
          <contact_surface_layer>0.2</contact_surface_layer>
          <cfm>0.005</cfm>
          <erp>0.2</erp>
          <split_impulse>1</split_impulse>
          <split_impulse_penetration_threshold>-0.01</split_impulse_penetration_threshold>
        </constraints>
      </bullet>
      <ode>
        <solver>
          <iters>50</iters>
          <sor>1.2</sor>
          <type>quick</type>
          <use_dynamic_moi_rescaling>0</use_dynamic_moi_rescaling>
        </solver>
        <constraints>
          <contact_surface_layer>0.0002</contact_surface_layer>
          <contact_max_correcting_vel>500</contact_max_correcting_vel>
          <cfm>1e-06</cfm>
          <erp>0.3</erp>
        </constraints>
      </ode>
      <real_time_factor>1</real_time_factor>
    </physics>
    <magnetic_field>6e-06 2.3e-05 -4.2e-05</magnetic_field>
    <atmosphere type='adiabatic'/>
    <scene>
      <ambient>0.4 0.4 0.4 1</ambient>
      <background>0.7 0.7 0.7 1</background>
      <shadows>1</shadows>
    </scene>
    <spherical_coordinates>
      <surface_model>EARTH_WGS84</surface_model>
      <latitude_deg>0</latitude_deg>
      <longitude_deg>0</longitude_deg>
      <elevation>0</elevation>
      <heading_deg>0</heading_deg>
    </spherical_coordinates>
    <model name='centauro'>
      <link name='torso_2'>
        <pose frame=''>0.2 0 1.1816 0 -0 0</pose>
        <inertial>
          <pose frame=''>0.006445 0.002139 0.143021 0 -0 0</pose>
          <mass>6.18864</mass>
          <inertia>
            <ixx>0.0636434</ixx>
            <ixy>8.939e-05</ixy>
            <ixz>-0.00086873</ixz>
            <iyy>0.0268023</iyy>
            <iyz>-4.657e-05</iyz>
            <izz>0.0474301</izz>
          </inertia>
        </inertial>
        <collision name='torso_2_collision'>
          <pose frame=''>0 0 0 0 -0 0</pose>
          <geometry>
            <mesh>
              <scale>0.001 0.001 0.001</scale>
              <uri>/home/Cheng/advr-superbuild/robots/centauro-simulator/centauro/centauro_urdf/meshes/convex_hull/link1.stl</uri>
            </mesh>
          </geometry>
          <surface>
            <contact>
              <ode/>
            </contact>
            <friction>
              <ode>
                <mu>0</mu>
                <mu2>0</mu2>
              </ode>
              <torsional>
                <ode/>
              </torsional>
            </friction>
            <bounce/>
          </surface>
          <max_contacts>10</max_contacts>
        </collision>
        <visual name='torso_2_visual'>
          <pose frame=''>0 0 0 0 -0 0</pose>
          <geometry>
            <mesh>
              <scale>0.001 0.001 0.001</scale>
              <uri>/home/Cheng/advr-superbuild/robots/centauro-simulator/centauro/centauro_urdf/meshes/link1.stl</uri>
            </mesh>
          </geometry>
          <material>
            <script>
              <name>Gazebo/OrangeTransparent</name>
              <uri>file://media/materials/scripts/gazebo.material</uri>
            </script>
          </material>
        </visual>
        <gravity>1</gravity>
        <velocity_decay/>
        <self_collide>0</self_collide>
        <kinematic>0</kinematic>
      </link>
      <joint name='torso_yaw' type='revolute'>
        <child>torso_2</child>
        <parent>world</parent>
        <axis>
          <xyz>0 0 1</xyz>
          <limit>
            <lower>-2.618</lower>
            <upper>2.618</upper>
            <effort>147</effort>
            <velocity>5.7</velocity>
          </limit>
          <dynamics>
            <spring_reference>0</spring_reference>
            <spring_stiffness>0</spring_stiffness>
          </dynamics>
          <use_parent_model_frame>1</use_parent_model_frame>
        </axis>
      </joint>
      <link name='arm1_1'>
        <pose frame=''>0.24576 0.169137 1.29823 0 0 -0.523603</pose>
        <inertial>
          <pose frame=''>-0.003101 0.040325 0.007452 0 -0 0</pose>
          <mass>1.55833</mass>
          <inertia>
            <ixx>0.00323186</ixx>
            <ixy>4.24587e-05</ixy>
            <ixz>4.91626e-05</ixz>
            <iyy>0.00275718</iyy>
            <iyz>-0.000238706</iyz>
            <izz>0.00427505</izz>
          </inertia>
        </inertial>
        <collision name='arm1_1_collision'>
          <pose frame=''>0 0 0 0 -0 0</pose>
          <geometry>
            <mesh>
              <scale>0.001 -0.001 0.001</scale>
              <uri>/home/Cheng/advr-superbuild/robots/centauro-simulator/centauro/centauro_urdf/meshes/convex_hull/link2.stl</uri>
            </mesh>
          </geometry>
          <surface>
            <contact>
              <ode/>
            </contact>
            <friction>
              <ode>
                <mu>0</mu>
                <mu2>0</mu2>
              </ode>
              <torsional>
                <ode/>
              </torsional>
            </friction>
            <bounce/>
          </surface>
          <max_contacts>10</max_contacts>
        </collision>
        <visual name='arm1_1_visual'>
          <pose frame=''>0 0 0 0 -0 0</pose>
          <geometry>
            <mesh>
              <scale>0.001 -0.001 0.001</scale>
              <uri>/home/Cheng/advr-superbuild/robots/centauro-simulator/centauro/centauro_urdf/meshes/link2.stl</uri>
            </mesh>
          </geometry>
          <material>
            <script>
              <name>Gazebo/Lane_1</name>
              <uri>file://media/materials/scripts/gazebo.material</uri>
            </script>
          </material>
        </visual>
        <gravity>1</gravity>
        <velocity_decay/>
        <self_collide>0</self_collide>
        <kinematic>0</kinematic>
      </link>
      <joint name='j_arm1_1' type='revolute'>
        <child>arm1_1</child>
        <parent>torso_2</parent>
        <axis>
          <xyz>0.492407 0.852867 0.173648</xyz>
          <limit>
            <lower>-3.403</lower>
            <upper>1.658</upper>
            <effort>147</effort>
            <velocity>5.7</velocity>
          </limit>
          <dynamics>
            <spring_reference>0</spring_reference>
            <spring_stiffness>0</spring_stiffness>
          </dynamics>
          <use_parent_model_frame>1</use_parent_model_frame>
        </axis>
      </joint>
      <link name='arm1_2'>
        <pose frame=''>0.197352 0.267592 1.30899 0 0 -0.523603</pose>
        <inertial>
          <pose frame=''>0.051054 0.000111 -0.076436 0 -0 0</pose>
          <mass>1.51506</mass>
          <inertia>
            <ixx>0.0102956</ixx>
            <ixy>2.846e-05</ixy>
            <ixz>0.0036567</ixz>
            <iyy>0.0117802</iyy>
            <iyz>2.088e-05</iyz>
            <izz>0.00386123</izz>
          </inertia>
        </inertial>
        <collision name='arm1_2_collision'>
          <pose frame=''>0 0 0 0 -0 0</pose>
          <geometry>
            <mesh>
              <scale>0.001 -0.001 0.001</scale>
              <uri>/home/Cheng/advr-superbuild/robots/centauro-simulator/centauro/centauro_urdf/meshes/convex_hull/link3.stl</uri>
            </mesh>
          </geometry>
          <surface>
            <contact>
              <ode/>
            </contact>
            <friction>
              <ode>
                <mu>0</mu>
                <mu2>0</mu2>
              </ode>
              <torsional>
                <ode/>
              </torsional>
            </friction>
            <bounce/>
          </surface>
          <max_contacts>10</max_contacts>
        </collision>
        <visual name='arm1_2_visual'>
          <pose frame=''>0 0 0 0 -0 0</pose>
          <geometry>
            <mesh>
              <scale>0.001 -0.001 0.001</scale>
              <uri>/home/Cheng/advr-superbuild/robots/centauro-simulator/centauro/centauro_urdf/meshes/link3.stl</uri>
            </mesh>
          </geometry>
          <material>
            <script>
              <name>Gazebo/OrangeTransparent</name>
              <uri>file://media/materials/scripts/gazebo.material</uri>
            </script>
          </material>
        </visual>
        <gravity>1</gravity>
        <velocity_decay/>
        <self_collide>0</self_collide>
        <kinematic>0</kinematic>
      </link>
      <joint name='j_arm1_2' type='revolute'>
        <child>arm1_2</child>
        <parent>arm1_1</parent>
        <axis>
          <xyz>-0.866023 0.500003 0</xyz>
          <limit>
            <lower>-3.49</lower>
            <upper>0</upper>
            <effort>147</effort>
            <velocity>5.7</velocity>
          </limit>
          <dynamics>
            <spring_reference>0</spring_reference>
            <spring_stiffness>0</spring_stiffness>
          </dynamics>
          <use_parent_model_frame>1</use_parent_model_frame>
        </axis>
      </joint>
      <link name='arm1_3'>
        <pose frame=''>0.27629 0.222016 1.08984 0 0 -0.523603</pose>
        <inertial>
          <pose frame=''>0.012076 0.00322 -0.034273 0 -0 0</pose>
          <mass>1.50881</mass>
          <inertia>
            <ixx>0.00469819</ixx>
            <ixy>-0.00026547</ixy>
            <ixz>0.00077706</ixz>
            <iyy>0.00501755</iyy>
            <iyz>0.00029679</iyz>
            <izz>0.00310954</izz>
          </inertia>
        </inertial>
        <collision name='arm1_3_collision'>
          <pose frame=''>0 0 0 0 -0 0</pose>
          <geometry>
            <mesh>
              <scale>0.001 -0.001 0.001</scale>
              <uri>/home/Cheng/advr-superbuild/robots/centauro-simulator/centauro/centauro_urdf/meshes/convex_hull/link4.stl</uri>
            </mesh>
          </geometry>
          <surface>
            <contact>
              <ode/>
            </contact>
            <friction>
              <ode>
                <mu>0</mu>
                <mu2>0</mu2>
              </ode>
              <torsional>
                <ode/>
              </torsional>
            </friction>
            <bounce/>
          </surface>
          <max_contacts>10</max_contacts>
        </collision>
        <visual name='arm1_3_visual'>
          <pose frame=''>0 0 0 0 -0 0</pose>
          <geometry>
            <mesh>
              <scale>0.001 -0.001 0.001</scale>
              <uri>/home/Cheng/advr-superbuild/robots/centauro-simulator/centauro/centauro_urdf/meshes/link4.stl</uri>
            </mesh>
          </geometry>
          <material>
            <script>
              <name>Gazebo/Lane_1</name>
              <uri>file://media/materials/scripts/gazebo.material</uri>
            </script>
          </material>
        </visual>
        <gravity>1</gravity>
        <velocity_decay/>
        <self_collide>0</self_collide>
        <kinematic>0</kinematic>
      </link>
      <joint name='j_arm1_3' type='revolute'>
        <child>arm1_3</child>
        <parent>arm1_2</parent>
        <axis>
          <xyz>0 0 -1</xyz>
          <limit>
            <lower>-2.618</lower>
            <upper>2.618</upper>
            <effort>147</effort>
            <velocity>8.2</velocity>
          </limit>
          <dynamics>
            <spring_reference>0</spring_reference>
            <spring_stiffness>0</spring_stiffness>
          </dynamics>
          <use_parent_model_frame>1</use_parent_model_frame>
        </axis>
      </joint>
      <link name='arm1_4'>
        <pose frame=''>0.339006 0.250643 1.01584 0 0 -0.523603</pose>
        <inertial>
          <pose frame=''>0.010148 -0.029929 -0.032528 0 -0 0</pose>
          <mass>0.962973</mass>
          <inertia>
            <ixx>0.00264936</ixx>
            <ixy>5.1632e-06</ixy>
            <ixz>0.000129231</ixz>
            <iyy>0.0023471</iyy>
            <iyz>-0.000789575</iyz>
            <izz>0.00122131</izz>
          </inertia>
        </inertial>
        <collision name='arm1_4_collision'>
          <pose frame=''>0 0 0 0 -0 0</pose>
          <geometry>
            <mesh>
              <scale>0.001 -0.001 0.001</scale>
              <uri>/home/Cheng/advr-superbuild/robots/centauro-simulator/centauro/centauro_urdf/meshes/convex_hull/link5.stl</uri>
            </mesh>
          </geometry>
          <surface>
            <contact>
              <ode/>
            </contact>
            <friction>
              <ode>
                <mu>0</mu>
                <mu2>0</mu2>
              </ode>
              <torsional>
                <ode/>
              </torsional>
            </friction>
            <bounce/>
          </surface>
          <max_contacts>10</max_contacts>
        </collision>
        <visual name='arm1_4_visual'>
          <pose frame=''>0 0 0 0 -0 0</pose>
          <geometry>
            <mesh>
              <scale>0.001 -0.001 0.001</scale>
              <uri>/home/Cheng/advr-superbuild/robots/centauro-simulator/centauro/centauro_urdf/meshes/link5.stl</uri>
            </mesh>
          </geometry>
          <material>
            <script>
              <name>Gazebo/OrangeTransparent</name>
              <uri>file://media/materials/scripts/gazebo.material</uri>
            </script>
          </material>
        </visual>
        <gravity>1</gravity>
        <velocity_decay/>
        <self_collide>0</self_collide>
        <kinematic>0</kinematic>
      </link>
      <joint name='j_arm1_4' type='revolute'>
        <child>arm1_4</child>
        <parent>arm1_3</parent>
        <axis>
          <xyz>0.500003 0.866023 0</xyz>
          <limit>
            <lower>-2.53</lower>
            <upper>0.349</upper>
            <effort>147</effort>
            <velocity>8.2</velocity>
          </limit>
          <dynamics>
            <spring_reference>0</spring_reference>
            <spring_stiffness>0</spring_stiffness>
          </dynamics>
          <use_parent_model_frame>1</use_parent_model_frame>
        </axis>
      </joint>
      <link name='arm1_5'>
        <pose frame=''>0.297941 0.209516 0.954842 0 0 -0.523603</pose>
        <inertial>
          <pose frame=''>-0.000157 0.004132 -0.107566 0 -0 0</pose>
          <mass>1.47037</mass>
          <inertia>
            <ixx>0.00641605</ixx>
            <ixy>1.96382e-05</ixy>
            <ixz>2.49912e-05</ixz>
            <iyy>0.00620164</iyy>
            <iyz>-0.00019879</iyz>
            <izz>0.00170917</izz>
          </inertia>
        </inertial>
        <collision name='arm1_5_collision'>
          <pose frame=''>0 0 0 0 -0 0</pose>
          <geometry>
            <mesh>
              <scale>0.001 -0.001 0.001</scale>
              <uri>/home/Cheng/advr-superbuild/robots/centauro-simulator/centauro/centauro_urdf/meshes/convex_hull/link6.stl</uri>
            </mesh>
          </geometry>
          <surface>
            <contact>
              <ode/>
            </contact>
            <friction>
              <ode>
                <mu>0</mu>
                <mu2>0</mu2>
              </ode>
              <torsional>
                <ode/>
              </torsional>
            </friction>
            <bounce/>
          </surface>
          <max_contacts>10</max_contacts>
        </collision>
        <visual name='arm1_5_visual'>
          <pose frame=''>0 0 0 0 -0 0</pose>
          <geometry>
            <mesh>
              <scale>0.001 -0.001 0.001</scale>
              <uri>/home/Cheng/advr-superbuild/robots/centauro-simulator/centauro/centauro_urdf/meshes/link6.stl</uri>
            </mesh>
          </geometry>
          <material>
            <script>
              <name>Gazebo/Lane_1</name>
              <uri>file://media/materials/scripts/gazebo.material</uri>
            </script>
          </material>
        </visual>
        <gravity>1</gravity>
        <velocity_decay/>
        <self_collide>0</self_collide>
        <kinematic>0</kinematic>
      </link>
      <joint name='j_arm1_5' type='revolute'>
        <child>arm1_5</child>
        <parent>arm1_4</parent>
        <axis>
          <xyz>0 0 -1</xyz>
          <limit>
            <lower>-2.618</lower>
            <upper>2.618</upper>
            <effort>55</effort>
            <velocity>11.6</velocity>
          </limit>
          <dynamics>
            <spring_reference>0</spring_reference>
            <spring_stiffness>0</spring_stiffness>
          </dynamics>
          <use_parent_model_frame>1</use_parent_model_frame>
        </axis>
      </joint>
      <link name='arm1_6'>
        <pose frame=''>0.322441 0.251951 0.774842 0 0 -0.523603</pose>
        <inertial>
          <pose frame=''>3.2e-05 -0.035947 -0.080878 0 -0 0</pose>
          <mass>0.946939</mass>
          <inertia>
            <ixx>0.00368966</ixx>
            <ixy>2.63667e-05</ixy>
            <ixz>1.4005e-06</ixz>
            <iyy>0.00341463</iyy>
            <iyz>-0.00082681</iyz>
            <izz>0.00107902</izz>
          </inertia>
        </inertial>
        <collision name='arm1_6_collision'>
          <pose frame=''>0 0 0 0 -0 0</pose>
          <geometry>
            <mesh>
              <scale>0.001 -0.001 0.001</scale>
              <uri>/home/Cheng/advr-superbuild/robots/centauro-simulator/centauro/centauro_urdf/meshes/convex_hull/link7.stl</uri>
            </mesh>
          </geometry>
          <surface>
            <contact>
              <ode/>
            </contact>
            <friction>
              <ode>
                <mu>0</mu>
                <mu2>0</mu2>
              </ode>
              <torsional>
                <ode/>
              </torsional>
            </friction>
            <bounce/>
          </surface>
          <max_contacts>10</max_contacts>
        </collision>
        <visual name='arm1_6_visual'>
          <pose frame=''>0 0 0 0 -0 0</pose>
          <geometry>
            <mesh>
              <scale>0.001 -0.001 0.001</scale>
              <uri>/home/Cheng/advr-superbuild/robots/centauro-simulator/centauro/centauro_urdf/meshes/link7.stl</uri>
            </mesh>
          </geometry>
          <material>
            <script>
              <name>Gazebo/OrangeTransparent</name>
              <uri>file://media/materials/scripts/gazebo.material</uri>
            </script>
          </material>
        </visual>
        <gravity>1</gravity>
        <velocity_decay/>
        <self_collide>0</self_collide>
        <kinematic>0</kinematic>
      </link>
      <joint name='j_arm1_6' type='revolute'>
        <child>arm1_6</child>
        <parent>arm1_5</parent>
        <axis>
          <xyz>0.500003 0.866023 0</xyz>
          <limit>
            <lower>-1.57</lower>
            <upper>1.57</upper>
            <effort>55</effort>
            <velocity>11.6</velocity>
          </limit>
          <dynamics>
            <spring_reference>0</spring_reference>
            <spring_stiffness>0</spring_stiffness>
          </dynamics>
          <use_parent_model_frame>1</use_parent_model_frame>
        </axis>
      </joint>
      <link name='arm1_7'>
        <pose frame=''>0.297941 0.209516 0.605842 0 0 -0.523603</pose>
        <inertial>
          <pose frame=''>2.5e-05 -0.000147 -0.005299 0 -0 0</pose>
          <mass>0.55981</mass>
          <inertia>
            <ixx>0.000436017</ixx>
            <ixy>1.397e-07</ixy>
            <ixz>-1.382e-07</ixz>
            <iyy>0.000429917</iyy>
            <iyz>-1.4752e-06</iyz>
            <izz>0.000452222</izz>
          </inertia>
        </inertial>
        <collision name='arm1_7_collision'>
          <pose frame=''>0 0 0 0 -0 0</pose>
          <geometry>
            <mesh>
              <scale>0.001 -0.001 0.001</scale>
              <uri>/home/Cheng/advr-superbuild/robots/centauro-simulator/centauro/centauro_urdf/meshes/convex_hull/link8.stl</uri>
            </mesh>
          </geometry>
          <surface>
            <contact>
              <ode/>
            </contact>
            <friction>
              <ode>
                <mu>0</mu>
                <mu2>0</mu2>
              </ode>
              <torsional>
                <ode/>
              </torsional>
            </friction>
            <bounce/>
          </surface>
          <max_contacts>10</max_contacts>
        </collision>
        <visual name='arm1_7_visual'>
          <pose frame=''>0 0 0 0 -0 0</pose>
          <geometry>
            <mesh>
              <scale>0.001 -0.001 0.001</scale>
              <uri>/home/Cheng/advr-superbuild/robots/centauro-simulator/centauro/centauro_urdf/meshes/link8.stl</uri>
            </mesh>
          </geometry>
          <material>
            <script>
              <name>Gazebo/Lane_1</name>
              <uri>file://media/materials/scripts/gazebo.material</uri>
            </script>
          </material>
        </visual>
        <gravity>1</gravity>
        <velocity_decay/>
        <self_collide>0</self_collide>
        <kinematic>0</kinematic>
      </link>
      <joint name='j_arm1_7' type='revolute'>
        <child>arm1_7</child>
        <parent>arm1_6</parent>
        <axis>
          <xyz>0 0 -1</xyz>
          <limit>
            <lower>-2.618</lower>
            <upper>2.618</upper>
            <effort>27</effort>
            <velocity>20.3</velocity>
          </limit>
          <dynamics>
            <spring_reference>0</spring_reference>
            <spring_stiffness>0</spring_stiffness>
          </dynamics>
          <use_parent_model_frame>1</use_parent_model_frame>
        </axis>
      </joint>
      <link name='arm1_8'>
        <pose frame=''>0.297941 0.209516 0.565342 3.14159 0 1.04719</pose>
        <inertial>
          <pose frame=''>0 0 0.1 0 -0 0</pose>
          <mass>0.3</mass>
          <inertia>
            <ixx>0.000245</ixx>
            <ixy>0</ixy>
            <ixz>0</ixz>
            <iyy>0.000245</iyy>
            <iyz>0</iyz>
            <izz>0.000245</izz>
          </inertia>
        </inertial>
        <collision name='arm1_8_collision'>
          <pose frame=''>0 0 0 0 -0 0</pose>
          <geometry>
            <box>
              <size>0.03 0.08 0.12</size>
            </box>
          </geometry>
          <surface>
            <contact>
              <ode/>
            </contact>
            <friction>
              <ode>
                <mu>0</mu>
                <mu2>0</mu2>
              </ode>
              <torsional>
                <ode/>
              </torsional>
            </friction>
            <bounce/>
          </surface>
          <max_contacts>10</max_contacts>
        </collision>
        <visual name='arm1_8_visual'>
          <pose frame=''>0 0 0 0 -0 0</pose>
          <geometry>
            <box>
              <size>0.03 0.08 0.12</size>
            </box>
          </geometry>
          <material>
            <script>
              <name>Gazebo/OrangeTransparent</name>
              <uri>file://media/materials/scripts/gazebo.material</uri>
            </script>
          </material>
        </visual>
        <gravity>1</gravity>
        <velocity_decay/>
        <self_collide>0</self_collide>
        <kinematic>0</kinematic>
      </link>
      <joint name='j_arm1_8' type='revolute'>
        <child>arm1_8</child>
        <parent>arm1_7</parent>
        <axis>
          <xyz>0.500003 0.866023 0</xyz>
          <limit>
            <lower>0</lower>
            <upper>0</upper>
            <effort>0</effort>
            <velocity>0</velocity>
          </limit>
          <dynamics>
            <spring_reference>0</spring_reference>
            <spring_stiffness>0</spring_stiffness>
          </dynamics>
          <use_parent_model_frame>1</use_parent_model_frame>
        </axis>
        <physics>
          <ode>
            <limit>
              <cfm>0</cfm>
              <erp>0.2</erp>
            </limit>
          </ode>
        </physics>
        <sensor name='left_arm_ft' type='force_torque'>
          <force_torque>
            <frame>parent</frame>
            <measure_direction>child_to_parent</measure_direction>
          </force_torque>
          <always_on>1</always_on>
          <visualize>1</visualize>
          <update_rate>1000</update_rate>
          <pose frame=''>0 0 0 0 -0 0</pose>
        </sensor>
      </joint>
      <link name='arm2_1'>
        <pose frame=''>0.24576 -0.169137 1.29823 0 -0 0.523603</pose>
        <inertial>
          <pose frame=''>-0.003101 -0.040325 0.007452 0 -0 0</pose>
          <mass>1.55833</mass>
          <inertia>
            <ixx>0.00323186</ixx>
            <ixy>-4.24587e-05</ixy>
            <ixz>4.91626e-05</ixz>
            <iyy>0.00275718</iyy>
            <iyz>0.000238706</iyz>
            <izz>0.00427505</izz>
          </inertia>
        </inertial>
        <collision name='arm2_1_collision'>
          <pose frame=''>0 0 0 0 -0 0</pose>
          <geometry>
            <mesh>
              <scale>0.001 0.001 0.001</scale>
              <uri>/home/Cheng/advr-superbuild/robots/centauro-simulator/centauro/centauro_urdf/meshes/convex_hull/link2.stl</uri>
            </mesh>
          </geometry>
          <surface>
            <contact>
              <ode/>
            </contact>
            <friction>
              <ode>
                <mu>0</mu>
                <mu2>0</mu2>
              </ode>
              <torsional>
                <ode/>
              </torsional>
            </friction>
            <bounce/>
          </surface>
          <max_contacts>10</max_contacts>
        </collision>
        <visual name='arm2_1_visual'>
          <pose frame=''>0 0 0 0 -0 0</pose>
          <geometry>
            <mesh>
              <scale>0.001 0.001 0.001</scale>
              <uri>/home/Cheng/advr-superbuild/robots/centauro-simulator/centauro/centauro_urdf/meshes/link2.stl</uri>
            </mesh>
          </geometry>
          <material>
            <script>
              <name>Gazebo/Lane_1</name>
              <uri>file://media/materials/scripts/gazebo.material</uri>
            </script>
          </material>
        </visual>
        <gravity>1</gravity>
        <velocity_decay/>
        <self_collide>0</self_collide>
        <kinematic>0</kinematic>
      </link>
      <joint name='j_arm2_1' type='revolute'>
        <child>arm2_1</child>
        <parent>torso_2</parent>
        <axis>
          <xyz>0.492407 -0.852867 0.173648</xyz>
          <limit>
            <lower>-1.658</lower>
            <upper>3.403</upper>
            <effort>147</effort>
            <velocity>5.7</velocity>
          </limit>
          <dynamics>
            <spring_reference>0</spring_reference>
            <spring_stiffness>0</spring_stiffness>
          </dynamics>
          <use_parent_model_frame>1</use_parent_model_frame>
        </axis>
      </joint>
      <link name='arm2_2'>
        <pose frame=''>0.197352 -0.267592 1.30899 0 -0 0.523603</pose>
        <inertial>
          <pose frame=''>0.051054 -0.000111 -0.076436 0 -0 0</pose>
          <mass>1.51506</mass>
          <inertia>
            <ixx>0.0102956</ixx>
            <ixy>-2.846e-05</ixy>
            <ixz>0.0036567</ixz>
            <iyy>0.0117802</iyy>
            <iyz>-2.088e-05</iyz>
            <izz>0.00386123</izz>
          </inertia>
        </inertial>
        <collision name='arm2_2_collision'>
          <pose frame=''>0 0 0 0 -0 0</pose>
          <geometry>
            <mesh>
              <scale>0.001 0.001 0.001</scale>
              <uri>/home/Cheng/advr-superbuild/robots/centauro-simulator/centauro/centauro_urdf/meshes/convex_hull/link3.stl</uri>
            </mesh>
          </geometry>
          <surface>
            <contact>
              <ode/>
            </contact>
            <friction>
              <ode>
                <mu>0</mu>
                <mu2>0</mu2>
              </ode>
              <torsional>
                <ode/>
              </torsional>
            </friction>
            <bounce/>
          </surface>
          <max_contacts>10</max_contacts>
        </collision>
        <visual name='arm2_2_visual'>
          <pose frame=''>0 0 0 0 -0 0</pose>
          <geometry>
            <mesh>
              <scale>0.001 0.001 0.001</scale>
              <uri>/home/Cheng/advr-superbuild/robots/centauro-simulator/centauro/centauro_urdf/meshes/link3.stl</uri>
            </mesh>
          </geometry>
          <material>
            <script>
              <name>Gazebo/OrangeTransparent</name>
              <uri>file://media/materials/scripts/gazebo.material</uri>
            </script>
          </material>
        </visual>
        <gravity>1</gravity>
        <velocity_decay/>
        <self_collide>0</self_collide>
        <kinematic>0</kinematic>
      </link>
      <joint name='j_arm2_2' type='revolute'>
        <child>arm2_2</child>
        <parent>arm2_1</parent>
        <axis>
          <xyz>-0.866023 -0.500003 0</xyz>
          <limit>
            <lower>0</lower>
            <upper>3.49</upper>
            <effort>147</effort>
            <velocity>5.7</velocity>
          </limit>
          <dynamics>
            <spring_reference>0</spring_reference>
            <spring_stiffness>0</spring_stiffness>
          </dynamics>
          <use_parent_model_frame>1</use_parent_model_frame>
        </axis>
      </joint>
      <link name='arm2_3'>
        <pose frame=''>0.27629 -0.222016 1.08984 0 -0 0.523603</pose>
        <inertial>
          <pose frame=''>0.012076 -0.00322 -0.034273 0 -0 0</pose>
          <mass>1.50881</mass>
          <inertia>
            <ixx>0.00469819</ixx>
            <ixy>0.00026547</ixy>
            <ixz>0.00077706</ixz>
            <iyy>0.00501755</iyy>
            <iyz>-0.00029679</iyz>
            <izz>0.00310954</izz>
          </inertia>
        </inertial>
        <collision name='arm2_3_collision'>
          <pose frame=''>0 0 0 0 -0 0</pose>
          <geometry>
            <mesh>
              <scale>0.001 0.001 0.001</scale>
              <uri>/home/Cheng/advr-superbuild/robots/centauro-simulator/centauro/centauro_urdf/meshes/convex_hull/link4.stl</uri>
            </mesh>
          </geometry>
          <surface>
            <contact>
              <ode/>
            </contact>
            <friction>
              <ode>
                <mu>0</mu>
                <mu2>0</mu2>
              </ode>
              <torsional>
                <ode/>
              </torsional>
            </friction>
            <bounce/>
          </surface>
          <max_contacts>10</max_contacts>
        </collision>
        <visual name='arm2_3_visual'>
          <pose frame=''>0 0 0 0 -0 0</pose>
          <geometry>
            <mesh>
              <scale>0.001 0.001 0.001</scale>
              <uri>/home/Cheng/advr-superbuild/robots/centauro-simulator/centauro/centauro_urdf/meshes/link4.stl</uri>
            </mesh>
          </geometry>
          <material>
            <script>
              <name>Gazebo/Lane_1</name>
              <uri>file://media/materials/scripts/gazebo.material</uri>
            </script>
          </material>
        </visual>
        <gravity>1</gravity>
        <velocity_decay/>
        <self_collide>0</self_collide>
        <kinematic>0</kinematic>
      </link>
      <joint name='j_arm2_3' type='revolute'>
        <child>arm2_3</child>
        <parent>arm2_2</parent>
        <axis>
          <xyz>0 0 -1</xyz>
          <limit>
            <lower>-2.618</lower>
            <upper>2.618</upper>
            <effort>147</effort>
            <velocity>8.2</velocity>
          </limit>
          <dynamics>
            <spring_reference>0</spring_reference>
            <spring_stiffness>0</spring_stiffness>
          </dynamics>
          <use_parent_model_frame>1</use_parent_model_frame>
        </axis>
      </joint>
      <link name='arm2_4'>
        <pose frame=''>0.339006 -0.250643 1.01584 0 -0 0.523603</pose>
        <inertial>
          <pose frame=''>0.010148 0.029929 -0.032528 0 -0 0</pose>
          <mass>0.962973</mass>
          <inertia>
            <ixx>0.00264936</ixx>
            <ixy>-5.1632e-06</ixy>
            <ixz>0.000129231</ixz>
            <iyy>0.0023471</iyy>
            <iyz>0.000789575</iyz>
            <izz>0.00122131</izz>
          </inertia>
        </inertial>
        <collision name='arm2_4_collision'>
          <pose frame=''>0 0 0 0 -0 0</pose>
          <geometry>
            <mesh>
              <scale>0.001 0.001 0.001</scale>
              <uri>/home/Cheng/advr-superbuild/robots/centauro-simulator/centauro/centauro_urdf/meshes/convex_hull/link5.stl</uri>
            </mesh>
          </geometry>
          <surface>
            <contact>
              <ode/>
            </contact>
            <friction>
              <ode>
                <mu>0</mu>
                <mu2>0</mu2>
              </ode>
              <torsional>
                <ode/>
              </torsional>
            </friction>
            <bounce/>
          </surface>
          <max_contacts>10</max_contacts>
        </collision>
        <visual name='arm2_4_visual'>
          <pose frame=''>0 0 0 0 -0 0</pose>
          <geometry>
            <mesh>
              <scale>0.001 0.001 0.001</scale>
              <uri>/home/Cheng/advr-superbuild/robots/centauro-simulator/centauro/centauro_urdf/meshes/link5.stl</uri>
            </mesh>
          </geometry>
          <material>
            <script>
              <name>Gazebo/OrangeTransparent</name>
              <uri>file://media/materials/scripts/gazebo.material</uri>
            </script>
          </material>
        </visual>
        <gravity>1</gravity>
        <velocity_decay/>
        <self_collide>0</self_collide>
        <kinematic>0</kinematic>
      </link>
      <joint name='j_arm2_4' type='revolute'>
        <child>arm2_4</child>
        <parent>arm2_3</parent>
        <axis>
          <xyz>0.500003 -0.866023 0</xyz>
          <limit>
            <lower>-0.349</lower>
            <upper>2.53</upper>
            <effort>147</effort>
            <velocity>8.2</velocity>
          </limit>
          <dynamics>
            <spring_reference>0</spring_reference>
            <spring_stiffness>0</spring_stiffness>
          </dynamics>
          <use_parent_model_frame>1</use_parent_model_frame>
        </axis>
      </joint>
      <link name='arm2_5'>
        <pose frame=''>0.297941 -0.209516 0.954842 0 -0 0.523603</pose>
        <inertial>
          <pose frame=''>-0.000157 -0.004132 -0.107566 0 -0 0</pose>
          <mass>1.47037</mass>
          <inertia>
            <ixx>0.00641605</ixx>
            <ixy>-1.96382e-05</ixy>
            <ixz>2.49912e-05</ixz>
            <iyy>0.00620164</iyy>
            <iyz>0.00019879</iyz>
            <izz>0.00170917</izz>
          </inertia>
        </inertial>
        <collision name='arm2_5_collision'>
          <pose frame=''>0 0 0 0 -0 0</pose>
          <geometry>
            <mesh>
              <scale>0.001 0.001 0.001</scale>
              <uri>/home/Cheng/advr-superbuild/robots/centauro-simulator/centauro/centauro_urdf/meshes/convex_hull/link6.stl</uri>
            </mesh>
          </geometry>
          <surface>
            <contact>
              <ode/>
            </contact>
            <friction>
              <ode>
                <mu>0</mu>
                <mu2>0</mu2>
              </ode>
              <torsional>
                <ode/>
              </torsional>
            </friction>
            <bounce/>
          </surface>
          <max_contacts>10</max_contacts>
        </collision>
        <visual name='arm2_5_visual'>
          <pose frame=''>0 0 0 0 -0 0</pose>
          <geometry>
            <mesh>
              <scale>0.001 0.001 0.001</scale>
              <uri>/home/Cheng/advr-superbuild/robots/centauro-simulator/centauro/centauro_urdf/meshes/link6.stl</uri>
            </mesh>
          </geometry>
          <material>
            <script>
              <name>Gazebo/Lane_1</name>
              <uri>file://media/materials/scripts/gazebo.material</uri>
            </script>
          </material>
        </visual>
        <gravity>1</gravity>
        <velocity_decay/>
        <self_collide>0</self_collide>
        <kinematic>0</kinematic>
      </link>
      <joint name='j_arm2_5' type='revolute'>
        <child>arm2_5</child>
        <parent>arm2_4</parent>
        <axis>
          <xyz>0 0 -1</xyz>
          <limit>
            <lower>-2.618</lower>
            <upper>2.618</upper>
            <effort>55</effort>
            <velocity>11.6</velocity>
          </limit>
          <dynamics>
            <spring_reference>0</spring_reference>
            <spring_stiffness>0</spring_stiffness>
          </dynamics>
          <use_parent_model_frame>1</use_parent_model_frame>
        </axis>
      </joint>
      <link name='arm2_6'>
        <pose frame=''>0.322441 -0.251951 0.774842 0 -0 0.523603</pose>
        <inertial>
          <pose frame=''>3.2e-05 0.035947 -0.080878 0 -0 0</pose>
          <mass>0.946939</mass>
          <inertia>
            <ixx>0.00368966</ixx>
            <ixy>-2.63667e-05</ixy>
            <ixz>1.4005e-06</ixz>
            <iyy>0.00341463</iyy>
            <iyz>0.00082681</iyz>
            <izz>0.00107902</izz>
          </inertia>
        </inertial>
        <collision name='arm2_6_collision'>
          <pose frame=''>0 0 0 0 -0 0</pose>
          <geometry>
            <mesh>
              <scale>0.001 0.001 0.001</scale>
              <uri>/home/Cheng/advr-superbuild/robots/centauro-simulator/centauro/centauro_urdf/meshes/convex_hull/link7.stl</uri>
            </mesh>
          </geometry>
          <surface>
            <contact>
              <ode/>
            </contact>
            <friction>
              <ode>
                <mu>0</mu>
                <mu2>0</mu2>
              </ode>
              <torsional>
                <ode/>
              </torsional>
            </friction>
            <bounce/>
          </surface>
          <max_contacts>10</max_contacts>
        </collision>
        <visual name='arm2_6_visual'>
          <pose frame=''>0 0 0 0 -0 0</pose>
          <geometry>
            <mesh>
              <scale>0.001 0.001 0.001</scale>
              <uri>/home/Cheng/advr-superbuild/robots/centauro-simulator/centauro/centauro_urdf/meshes/link7.stl</uri>
            </mesh>
          </geometry>
          <material>
            <script>
              <name>Gazebo/OrangeTransparent</name>
              <uri>file://media/materials/scripts/gazebo.material</uri>
            </script>
          </material>
        </visual>
        <gravity>1</gravity>
        <velocity_decay/>
        <self_collide>0</self_collide>
        <kinematic>0</kinematic>
      </link>
      <joint name='j_arm2_6' type='revolute'>
        <child>arm2_6</child>
        <parent>arm2_5</parent>
        <axis>
          <xyz>0.500003 -0.866023 0</xyz>
          <limit>
            <lower>-1.57</lower>
            <upper>1.57</upper>
            <effort>55</effort>
            <velocity>11.6</velocity>
          </limit>
          <dynamics>
            <spring_reference>0</spring_reference>
            <spring_stiffness>0</spring_stiffness>
          </dynamics>
          <use_parent_model_frame>1</use_parent_model_frame>
        </axis>
      </joint>
      <link name='arm2_7'>
        <pose frame=''>0.297941 -0.209516 0.605842 0 -0 0.523603</pose>
        <inertial>
          <pose frame=''>2.5e-05 0.000147 -0.005299 0 -0 0</pose>
          <mass>0.55981</mass>
          <inertia>
            <ixx>0.000436017</ixx>
            <ixy>-1.397e-07</ixy>
            <ixz>-1.382e-07</ixz>
            <iyy>0.000429917</iyy>
            <iyz>1.4752e-06</iyz>
            <izz>0.000452222</izz>
          </inertia>
        </inertial>
        <collision name='arm2_7_collision'>
          <pose frame=''>0 0 0 0 -0 0</pose>
          <geometry>
            <mesh>
              <scale>0.001 0.001 0.001</scale>
              <uri>/home/Cheng/advr-superbuild/robots/centauro-simulator/centauro/centauro_urdf/meshes/convex_hull/link8.stl</uri>
            </mesh>
          </geometry>
          <surface>
            <contact>
              <ode/>
            </contact>
            <friction>
              <ode>
                <mu>0</mu>
                <mu2>0</mu2>
              </ode>
              <torsional>
                <ode/>
              </torsional>
            </friction>
            <bounce/>
          </surface>
          <max_contacts>10</max_contacts>
        </collision>
        <visual name='arm2_7_visual'>
          <pose frame=''>0 0 0 0 -0 0</pose>
          <geometry>
            <mesh>
              <scale>0.001 0.001 0.001</scale>
              <uri>/home/Cheng/advr-superbuild/robots/centauro-simulator/centauro/centauro_urdf/meshes/link8.stl</uri>
            </mesh>
          </geometry>
          <material>
            <script>
              <name>Gazebo/Lane_1</name>
              <uri>file://media/materials/scripts/gazebo.material</uri>
            </script>
          </material>
        </visual>
        <gravity>1</gravity>
        <velocity_decay/>
        <self_collide>0</self_collide>
        <kinematic>0</kinematic>
      </link>
      <joint name='j_arm2_7' type='revolute'>
        <child>arm2_7</child>
        <parent>arm2_6</parent>
        <axis>
          <xyz>0 0 -1</xyz>
          <limit>
            <lower>-2.618</lower>
            <upper>2.618</upper>
            <effort>27</effort>
            <velocity>20.3</velocity>
          </limit>
          <dynamics>
            <spring_reference>0</spring_reference>
            <spring_stiffness>0</spring_stiffness>
          </dynamics>
          <use_parent_model_frame>1</use_parent_model_frame>
        </axis>
      </joint>
      <link name='arm2_8'>
        <pose frame=''>0.297941 -0.209516 0.565342 -3.14159 -0 2.0944</pose>
        <inertial>
          <pose frame=''>0 0 0.1 0 -0 0</pose>
          <mass>0.3</mass>
          <inertia>
            <ixx>0.000245</ixx>
            <ixy>0</ixy>
            <ixz>0</ixz>
            <iyy>0.000245</iyy>
            <iyz>0</iyz>
            <izz>0.000245</izz>
          </inertia>
        </inertial>
        <collision name='arm2_8_collision'>
          <pose frame=''>0 0 0 0 -0 0</pose>
          <geometry>
            <box>
              <size>0.03 0.08 0.12</size>
            </box>
          </geometry>
          <surface>
            <contact>
              <ode/>
            </contact>
            <friction>
              <ode>
                <mu>0</mu>
                <mu2>0</mu2>
              </ode>
              <torsional>
                <ode/>
              </torsional>
            </friction>
            <bounce/>
          </surface>
          <max_contacts>10</max_contacts>
        </collision>
        <visual name='arm2_8_visual'>
          <pose frame=''>0 0 0 0 -0 0</pose>
          <geometry>
            <box>
              <size>0.03 0.08 0.12</size>
            </box>
          </geometry>
          <material>
            <script>
              <name>Gazebo/OrangeTransparent</name>
              <uri>file://media/materials/scripts/gazebo.material</uri>
            </script>
          </material>
        </visual>
        <gravity>1</gravity>
        <velocity_decay/>
        <self_collide>0</self_collide>
        <kinematic>0</kinematic>
      </link>
      <joint name='j_arm2_8' type='revolute'>
        <child>arm2_8</child>
        <parent>arm2_7</parent>
        <axis>
          <xyz>-0.500003 0.866023 0</xyz>
          <limit>
            <lower>0</lower>
            <upper>0</upper>
            <effort>0</effort>
            <velocity>0</velocity>
          </limit>
          <dynamics>
            <spring_reference>0</spring_reference>
            <spring_stiffness>0</spring_stiffness>
          </dynamics>
          <use_parent_model_frame>1</use_parent_model_frame>
        </axis>
        <physics>
          <ode>
            <limit>
              <cfm>0</cfm>
              <erp>0.2</erp>
            </limit>
          </ode>
        </physics>
        <sensor name='right_arm_ft' type='force_torque'>
          <force_torque>
            <frame>parent</frame>
            <measure_direction>child_to_parent</measure_direction>
          </force_torque>
          <always_on>1</always_on>
          <visualize>1</visualize>
          <update_rate>1000</update_rate>
          <pose frame=''>0 0 0 0 -0 0</pose>
        </sensor>
      </joint>
      <link name='neck_3'>
        <pose frame=''>0.255 0 1.65486 0 -0 0</pose>
        <inertial>
          <pose frame=''>0.048467 -0.059852 -0.008531 0 -0 0</pose>
          <mass>0.785269</mass>
          <inertia>
            <ixx>0.000468234</ixx>
            <ixy>-1.05438e-05</ixy>
            <ixz>7.24398e-05</ixz>
            <iyy>0.000263525</iyy>
            <iyz>1.6904e-06</iyz>
            <izz>0.000376335</izz>
          </inertia>
        </inertial>
        <collision name='neck_3_collision'>
          <pose frame=''>0 0 0 0 -0 0</pose>
          <geometry>
            <mesh>
              <scale>0.001 0.001 0.001</scale>
              <uri>/home/Cheng/advr-superbuild/robots/centauro-simulator/centauro/centauro_urdf/meshes/convex_hull/velodyne.stl</uri>
            </mesh>
          </geometry>
          <max_contacts>10</max_contacts>
          <surface>
            <contact>
              <ode/>
            </contact>
            <bounce/>
            <friction>
              <torsional>
                <ode/>
              </torsional>
              <ode/>
            </friction>
          </surface>
        </collision>
        <visual name='neck_3_visual'>
          <pose frame=''>0 0 0 0 -0 0</pose>
          <geometry>
            <mesh>
              <scale>0.001 0.001 0.001</scale>
              <uri>/home/Cheng/advr-superbuild/robots/centauro-simulator/centauro/centauro_urdf/meshes/velodyne.stl</uri>
            </mesh>
          </geometry>
        </visual>
        <self_collide>0</self_collide>
        <kinematic>0</kinematic>
      </link>
      <joint name='neck_velodyne' type='revolute'>
        <child>neck_3</child>
        <parent>torso_2</parent>
        <axis>
          <xyz>0 0 1</xyz>
          <limit>
            <lower>-1e+16</lower>
            <upper>1e+16</upper>
          </limit>
          <dynamics>
            <spring_reference>0</spring_reference>
            <spring_stiffness>0</spring_stiffness>
          </dynamics>
          <use_parent_model_frame>1</use_parent_model_frame>
        </axis>
      </joint>
      <link name='neck_1'>
        <pose frame=''>0.2 0 1.4611 0 -0 0</pose>
        <inertial>
          <pose frame=''>0.04048 0.021378 -0.014595 0 -0 0</pose>
          <mass>0.338787</mass>
          <inertia>
            <ixx>0.000371857</ixx>
            <ixy>-9.42983e-05</ixy>
            <ixz>-2.80644e-05</ixz>
            <iyy>0.000188688</iyy>
            <iyz>-1.54534e-05</iyz>
            <izz>0.000502344</izz>
          </inertia>
        </inertial>
        <collision name='neck_1_collision'>
          <pose frame=''>0 0 0 0 -0 0</pose>
          <geometry>
            <mesh>
              <scale>0.001 0.001 0.001</scale>
              <uri>/home/Cheng/advr-superbuild/robots/centauro-simulator/centauro/centauro_urdf/meshes/convex_hull/neck_yaw.stl</uri>
            </mesh>
          </geometry>
          <max_contacts>10</max_contacts>
          <surface>
            <contact>
              <ode/>
            </contact>
            <bounce/>
            <friction>
              <torsional>
                <ode/>
              </torsional>
              <ode/>
            </friction>
          </surface>
        </collision>
        <visual name='neck_1_visual'>
          <pose frame=''>0 0 0 0 -0 0</pose>
          <geometry>
            <mesh>
              <scale>0.001 0.001 0.001</scale>
              <uri>/home/Cheng/advr-superbuild/robots/centauro-simulator/centauro/centauro_urdf/meshes/neck_yaw.stl</uri>
            </mesh>
          </geometry>
        </visual>
        <self_collide>0</self_collide>
        <kinematic>0</kinematic>
      </link>
      <joint name='neck_yaw' type='revolute'>
        <child>neck_1</child>
        <parent>torso_2</parent>
        <axis>
          <xyz>0 0 1</xyz>
          <limit>
            <lower>-0.785398</lower>
            <upper>0.785398</upper>
            <effort>35</effort>
            <velocity>5.7</velocity>
          </limit>
          <dynamics>
            <spring_reference>0</spring_reference>
            <spring_stiffness>0</spring_stiffness>
          </dynamics>
          <use_parent_model_frame>1</use_parent_model_frame>
        </axis>
      </joint>
      <link name='neck_2'>
        <pose frame=''>0.254 0.0596 1.4486 0 -0 0</pose>
        <inertial>
          <pose frame=''>0.048467 -0.059852 -0.008531 0 -0 0</pose>
          <mass>0.785269</mass>
          <inertia>
            <ixx>0.000468234</ixx>
            <ixy>-1.05438e-05</ixy>
            <ixz>7.24398e-05</ixz>
            <iyy>0.000263525</iyy>
            <iyz>1.6904e-06</iyz>
            <izz>0.000376335</izz>
          </inertia>
        </inertial>
        <collision name='neck_2_collision'>
          <pose frame=''>0 0 0 0 -0 0</pose>
          <geometry>
            <mesh>
              <scale>0.001 0.001 0.001</scale>
              <uri>/home/Cheng/advr-superbuild/robots/centauro-simulator/centauro/centauro_urdf/meshes/convex_hull/neck_pitch.stl</uri>
            </mesh>
          </geometry>
          <max_contacts>10</max_contacts>
          <surface>
            <contact>
              <ode/>
            </contact>
            <bounce/>
            <friction>
              <torsional>
                <ode/>
              </torsional>
              <ode/>
            </friction>
          </surface>
        </collision>
        <visual name='neck_2_visual'>
          <pose frame=''>0 0 0 0 -0 0</pose>
          <geometry>
            <mesh>
              <scale>0.001 0.001 0.001</scale>
              <uri>/home/Cheng/advr-superbuild/robots/centauro-simulator/centauro/centauro_urdf/meshes/neck_pitch.stl</uri>
            </mesh>
          </geometry>
        </visual>
        <self_collide>0</self_collide>
        <kinematic>0</kinematic>
      </link>
      <joint name='neck_pitch' type='revolute'>
        <child>neck_2</child>
        <parent>neck_1</parent>
        <axis>
          <xyz>0 1 0</xyz>
          <limit>
            <lower>-0.349066</lower>
            <upper>0.785398</upper>
            <effort>35</effort>
            <velocity>5.7</velocity>
          </limit>
          <dynamics>
            <spring_reference>0</spring_reference>
            <spring_stiffness>0</spring_stiffness>
          </dynamics>
          <use_parent_model_frame>1</use_parent_model_frame>
        </axis>
      </joint>
      <static>0</static>
      <plugin name='gazebo_xbot_plugin' filename='libGazeboXBotPlugin.so'>
        <path_to_config_file>configs/ADVR_shared/centauro/configs/config_centauro.yaml</path_to_config_file>
        <robotNamespace>/</robotNamespace>
      </plugin>
      <pose frame=''>0 0 0 0 -0 0</pose>
    </model>
    <model name='table'>
      <static>1</static>
      <link name='link'>
        <collision name='surface'>
          <pose frame=''>0 0 1.36 0 -0 0</pose>
          <geometry>
            <box>
              <size>1.5 0.8 0.03</size>
            </box>
          </geometry>
          <surface>
            <friction>
              <ode>
                <mu>0.3</mu>
                <mu2>0.3</mu2>
              </ode>
              <torsional>
                <ode/>
              </torsional>
            </friction>
            <contact>
              <ode/>
            </contact>
            <bounce/>
          </surface>
          <max_contacts>10</max_contacts>
        </collision>
        <visual name='visual1'>
          <pose frame=''>0 0 1 0 -0 0</pose>
          <geometry>
            <box>
              <size>1.5 0.8 0.03</size>
            </box>
          </geometry>
          <material>
            <script>
              <uri>file://media/materials/scripts/gazebo.material</uri>
              <name>Gazebo/Wood</name>
            </script>
          </material>
        </visual>
        <collision name='front_left_leg'>
          <pose frame=''>0.68 0.38 0.5 0 -0 0</pose>
          <geometry>
            <cylinder>
              <radius>0.02</radius>
              <length>1</length>
            </cylinder>
          </geometry>
          <max_contacts>10</max_contacts>
          <surface>
            <contact>
              <ode/>
            </contact>
            <bounce/>
            <friction>
              <torsional>
                <ode/>
              </torsional>
              <ode/>
            </friction>
          </surface>
        </collision>
        <visual name='front_left_leg'>
          <pose frame=''>0.68 0.38 0.5 0 -0 0</pose>
          <geometry>
            <cylinder>
              <radius>0.02</radius>
              <length>1</length>
            </cylinder>
          </geometry>
          <material>
            <script>
              <uri>file://media/materials/scripts/gazebo.material</uri>
              <name>Gazebo/Grey</name>
            </script>
          </material>
        </visual>
        <collision name='front_right_leg'>
          <pose frame=''>0.68 -0.38 0.5 0 -0 0</pose>
          <geometry>
            <cylinder>
              <radius>0.02</radius>
              <length>1</length>
            </cylinder>
          </geometry>
          <max_contacts>10</max_contacts>
          <surface>
            <contact>
              <ode/>
            </contact>
            <bounce/>
            <friction>
              <torsional>
                <ode/>
              </torsional>
              <ode/>
            </friction>
          </surface>
        </collision>
        <visual name='front_right_leg'>
          <pose frame=''>0.68 -0.38 0.5 0 -0 0</pose>
          <geometry>
            <cylinder>
              <radius>0.02</radius>
              <length>1</length>
            </cylinder>
          </geometry>
          <material>
            <script>
              <uri>file://media/materials/scripts/gazebo.material</uri>
              <name>Gazebo/Grey</name>
            </script>
          </material>
        </visual>
        <collision name='back_right_leg'>
          <pose frame=''>-0.68 -0.38 0.5 0 -0 0</pose>
          <geometry>
            <cylinder>
              <radius>0.02</radius>
              <length>1</length>
            </cylinder>
          </geometry>
          <max_contacts>10</max_contacts>
          <surface>
            <contact>
              <ode/>
            </contact>
            <bounce/>
            <friction>
              <torsional>
                <ode/>
              </torsional>
              <ode/>
            </friction>
          </surface>
        </collision>
        <visual name='back_right_leg'>
          <pose frame=''>-0.68 -0.38 0.5 0 -0 0</pose>
          <geometry>
            <cylinder>
              <radius>0.02</radius>
              <length>1</length>
            </cylinder>
          </geometry>
          <material>
            <script>
              <uri>file://media/materials/scripts/gazebo.material</uri>
              <name>Gazebo/Grey</name>
            </script>
          </material>
        </visual>
        <collision name='back_left_leg'>
          <pose frame=''>-0.68 0.38 0.5 0 -0 0</pose>
          <geometry>
            <cylinder>
              <radius>0.02</radius>
              <length>1</length>
            </cylinder>
          </geometry>
          <max_contacts>10</max_contacts>
          <surface>
            <contact>
              <ode/>
            </contact>
            <bounce/>
            <friction>
              <torsional>
                <ode/>
              </torsional>
              <ode/>
            </friction>
          </surface>
        </collision>
        <visual name='back_left_leg'>
          <pose frame=''>-0.68 0.38 0.5 0 -0 0</pose>
          <geometry>
            <cylinder>
              <radius>0.02</radius>
              <length>1</length>
            </cylinder>
          </geometry>
          <material>
            <script>
              <uri>file://media/materials/scripts/gazebo.material</uri>
              <name>Gazebo/Grey</name>
            </script>
          </material>
        </visual>
        <self_collide>0</self_collide>
        <kinematic>0</kinematic>
      </link>
      <pose frame=''>0.279058 1.60558 0 0 -0 0</pose>
    </model>
    <state world_name='default'>
      <sim_time>470 805250000</sim_time>
      <real_time>58 887847904</real_time>
      <wall_time>1509402816 456101159</wall_time>
      <iterations>167177</iterations>
      <model name='centauro'>
        <pose frame=''>0 0 0 0 -0 0</pose>
        <scale>1 1 1</scale>
        <link name='arm1_1'>
          <pose frame=''>0.24576 0.169137 1.29823 -1e-06 0.000157 -0.523575</pose>
          <velocity>2e-06 0 0 -6.3e-05 7e-05 -6e-06</velocity>
          <acceleration>-0.002807 0.000596 0.011012 -0.626376 -0.729376 -1.85894</acceleration>
          <wrench>-0.004374 0.000928 0.017161 0 -0 0</wrench>
        </link>
        <link name='arm1_2'>
          <pose frame=''>0.197351 0.26759 1.309 -1e-06 0.000156 -0.523576</pose>
          <velocity>3e-06 -1e-06 0 6.3e-05 -3e-06 -1.5e-05</velocity>
          <acceleration>-0.002594 0.025225 0.018221 0.296125 -1.32659 -0.958152</acceleration>
          <wrench>-0.003931 0.038218 0.027605 0 -0 0</wrench>
        </link>
        <link name='arm1_3'>
          <pose frame=''>0.27626 0.222033 1.08984 -1e-06 0.000157 -0.523576</pose>
          <velocity>5e-06 1.5e-05 -3e-06 3.2e-05 7e-06 -0.000328</velocity>
          <acceleration>-0.020354 0.027244 0.011471 -0.660772 1.33083 -3.08275</acceleration>
          <wrench>-0.03071 0.041106 0.017308 0 -0 0</wrench>
        </link>
        <link name='arm1_4'>
          <pose frame=''>0.338966 0.250667 1.01583 -1e-06 7.9e-05 -0.523576</pose>
          <velocity>1.4e-05 -3e-06 0 -3.2e-05 -8e-06 -0.000307</velocity>
          <acceleration>-0.009586 -0.088342 0.013632 -2.63805 -1.42458 2.45659</acceleration>
          <wrench>-0.009231 -0.085071 0.013128 0 -0 0</wrench>
        </link>
        <link name='arm1_5'>
          <pose frame=''>0.297897 0.209542 0.954836 -1e-06 7.9e-05 -0.523576</pose>
          <velocity>2e-06 9e-06 -1e-06 -3.2e-05 0 1.1e-05</velocity>
          <acceleration>0.003845 0.010416 0.00334 -0.018106 -0.309293 0.222482</acceleration>
          <wrench>0.005654 0.015315 0.00491 0 -0 0</wrench>
        </link>
        <link name='arm1_6'>
          <pose frame=''>0.322384 0.251984 0.774836 -1e-06 7.9e-05 -0.523576</pose>
          <velocity>2e-06 3e-06 -1e-06 -2.8e-05 1.8e-05 1.1e-05</velocity>
          <acceleration>0.023214 0.023625 0.006154 0.187077 0.034368 0.29588</acceleration>
          <wrench>0.021982 0.022371 0.005827 0 -0 0</wrench>
        </link>
        <link name='arm1_7'>
          <pose frame=''>0.297873 0.209555 0.605836 -1e-06 7.9e-05 -0.523576</pose>
          <velocity>-1e-06 -2e-06 0 -5.3e-05 3.3e-05 7e-06</velocity>
          <acceleration>0.024207 0.037451 0.004286 0.100372 0.05626 -0.060346</acceleration>
          <wrench>0.013551 0.020965 0.002399 0 -0 0</wrench>
        </link>
        <link name='arm1_8'>
          <pose frame=''>0.297871 0.209557 0.565336 -3.14152 1e-06 1.04722</pose>
          <velocity>-4e-06 -6e-06 0 -4.2e-05 2.7e-05 7e-06</velocity>
          <acceleration>0.014564 0.04703 0.004231 0.126481 0.0384 -0.060479</acceleration>
          <wrench>0.004369 0.014109 0.001269 0 -0 0</wrench>
        </link>
        <link name='arm2_1'>
          <pose frame=''>0.24576 -0.169137 1.29823 1e-06 0.000157 0.523575</pose>
          <velocity>-1e-06 0 0 3.4e-05 1.8e-05 -1e-05</velocity>
          <acceleration>0.002736 0.000371 0.0028 0.863701 -0.684461 1.90081</acceleration>
          <wrench>0.004264 0.000578 0.004363 0 -0 0</wrench>
        </link>
        <link name='arm2_2'>
          <pose frame=''>0.197351 -0.26759 1.309 1e-06 0.000156 0.523576</pose>
          <velocity>-2e-06 1e-06 -2e-06 -7.4e-05 -4.4e-05 -5e-06</velocity>
          <acceleration>0.005997 -0.009045 0.003228 -0.102646 0.129469 -0.039895</acceleration>
          <wrench>0.009086 -0.013704 0.004891 0 -0 0</wrench>
        </link>
        <link name='arm2_3'>
          <pose frame=''>0.27626 -0.222033 1.08984 1e-06 0.000157 0.523576</pose>
          <velocity>8e-06 -1.6e-05 -2e-06 -6.5e-05 -4.1e-05 0.000169</velocity>
          <acceleration>0.007509 -0.018736 0.002164 -2.45401 1.39619 -2.52714</acceleration>
          <wrench>0.011329 -0.028269 0.003266 0 -0 0</wrench>
        </link>
        <link name='arm2_4'>
          <pose frame=''>0.338965 -0.250667 1.01583 1e-06 7.9e-05 0.523576</pose>
          <velocity>1.6e-05 -1.1e-05 4e-06 -5.4e-05 -3.3e-05 0.000162</velocity>
          <acceleration>0.010944 -0.011922 0.002106 2.35829 -1.22856 1.35965</acceleration>
          <wrench>0.010538 -0.011481 0.002028 0 -0 0</wrench>
        </link>
        <link name='arm2_5'>
          <pose frame=''>0.297897 -0.209542 0.954836 1e-06 7.9e-05 0.523576</pose>
          <velocity>1.2e-05 -2.1e-05 0 -5.5e-05 -3.1e-05 3.3e-05</velocity>
          <acceleration>0.01976 -0.03348 -0.000615 -0.077634 -0.087109 -0.004702</acceleration>
          <wrench>0.029055 -0.049228 -0.000904 0 -0 0</wrench>
        </link>
        <link name='arm2_6'>
          <pose frame=''>0.322384 -0.251984 0.774836 1e-06 7.9e-05 0.523576</pose>
          <velocity>1.8e-05 -3e-05 3e-06 -5.3e-05 -3.2e-05 3.3e-05</velocity>
          <acceleration>0.029654 -0.047698 0.000247 -0.112014 -0.022696 -0.062764</acceleration>
          <wrench>0.02808 -0.045167 0.000234 0 -0 0</wrench>
        </link>
        <link name='arm2_7'>
          <pose frame=''>0.297873 -0.209555 0.605836 1e-06 7.9e-05 0.523576</pose>
          <velocity>2.3e-05 -3.9e-05 0 -4.9e-05 -3e-05 3.1e-05</velocity>
          <acceleration>0.03351 -0.057499 -0.001235 -0.100295 -0.037715 0.066833</acceleration>
          <wrench>0.018759 -0.032189 -0.000691 0 -0 0</wrench>
        </link>
        <link name='arm2_8'>
          <pose frame=''>0.297871 -0.209556 0.565336 -3.14151 -1e-06 2.09437</pose>
          <velocity>2.4e-05 -4.1e-05 0 -5.1e-05 -3.2e-05 3.1e-05</velocity>
          <acceleration>0.03855 -0.070778 -0.001219 -0.102298 -0.039463 0.067017</acceleration>
          <wrench>0.011565 -0.021233 -0.000366 0 -0 0</wrench>
        </link>
        <link name='neck_1'>
          <pose frame=''>0.2 0 1.4611 0 -1e-06 0.615409</pose>
          <velocity>1e-06 0 0 0 -0 0.003551</velocity>
          <acceleration>-0.000791 -0.000666 -0.000637 -0.00487 0.010206 -0.001783</acceleration>
          <wrench>-0.000268 -0.000226 -0.000216 0 -0 0</wrench>
        </link>
        <link name='neck_2'>
          <pose frame=''>0.209686 0.079839 1.4486 0 0.785399 0.615409</pose>
          <velocity>-0.000283 3.5e-05 0 1e-06 -2e-06 0.003551</velocity>
          <acceleration>-0.000645 -0.000526 -0.000381 0.000341 3.2e-05 -0.002318</acceleration>
          <wrench>-0.000506 -0.000413 -0.0003 0 -0 0</wrench>
        </link>
        <link name='neck_3'>
          <pose frame=''>0.255 0 1.65486 0 0 -0.193908</pose>
          <velocity>0 0 0 0 -1e-06 -0.000365</velocity>
          <acceleration>-0.000361 0.000664 -0.001078 -0.001583 0.002486 0.00168</acceleration>
          <wrench>-0.000283 0.000522 -0.000847 0 -0 0</wrench>
        </link>
        <link name='torso_2'>
          <pose frame=''>0.2 0 1.1816 0 -0 0</pose>
          <velocity>1e-06 0 0 -0 -1e-06 -1e-05</velocity>
          <acceleration>-0.001417 -0.000742 -0.000903 -0.001638 0.002966 0.016863</acceleration>
          <wrench>-0.008769 -0.00459 -0.005586 0 -0 0</wrench>
        </link>
      </model>
      <model name='ground_plane'>
        <pose frame=''>0 0 0 0 -0 0</pose>
        <scale>1 1 1</scale>
        <link name='link'>
          <pose frame=''>0 0 0 0 -0 0</pose>
          <velocity>0 0 0 0 -0 0</velocity>
          <acceleration>0 0 0 0 -0 0</acceleration>
          <wrench>0 0 0 0 -0 0</wrench>
        </link>
      </model>
      <model name='table'>
        <pose frame=''>0.520527 -0.060244 0 0 -0 1.55408</pose>
        <scale>1.2 0.1 1.36</scale>
        <link name='link'>
          <pose frame=''>0.520527 -0.060244 0 0 -0 1.55408</pose>
          <velocity>0 0 0 0 -0 0</velocity>
          <acceleration>0 0 0 0 -0 0</acceleration>
          <wrench>0 0 0 0 -0 0</wrench>
        </link>
      </model>
      <light name='sun'>
        <pose frame=''>0 0 10 0 -0 0</pose>
      </light>
    </state>
  </world>
</sdf>
